Workbook

Sheet 使用說明
B1: 期中團體作業 項目分析範本
B2: 員工意向調查 HRM922 2026 Fall 國立中山大學人力資源管理研究所 王豫萱
B4: 使用前
B5: 先完成草率作答篩檢，刪除要剔除的填答者；作答秒數、檢核題等非題目欄位也先刪除，只留編號與題目
B7: 操作步驟
B8: 1 原始資料：從 A1 貼上，第 1 列為欄位名稱（編號、題目代號），第 2 列起每列一位填答者；最多 40 題、500 人
B9: 2 反向題設定：B2 填量尺點數（五點量表填 5、六點量表填 6、七點量表填 7）；C 欄把反向題選為「是」
B10: 3 計分、校正總分：自動完成反向計分與總分，不需要填寫
B11: 4 項目分析：查看每一題的決斷值與校正題總相關，依判定欄決定保留或檢查
B13: 判讀標準
B14: 決斷值（CR）：總分前 27% 為高分組、後 27% 為低分組，比較兩組在該題的平均數；t 值 3.00 以上表示該題能區分高低分者
B15: 校正題總相關：該題與「其他題目總分」的相關；.30 以上表示該題與其他題目測的方向一致
... B18: 項目分析只是第一關，是否刪題還要看探索性因素分析的負荷量與題目內容，刪題理由寫入企劃書 5.1

Sheet 原始資料
A1: 編號

Sheet 反向題設定
A2: 量尺點數 | B2: 6 | C2: 五點量表填 5、六點填 6、七點填 7；反向計分＝（量尺點數＋1）－原始分數，例如六點量表為 7 減原始分數、五點量表為 6 減原始分數
A4: 順序 | B4: 題目代號 | C4: 反向題
A5: 1 | B5: =IF(INDEX(原始資料!$B$1:$AO$1,1)="","",INDEX(原始資料!$B$1:$AO$1,1))
A6: 2 | B6: =IF(INDEX(原始資料!$B$1:$AO$1,2)="","",INDEX(原始資料!$B$1:$AO$1,2))
A7: 3 | B7: =IF(INDEX(原始資料!$B$1:$AO$1,3)="","",INDEX(原始資料!$B$1:$AO$1,3))
A8: 4 | B8: =IF(INDEX(原始資料!$B$1:$AO$1,4)="","",INDEX(原始資料!$B$1:$AO$1,4))
A9: 5 | B9: =IF(INDEX(原始資料!$B$1:$AO$1,5)="","",INDEX(原始資料!$B$1:$AO$1,5))
A10: 6 | B10: =IF(INDEX(原始資料!$B$1:$AO$1,6)="","",INDEX(原始資料!$B$1:$AO$1,6))
A11: 7 | B11: =IF(INDEX(原始資料!$B$1:$AO$1,7)="","",INDEX(原始資料!$B$1:$AO$1,7))
A12: 8 | B12: =IF(INDEX(原始資料!$B$1:$AO$1,8)="","",INDEX(原始資料!$B$1:$AO$1,8))
A13: 9 | B13: =IF(INDEX(原始資料!$B$1:$AO$1,9)="","",INDEX(原始資料!$B$1:$AO$1,9))
A14: 10 | B14: =IF(INDEX(原始資料!$B$1:$AO$1,10)="","",INDEX(原始資料!$B$1:$AO$1,10))
A15: 11 | B15: =IF(INDEX(原始資料!$B$1:$AO$1,11)="","",INDEX(原始資料!$B$1:$AO$1,11))
A16: 12 | B16: =IF(INDEX(原始資料!$B$1:$AO$1,12)="","",INDEX(原始資料!$B$1:$AO$1,12))
A17: 13 | B17: =IF(INDEX(原始資料!$B$1:$AO$1,13)="","",INDEX(原始資料!$B$1:$AO$1,13))
A18: 14 | B18: =IF(INDEX(原始資料!$B$1:$AO$1,14)="","",INDEX(原始資料!$B$1:$AO$1,14))
A19: 15 | B19: =IF(INDEX(原始資料!$B$1:$AO$1,15)="","",INDEX(原始資料!$B$1:$AO$1,15))
A20: 16 | B20: =IF(INDEX(原始資料!$B$1:$AO$1,16)="","",INDEX(原始資料!$B$1:$AO$1,16))
A21: 17 | B21: =IF(INDEX(原始資料!$B$1:$AO$1,17)="","",INDEX(原始資料!$B$1:$AO$1,17))
A22: 18 | B22: =IF(INDEX(原始資料!$B$1:$AO$1,18)="","",INDEX(原始資料!$B$1:$AO$1,18))
A23: 19 | B23: =IF(INDEX(原始資料!$B$1:$AO$1,19)="","",INDEX(原始資料!$B$1:$AO$1,19))
A24: 20 | B24: =IF(INDEX(原始資料!$B$1:$AO$1,20)="","",INDEX(原始資料!$B$1:$AO$1,20))
A25: 21 | B25: =IF(INDEX(原始資料!$B$1:$AO$1,21)="","",INDEX(原始資料!$B$1:$AO$1,21))
A26: 22 | B26: =IF(INDEX(原始資料!$B$1:$AO$1,22)="","",INDEX(原始資料!$B$1:$AO$1,22))
A27: 23 | B27: =IF(INDEX(原始資料!$B$1:$AO$1,23)="","",INDEX(原始資料!$B$1:$AO$1,23))
A28: 24 | B28: =IF(INDEX(原始資料!$B$1:$AO$1,24)="","",INDEX(原始資料!$B$1:$AO$1,24))
A29: 25 | B29: =IF(INDEX(原始資料!$B$1:$AO$1,25)="","",INDEX(原始資料!$B$1:$AO$1,25))
A30: 26 | B30: =IF(INDEX(原始資料!$B$1:$AO$1,26)="","",INDEX(原始資料!$B$1:$AO$1,26))
A31: 27 | B31: =IF(INDEX(原始資料!$B$1:$AO$1,27)="","",INDEX(原始資料!$B$1:$AO$1,27))
A32: 28 | B32: =IF(INDEX(原始資料!$B$1:$AO$1,28)="","",INDEX(原始資料!$B$1:$AO$1,28))
A33: 29 | B33: =IF(INDEX(原始資料!$B$1:$AO$1,29)="","",INDEX(原始資料!$B$1:$AO$1,29))
A34: 30 | B34: =IF(INDEX(原始資料!$B$1:$AO$1,30)="","",INDEX(原始資料!$B$1:$AO$1,30))
A35: 31 | B35: =IF(INDEX(原始資料!$B$1:$AO$1,31)="","",INDEX(原始資料!$B$1:$AO$1,31))
A36: 32 | B36: =IF(INDEX(原始資料!$B$1:$AO$1,32)="","",INDEX(原始資料!$B$1:$AO$1,32))
A37: 33 | B37: =IF(INDEX(原始資料!$B$1:$AO$1,33)="","",INDEX(原始資料!$B$1:$AO$1,33))
A38: 34 | B38: =IF(INDEX(原始資料!$B$1:$AO$1,34)="","",INDEX(原始資料!$B$1:$AO$1,34))
A39: 35 | B39: =IF(INDEX(原始資料!$B$1:$AO$1,35)="","",INDEX(原始資料!$B$1:$AO$1,35))
A40: 36 | B40: =IF(INDEX(原始資料!$B$1:$AO$1,36)="","",INDEX(原始資料!$B$1:$AO$1,36))
A41: 37 | B41: =IF(INDEX(原始資料!$B$1:$AO$1,37)="","",INDEX(原始資料!$B$1:$AO$1,37))
A42: 38 | B42: =IF(INDEX(原始資料!$B$1:$AO$1,38)="","",INDEX(原始資料!$B$1:$AO$1,38))
...

Sheet 項目分析
A1: 項目分析
A2: 全部自動計算；判定欄為「檢查」的題目，回到題目內容與因素分析結果再決定是否刪除
A4: 有效樣本數 | C4: =COUNT(計分!$AP$2:$AP$501)
A5: 高分組切點（總分 ≥） | C5: =IF(C4<2,"",PERCENTILE(計分!$AP$2:$AP$501,0.73))
A6: 低分組切點（總分 ≤） | C6: =IF(C4<2,"",PERCENTILE(計分!$AP$2:$AP$501,0.27))
A7: 高分組人數 | C7: =COUNTIF(計分!$AQ$2:$AQ$501,"高")
A8: 低分組人數 | C8: =COUNTIF(計分!$AQ$2:$AQ$501,"低")
A9: 全量表 α | C9: =IF(COUNT(C12:C51)<3,"",COUNT(C12:C51)/(COUNT(C12:C51)-1)*(1-SUMSQ(D12:D51)/VAR(計分!$AP$2:$AP$501)))
A10: 判讀標準：決斷值 3.00 以上、校正題總相關 .30 以上為保留；刪除後 α 高於全量表 α 時以底色標示。三項都只是參考，刪題還要看因素分析與題目內容
A11: 題目代號 | B11: 反向題 | C11: 平均數 | D11: 標準差 | E11: 高分組平均 | F11: 低分組平均 | G11: 決斷值 CR | H11: 校正題總相關 | I11: 刪除後 α | J11: 判定 | K11: 高分組變異數 | L11: 低分組變異數
A12: =反向題設定!B5 | B12: =IF(A12="","",IF(反向題設定!C5="是","是","")) | C12: =IF(OR(A12="",COUNT(計分!B$2:B$501)<2),"",AVERAGE(計分!B$2:B$501)) | D12: =IF(C12="","",STDEV(計分!B$2:B$501)) | E12: =IF(OR(C12="",$C$7<2),"",AVERAGEIFS(計分!B$2:B$501,計分!$AQ$2:$AQ$501,"高")) | F12: =IF(OR(C12="",$C$8<2),"",AVERAGEIFS(計分!B$2:B$501,計分!$AQ$2:$AQ$501,"低")) | G12: =IF(OR(E12="",F12=""),"",IF(K12/$C$7+L12/$C$8=0,"",(E12-F12)/SQRT(K12/$C$7+L12/$C$8))) | H12: =IF(C12="","",CORREL(計分!B$2:B$501,校正總分!B$2:B$501)) | I12: =IF(OR(C12="",$C$9=""),"",(COUNT($C$12:$C$51)-1)/(COUNT($C$12:$C$51)-2)*(1-(SUMSQ($D$12:$D$51)-D12^2)/VAR(校正總分!B$2:B$501))) | J12: =IF(OR(G12="",H12=""),"",IF(H12<0,"檢查：負相關，確認是否漏了反向計分",IF(AND(G12>=3,H12>=0.3),IF(I12>$C$9,"保留；刪除後 α 略升，對照因素分析","保留"),IF(H12<0.3,"檢查：校正題總相關低於 .30","檢查：決斷值低於 3.00")))) | K12: =IF(E12="","",(SUMIFS(平方!B$2:B$501,計分!$AQ$2:$AQ$501,"高")-$C$7*E12^2)/($C$7-1)) | L12: =IF(F12="","",(SUMIFS(平方!B$2:B$501,計分!$AQ$2:$AQ$501,"低")-$C$8*F12^2)/($C$8-1))
A13: =反向題設定!B6 | B13: =IF(A13="","",IF(反向題設定!C6="是","是","")) | C13: =IF(OR(A13="",COUNT(計分!C$2:C$501)<2),"",AVERAGE(計分!C$2:C$501)) | D13: =IF(C13="","",STDEV(計分!C$2:C$501)) | E13: =IF(OR(C13="",$C$7<2),"",AVERAGEIFS(計分!C$2:C$501,計分!$AQ$2:$AQ$501,"高")) | F13: =IF(OR(C13="",$C$8<2),"",AVERAGEIFS(計分!C$2:C$501,計分!$AQ$2:$AQ$501,"低")) | G13: =IF(OR(E13="",F13=""),"",IF(K13/$C$7+L13/$C$8=0,"",(E13-F13)/SQRT(K13/$C$7+L13/$C$8))) | H13: =IF(C13="","",CORREL(計分!C$2:C$501,校正總分!C$2:C$501)) | I13: =IF(OR(C13="",$C$9=""),"",(COUNT($C$12:$C$51)-1)/(COUNT($C$12:$C$51)-2)*(1-(SUMSQ($D$12:$D$51)-D13^2)/VAR(校正總分!C$2:C$501))) | J13: =IF(OR(G13="",H13=""),"",IF(H13<0,"檢查：負相關，確認是否漏了反向計分",IF(AND(G13>=3,H13>=0.3),IF(I13>$C$9,"保留；刪除後 α 略升，對照因素分析","保留"),IF(H13<0.3,"檢查：校正題總相關低於 .30","檢查：決斷值低於 3.00")))) | K13: =IF(E13="","",(SUMIFS(平方!C$2:C$501,計分!$AQ$2:$AQ$501,"高")-$C$7*E13^2)/($C$7-1)) | L13: =IF(F13="","",(SUMIFS(平方!C$2:C$501,計分!$AQ$2:$AQ$501,"低")-$C$8*F13^2)/($C$8-1))
A14: =反向題設定!B7 | B14: =IF(A14="","",IF(反向題設定!C7="是","是","")) | C14: =IF(OR(A14="",COUNT(計分!D$2:D$501)<2),"",AVERAGE(計分!D$2:D$501)) | D14: =IF(C14="","",STDEV(計分!D$2:D$501)) | E14: =IF(OR(C14="",$C$7<2),"",AVERAGEIFS(計分!D$2:D$501,計分!$AQ$2:$AQ$501,"高")) | F14: =IF(OR(C14="",$C$8<2),"",AVERAGEIFS(計分!D$2:D$501,計分!$AQ$2:$AQ$501,"低")) | G14: =IF(OR(E14="",F14=""),"",IF(K14/$C$7+L14/$C$8=0,"",(E14-F14)/SQRT(K14/$C$7+L14/$C$8))) | H14: =IF(C14="","",CORREL(計分!D$2:D$501,校正總分!D$2:D$501)) | I14: =IF(OR(C14="",$C$9=""),"",(COUNT($C$12:$C$51)-1)/(COUNT($C$12:$C$51)-2)*(1-(SUMSQ($D$12:$D$51)-D14^2)/VAR(校正總分!D$2:D$501))) | J14: =IF(OR(G14="",H14=""),"",IF(H14<0,"檢查：負相關，確認是否漏了反向計分",IF(AND(G14>=3,H14>=0.3),IF(I14>$C$9,"保留；刪除後 α 略升，對照因素分析","保留"),IF(H14<0.3,"檢查：校正題總相關低於 .30","檢查：決斷值低於 3.00")))) | K14: =IF(E14="","",(SUMIFS(平方!D$2:D$501,計分!$AQ$2:$AQ$501,"高")-$C$7*E14^2)/($C$7-1)) | L14: =IF(F14="","",(SUMIFS(平方!D$2:D$501,計分!$AQ$2:$AQ$501,"低")-$C$8*F14^2)/($C$8-1))
A15: =反向題設定!B8 | B15: =IF(A15="","",IF(反向題設定!C8="是","是","")) | C15: =IF(OR(A15="",COUNT(計分!E$2:E$501)<2),"",AVERAGE(計分!E$2:E$501)) | D15: =IF(C15="","",STDEV(計分!E$2:E$501)) | E15: =IF(OR(C15="",$C$7<2),"",AVERAGEIFS(計分!E$2:E$501,計分!$AQ$2:$AQ$501,"高")) | F15: =IF(OR(C15="",$C$8<2),"",AVERAGEIFS(計分!E$2:E$501,計分!$AQ$2:$AQ$501,"低")) | G15: =IF(OR(E15="",F15=""),"",IF(K15/$C$7+L15/$C$8=0,"",(E15-F15)/SQRT(K15/$C$7+L15/$C$8))) | H15: =IF(C15="","",CORREL(計分!E$2:E$501,校正總分!E$2:E$501)) | I15: =IF(OR(C15="",$C$9=""),"",(COUNT($C$12:$C$51)-1)/(COUNT($C$12:$C$51)-2)*(1-(SUMSQ($D$12:$D$51)-D15^2)/VAR(校正總分!E$2:E$501))) | J15: =IF(OR(G15="",H15=""),"",IF(H15<0,"檢查：負相關，確認是否漏了反向計分",IF(AND(G15>=3,H15>=0.3),IF(I15>$C$9,"保留；刪除後 α 略升，對照因素分析","保留"),IF(H15<0.3,"檢查：校正題總相關低於 .30","檢查：決斷值低於 3.00")))) | K15: =IF(E15="","",(SUMIFS(平方!E$2:E$501,計分!$AQ$2:$AQ$501,"高")-$C$7*E15^2)/($C$7-1)) | L15: =IF(F15="","",(SUMIFS(平方!E$2:E$501,計分!$AQ$2:$AQ$501,"低")-$C$8*F15^2)/($C$8-1))
A16: =反向題設定!B9 | B16: =IF(A16="","",IF(反向題設定!C9="是","是","")) | C16: =IF(OR(A16="",COUNT(計分!F$2:F$501)<2),"",AVERAGE(計分!F$2:F$501)) | D16: =IF(C16="","",STDEV(計分!F$2:F$501)) | E16: =IF(OR(C16="",$C$7<2),"",AVERAGEIFS(計分!F$2:F$501,計分!$AQ$2:$AQ$501,"高")) | F16: =IF(OR(C16="",$C$8<2),"",AVERAGEIFS(計分!F$2:F$501,計分!$AQ$2:$AQ$501,"低")) | G16: =IF(OR(E16="",F16=""),"",IF(K16/$C$7+L16/$C$8=0,"",(E16-F16)/SQRT(K16/$C$7+L16/$C$8))) | H16: =IF(C16="","",CORREL(計分!F$2:F$501,校正總分!F$2:F$501)) | I16: =IF(OR(C16="",$C$9=""),"",(COUNT($C$12:$C$51)-1)/(COUNT($C$12:$C$51)-2)*(1-(SUMSQ($D$12:$D$51)-D16^2)/VAR(校正總分!F$2:F$501))) | J16: =IF(OR(G16="",H16=""),"",IF(H16<0,"檢查：負相關，確認是否漏了反向計分",IF(AND(G16>=3,H16>=0.3),IF(I16>$C$9,"保留；刪除後 α 略升，對照因素分析","保留"),IF(H16<0.3,"檢查：校正題總相關低於 .30","檢查：決斷值低於 3.00")))) | K16: =IF(E16="","",(SUMIFS(平方!F$2:F$501,計分!$AQ$2:$AQ$501,"高")-$C$7*E16^2)/($C$7-1)) | L16: =IF(F16="","",(SUMIFS(平方!F$2:F$501,計分!$AQ$2:$AQ$501,"低")-$C$8*F16^2)/($C$8-1))
A17: =反向題設定!B10 | B17: =IF(A17="","",IF(反向題設定!C10="是","是","")) | C17: =IF(OR(A17="",COUNT(計分!G$2:G$501)<2),"",AVERAGE(計分!G$2:G$501)) | D17: =IF(C17="","",STDEV(計分!G$2:G$501)) | E17: =IF(OR(C17="",$C$7<2),"",AVERAGEIFS(計分!G$2:G$501,計分!$AQ$2:$AQ$501,"高")) | F17: =IF(OR(C17="",$C$8<2),"",AVERAGEIFS(計分!G$2:G$501,計分!$AQ$2:$AQ$501,"低")) | G17: =IF(OR(E17="",F17=""),"",IF(K17/$C$7+L17/$C$8=0,"",(E17-F17)/SQRT(K17/$C$7+L17/$C$8))) | H17: =IF(C17="","",CORREL(計分!G$2:G$501,校正總分!G$2:G$501)) | I17: =IF(OR(C17="",$C$9=""),"",(COUNT($C$12:$C$51)-1)/(COUNT($C$12:$C$51)-2)*(1-(SUMSQ($D$12:$D$51)-D17^2)/VAR(校正總分!G$2:G$501))) | J17: =IF(OR(G17="",H17=""),"",IF(H17<0,"檢查：負相關，確認是否漏了反向計分",IF(AND(G17>=3,H17>=0.3),IF(I17>$C$9,"保留；刪除後 α 略升，對照因素分析","保留"),IF(H17<0.3,"檢查：校正題總相關低於 .30","檢查：決斷值低於 3.00")))) | K17: =IF(E17="","",(SUMIFS(平方!G$2:G$501,計分!$AQ$2:$AQ$501,"高")-$C$7*E17^2)/($C$7-1)) | L17: =IF(F17="","",(SUMIFS(平方!G$2:G$501,計分!$AQ$2:$AQ$501,"低")-$C$8*F17^2)/($C$8-1))
A18: =反向題設定!B11 | B18: =IF(A18="","",IF(反向題設定!C11="是","是","")) | C18: =IF(OR(A18="",COUNT(計分!H$2:H$501)<2),"",AVERAGE(計分!H$2:H$501)) | D18: =IF(C18="","",STDEV(計分!H$2:H$501)) | E18: =IF(OR(C18="",$C$7<2),"",AVERAGEIFS(計分!H$2:H$501,計分!$AQ$2:$AQ$501,"高")) | F18: =IF(OR(C18="",$C$8<2),"",AVERAGEIFS(計分!H$2:H$501,計分!$AQ$2:$AQ$501,"低")) | G18: =IF(OR(E18="",F18=""),"",IF(K18/$C$7+L18/$C$8=0,"",(E18-F18)/SQRT(K18/$C$7+L18/$C$8))) | H18: =IF(C18="","",CORREL(計分!H$2:H$501,校正總分!H$2:H$501)) | I18: =IF(OR(C18="",$C$9=""),"",(COUNT($C$12:$C$51)-1)/(COUNT($C$12:$C$51)-2)*(1-(SUMSQ($D$12:$D$51)-D18^2)/VAR(校正總分!H$2:H$501))) | J18: =IF(OR(G18="",H18=""),"",IF(H18<0,"檢查：負相關，確認是否漏了反向計分",IF(AND(G18>=3,H18>=0.3),IF(I18>$C$9,"保留；刪除後 α 略升，對照因素分析","保留"),IF(H18<0.3,"檢查：校正題總相關低於 .30","檢查：決斷值低於 3.00")))) | K18: =IF(E18="","",(SUMIFS(平方!H$2:H$501,計分!$AQ$2:$AQ$501,"高")-$C$7*E18^2)/($C$7-1)) | L18: =IF(F18="","",(SUMIFS(平方!H$2:H$501,計分!$AQ$2:$AQ$501,"低")-$C$8*F18^2)/($C$8-1))
A19: =反向題設定!B12 | B19: =IF(A19="","",IF(反向題設定!C12="是","是","")) | C19: =IF(OR(A19="",COUNT(計分!I$2:I$501)<2),"",AVERAGE(計分!I$2:I$501)) | D19: =IF(C19="","",STDEV(計分!I$2:I$501)) | E19: =IF(OR(C19="",$C$7<2),"",AVERAGEIFS(計分!I$2:I$501,計分!$AQ$2:$AQ$501,"高")) | F19: =IF(OR(C19="",$C$8<2),"",AVERAGEIFS(計分!I$2:I$501,計分!$AQ$2:$AQ$501,"低")) | G19: =IF(OR(E19="",F19=""),"",IF(K19/$C$7+L19/$C$8=0,"",(E19-F19)/SQRT(K19/$C$7+L19/$C$8))) | H19: =IF(C19="","",CORREL(計分!I$2:I$501,校正總分!I$2:I$501)) | I19: =IF(OR(C19="",$C$9=""),"",(COUNT($C$12:$C$51)-1)/(COUNT($C$12:$C$51)-2)*(1-(SUMSQ($D$12:$D$51)-D19^2)/VAR(校正總分!I$2:I$501))) | J19: =IF(OR(G19="",H19=""),"",IF(H19<0,"檢查：負相關，確認是否漏了反向計分",IF(AND(G19>=3,H19>=0.3),IF(I19>$C$9,"保留；刪除後 α 略升，對照因素分析","保留"),IF(H19<0.3,"檢查：校正題總相關低於 .30","檢查：決斷值低於 3.00")))) | K19: =IF(E19="","",(SUMIFS(平方!I$2:I$501,計分!$AQ$2:$AQ$501,"高")-$C$7*E19^2)/($C$7-1)) | L19: =IF(F19="","",(SUMIFS(平方!I$2:I$501,計分!$AQ$2:$AQ$501,"低")-$C$8*F19^2)/($C$8-1))
A20: =反向題設定!B13 | B20: =IF(A20="","",IF(反向題設定!C13="是","是","")) | C20: =IF(OR(A20="",COUNT(計分!J$2:J$501)<2),"",AVERAGE(計分!J$2:J$501)) | D20: =IF(C20="","",STDEV(計分!J$2:J$501)) | E20: =IF(OR(C20="",$C$7<2),"",AVERAGEIFS(計分!J$2:J$501,計分!$AQ$2:$AQ$501,"高")) | F20: =IF(OR(C20="",$C$8<2),"",AVERAGEIFS(計分!J$2:J$501,計分!$AQ$2:$AQ$501,"低")) | G20: =IF(OR(E20="",F20=""),"",IF(K20/$C$7+L20/$C$8=0,"",(E20-F20)/SQRT(K20/$C$7+L20/$C$8))) | H20: =IF(C20="","",CORREL(計分!J$2:J$501,校正總分!J$2:J$501)) | I20: =IF(OR(C20="",$C$9=""),"",(COUNT($C$12:$C$51)-1)/(COUNT($C$12:$C$51)-2)*(1-(SUMSQ($D$12:$D$51)-D20^2)/VAR(校正總分!J$2:J$501))) | J20: =IF(OR(G20="",H20=""),"",IF(H20<0,"檢查：負相關，確認是否漏了反向計分",IF(AND(G20>=3,H20>=0.3),IF(I20>$C$9,"保留；刪除後 α 略升，對照因素分析","保留"),IF(H20<0.3,"檢查：校正題總相關低於 .30","檢查：決斷值低於 3.00")))) | K20: =IF(E20="","",(SUMIFS(平方!J$2:J$501,計分!$AQ$2:$AQ$501,"高")-$C$7*E20^2)/($C$7-1)) | L20: =IF(F20="","",(SUMIFS(平方!J$2:J$501,計分!$AQ$2:$AQ$501,"低")-$C$8*F20^2)/($C$8-1))
A21: =反向題設定!B14 | B21: =IF(A21="","",IF(反向題設定!C14="是","是","")) | C21: =IF(OR(A21="",COUNT(計分!K$2:K$501)<2),"",AVERAGE(計分!K$2:K$501)) | D21: =IF(C21="","",STDEV(計分!K$2:K$501)) | E21: =IF(OR(C21="",$C$7<2),"",AVERAGEIFS(計分!K$2:K$501,計分!$AQ$2:$AQ$501,"高")) | F21: =IF(OR(C21="",$C$8<2),"",AVERAGEIFS(計分!K$2:K$501,計分!$AQ$2:$AQ$501,"低")) | G21: =IF(OR(E21="",F21=""),"",IF(K21/$C$7+L21/$C$8=0,"",(E21-F21)/SQRT(K21/$C$7+L21/$C$8))) | H21: =IF(C21="","",CORREL(計分!K$2:K$501,校正總分!K$2:K$501)) | I21: =IF(OR(C21="",$C$9=""),"",(COUNT($C$12:$C$51)-1)/(COUNT($C$12:$C$51)-2)*(1-(SUMSQ($D$12:$D$51)-D21^2)/VAR(校正總分!K$2:K$501))) | J21: =IF(OR(G21="",H21=""),"",IF(H21<0,"檢查：負相關，確認是否漏了反向計分",IF(AND(G21>=3,H21>=0.3),IF(I21>$C$9,"保留；刪除後 α 略升，對照因素分析","保留"),IF(H21<0.3,"檢查：校正題總相關低於 .30","檢查：決斷值低於 3.00")))) | K21: =IF(E21="","",(SUMIFS(平方!K$2:K$501,計分!$AQ$2:$AQ$501,"高")-$C$7*E21^2)/($C$7-1)) | L21: =IF(F21="","",(SUMIFS(平方!K$2:K$501,計分!$AQ$2:$AQ$501,"低")-$C$8*F21^2)/($C$8-1))
A22: =反向題設定!B15 | B22: =IF(A22="","",IF(反向題設定!C15="是","是","")) | C22: =IF(OR(A22="",COUNT(計分!L$2:L$501)<2),"",AVERAGE(計分!L$2:L$501)) | D22: =IF(C22="","",STDEV(計分!L$2:L$501)) | E22: =IF(OR(C22="",$C$7<2),"",AVERAGEIFS(計分!L$2:L$501,計分!$AQ$2:$AQ$501,"高")) | F22: =IF(OR(C22="",$C$8<2),"",AVERAGEIFS(計分!L$2:L$501,計分!$AQ$2:$AQ$501,"低")) | G22: =IF(OR(E22="",F22=""),"",IF(K22/$C$7+L22/$C$8=0,"",(E22-F22)/SQRT(K22/$C$7+L22/$C$8))) | H22: =IF(C22="","",CORREL(計分!L$2:L$501,校正總分!L$2:L$501)) | I22: =IF(OR(C22="",$C$9=""),"",(COUNT($C$12:$C$51)-1)/(COUNT($C$12:$C$51)-2)*(1-(SUMSQ($D$12:$D$51)-D22^2)/VAR(校正總分!L$2:L$501))) | J22: =IF(OR(G22="",H22=""),"",IF(H22<0,"檢查：負相關，確認是否漏了反向計分",IF(AND(G22>=3,H22>=0.3),IF(I22>$C$9,"保留；刪除後 α 略升，對照因素分析","保留"),IF(H22<0.3,"檢查：校正題總相關低於 .30","檢查：決斷值低於 3.00")))) | K22: =IF(E22="","",(SUMIFS(平方!L$2:L$501,計分!$AQ$2:$AQ$501,"高")-$C$7*E22^2)/($C$7-1)) | L22: =IF(F22="","",(SUMIFS(平方!L$2:L$501,計分!$AQ$2:$AQ$501,"低")-$C$8*F22^2)/($C$8-1))
A23: =反向題設定!B16 | B23: =IF(A23="","",IF(反向題設定!C16="是","是","")) | C23: =IF(OR(A23="",COUNT(計分!M$2:M$501)<2),"",AVERAGE(計分!M$2:M$501)) | D23: =IF(C23="","",STDEV(計分!M$2:M$501)) | E23: =IF(OR(C23="",$C$7<2),"",AVERAGEIFS(計分!M$2:M$501,計分!$AQ$2:$AQ$501,"高")) | F23: =IF(OR(C23="",$C$8<2),"",AVERAGEIFS(計分!M$2:M$501,計分!$AQ$2:$AQ$501,"低")) | G23: =IF(OR(E23="",F23=""),"",IF(K23/$C$7+L23/$C$8=0,"",(E23-F23)/SQRT(K23/$C$7+L23/$C$8))) | H23: =IF(C23="","",CORREL(計分!M$2:M$501,校正總分!M$2:M$501)) | I23: =IF(OR(C23="",$C$9=""),"",(COUNT($C$12:$C$51)-1)/(COUNT($C$12:$C$51)-2)*(1-(SUMSQ($D$12:$D$51)-D23^2)/VAR(校正總分!M$2:M$501))) | J23: =IF(OR(G23="",H23=""),"",IF(H23<0,"檢查：負相關，確認是否漏了反向計分",IF(AND(G23>=3,H23>=0.3),IF(I23>$C$9,"保留；刪除後 α 略升，對照因素分析","保留"),IF(H23<0.3,"檢查：校正題總相關低於 .30","檢查：決斷值低於 3.00")))) | K23: =IF(E23="","",(SUMIFS(平方!M$2:M$501,計分!$AQ$2:$AQ$501,"高")-$C$7*E23^2)/($C$7-1)) | L23: =IF(F23="","",(SUMIFS(平方!M$2:M$501,計分!$AQ$2:$AQ$501,"低")-$C$8*F23^2)/($C$8-1))
A24: =反向題設定!B17 | B24: =IF(A24="","",IF(反向題設定!C17="是","是","")) | C24: =IF(OR(A24="",COUNT(計分!N$2:N$501)<2),"",AVERAGE(計分!N$2:N$501)) | D24: =IF(C24="","",STDEV(計分!N$2:N$501)) | E24: =IF(OR(C24="",$C$7<2),"",AVERAGEIFS(計分!N$2:N$501,計分!$AQ$2:$AQ$501,"高")) | F24: =IF(OR(C24="",$C$8<2),"",AVERAGEIFS(計分!N$2:N$501,計分!$AQ$2:$AQ$501,"低")) | G24: =IF(OR(E24="",F24=""),"",IF(K24/$C$7+L24/$C$8=0,"",(E24-F24)/SQRT(K24/$C$7+L24/$C$8))) | H24: =IF(C24="","",CORREL(計分!N$2:N$501,校正總分!N$2:N$501)) | I24: =IF(OR(C24="",$C$9=""),"",(COUNT($C$12:$C$51)-1)/(COUNT($C$12:$C$51)-2)*(1-(SUMSQ($D$12:$D$51)-D24^2)/VAR(校正總分!N$2:N$501))) | J24: =IF(OR(G24="",H24=""),"",IF(H24<0,"檢查：負相關，確認是否漏了反向計分",IF(AND(G24>=3,H24>=0.3),IF(I24>$C$9,"保留；刪除後 α 略升，對照因素分析","保留"),IF(H24<0.3,"檢查：校正題總相關低於 .30","檢查：決斷值低於 3.00")))) | K24: =IF(E24="","",(SUMIFS(平方!N$2:N$501,計分!$AQ$2:$AQ$501,"高")-$C$7*E24^2)/($C$7-1)) | L24: =IF(F24="","",(SUMIFS(平方!N$2:N$501,計分!$AQ$2:$AQ$501,"低")-$C$8*F24^2)/($C$8-1))
A25: =反向題設定!B18 | B25: =IF(A25="","",IF(反向題設定!C18="是","是","")) | C25: =IF(OR(A25="",COUNT(計分!O$2:O$501)<2),"",AVERAGE(計分!O$2:O$501)) | D25: =IF(C25="","",STDEV(計分!O$2:O$501)) | E25: =IF(OR(C25="",$C$7<2),"",AVERAGEIFS(計分!O$2:O$501,計分!$AQ$2:$AQ$501,"高")) | F25: =IF(OR(C25="",$C$8<2),"",AVERAGEIFS(計分!O$2:O$501,計分!$AQ$2:$AQ$501,"低")) | G25: =IF(OR(E25="",F25=""),"",IF(K25/$C$7+L25/$C$8=0,"",(E25-F25)/SQRT(K25/$C$7+L25/$C$8))) | H25: =IF(C25="","",CORREL(計分!O$2:O$501,校正總分!O$2:O$501)) | I25: =IF(OR(C25="",$C$9=""),"",(COUNT($C$12:$C$51)-1)/(COUNT($C$12:$C$51)-2)*(1-(SUMSQ($D$12:$D$51)-D25^2)/VAR(校正總分!O$2:O$501))) | J25: =IF(OR(G25="",H25=""),"",IF(H25<0,"檢查：負相關，確認是否漏了反向計分",IF(AND(G25>=3,H25>=0.3),IF(I25>$C$9,"保留；刪除後 α 略升，對照因素分析","保留"),IF(H25<0.3,"檢查：校正題總相關低於 .30","檢查：決斷值低於 3.00")))) | K25: =IF(E25="","",(SUMIFS(平方!O$2:O$501,計分!$AQ$2:$AQ$501,"高")-$C$7*E25^2)/($C$7-1)) | L25: =IF(F25="","",(SUMIFS(平方!O$2:O$501,計分!$AQ$2:$AQ$501,"低")-$C$8*F25^2)/($C$8-1))
A26: =反向題設定!B19 | B26: =IF(A26="","",IF(反向題設定!C19="是","是","")) | C26: =IF(OR(A26="",COUNT(計分!P$2:P$501)<2),"",AVERAGE(計分!P$2:P$501)) | D26: =IF(C26="","",STDEV(計分!P$2:P$501)) | E26: =IF(OR(C26="",$C$7<2),"",AVERAGEIFS(計分!P$2:P$501,計分!$AQ$2:$AQ$501,"高")) | F26: =IF(OR(C26="",$C$8<2),"",AVERAGEIFS(計分!P$2:P$501,計分!$AQ$2:$AQ$501,"低")) | G26: =IF(OR(E26="",F26=""),"",IF(K26/$C$7+L26/$C$8=0,"",(E26-F26)/SQRT(K26/$C$7+L26/$C$8))) | H26: =IF(C26="","",CORREL(計分!P$2:P$501,校正總分!P$2:P$501)) | I26: =IF(OR(C26="",$C$9=""),"",(COUNT($C$12:$C$51)-1)/(COUNT($C$12:$C$51)-2)*(1-(SUMSQ($D$12:$D$51)-D26^2)/VAR(校正總分!P$2:P$501))) | J26: =IF(OR(G26="",H26=""),"",IF(H26<0,"檢查：負相關，確認是否漏了反向計分",IF(AND(G26>=3,H26>=0.3),IF(I26>$C$9,"保留；刪除後 α 略升，對照因素分析","保留"),IF(H26<0.3,"檢查：校正題總相關低於 .30","檢查：決斷值低於 3.00")))) | K26: =IF(E26="","",(SUMIFS(平方!P$2:P$501,計分!$AQ$2:$AQ$501,"高")-$C$7*E26^2)/($C$7-1)) | L26: =IF(F26="","",(SUMIFS(平方!P$2:P$501,計分!$AQ$2:$AQ$501,"低")-$C$8*F26^2)/($C$8-1))
A27: =反向題設定!B20 | B27: =IF(A27="","",IF(反向題設定!C20="是","是","")) | C27: =IF(OR(A27="",COUNT(計分!Q$2:Q$501)<2),"",AVERAGE(計分!Q$2:Q$501)) | D27: =IF(C27="","",STDEV(計分!Q$2:Q$501)) | E27: =IF(OR(C27="",$C$7<2),"",AVERAGEIFS(計分!Q$2:Q$501,計分!$AQ$2:$AQ$501,"高")) | F27: =IF(OR(C27="",$C$8<2),"",AVERAGEIFS(計分!Q$2:Q$501,計分!$AQ$2:$AQ$501,"低")) | G27: =IF(OR(E27="",F27=""),"",IF(K27/$C$7+L27/$C$8=0,"",(E27-F27)/SQRT(K27/$C$7+L27/$C$8))) | H27: =IF(C27="","",CORREL(計分!Q$2:Q$501,校正總分!Q$2:Q$501)) | I27: =IF(OR(C27="",$C$9=""),"",(COUNT($C$12:$C$51)-1)/(COUNT($C$12:$C$51)-2)*(1-(SUMSQ($D$12:$D$51)-D27^2)/VAR(校正總分!Q$2:Q$501))) | J27: =IF(OR(G27="",H27=""),"",IF(H27<0,"檢查：負相關，確認是否漏了反向計分",IF(AND(G27>=3,H27>=0.3),IF(I27>$C$9,"保留；刪除後 α 略升，對照因素分析","保留"),IF(H27<0.3,"檢查：校正題總相關低於 .30","檢查：決斷值低於 3.00")))) | K27: =IF(E27="","",(SUMIFS(平方!Q$2:Q$501,計分!$AQ$2:$AQ$501,"高")-$C$7*E27^2)/($C$7-1)) | L27: =IF(F27="","",(SUMIFS(平方!Q$2:Q$501,計分!$AQ$2:$AQ$501,"低")-$C$8*F27^2)/($C$8-1))
A28: =反向題設定!B21 | B28: =IF(A28="","",IF(反向題設定!C21="是","是","")) | C28: =IF(OR(A28="",COUNT(計分!R$2:R$501)<2),"",AVERAGE(計分!R$2:R$501)) | D28: =IF(C28="","",STDEV(計分!R$2:R$501)) | E28: =IF(OR(C28="",$C$7<2),"",AVERAGEIFS(計分!R$2:R$501,計分!$AQ$2:$AQ$501,"高")) | F28: =IF(OR(C28="",$C$8<2),"",AVERAGEIFS(計分!R$2:R$501,計分!$AQ$2:$AQ$501,"低")) | G28: =IF(OR(E28="",F28=""),"",IF(K28/$C$7+L28/$C$8=0,"",(E28-F28)/SQRT(K28/$C$7+L28/$C$8))) | H28: =IF(C28="","",CORREL(計分!R$2:R$501,校正總分!R$2:R$501)) | I28: =IF(OR(C28="",$C$9=""),"",(COUNT($C$12:$C$51)-1)/(COUNT($C$12:$C$51)-2)*(1-(SUMSQ($D$12:$D$51)-D28^2)/VAR(校正總分!R$2:R$501))) | J28: =IF(OR(G28="",H28=""),"",IF(H28<0,"檢查：負相關，確認是否漏了反向計分",IF(AND(G28>=3,H28>=0.3),IF(I28>$C$9,"保留；刪除後 α 略升，對照因素分析","保留"),IF(H28<0.3,"檢查：校正題總相關低於 .30","檢查：決斷值低於 3.00")))) | K28: =IF(E28="","",(SUMIFS(平方!R$2:R$501,計分!$AQ$2:$AQ$501,"高")-$C$7*E28^2)/($C$7-1)) | L28: =IF(F28="","",(SUMIFS(平方!R$2:R$501,計分!$AQ$2:$AQ$501,"低")-$C$8*F28^2)/($C$8-1))
A29: =反向題設定!B22 | B29: =IF(A29="","",IF(反向題設定!C22="是","是","")) | C29: =IF(OR(A29="",COUNT(計分!S$2:S$501)<2),"",AVERAGE(計分!S$2:S$501)) | D29: =IF(C29="","",STDEV(計分!S$2:S$501)) | E29: =IF(OR(C29="",$C$7<2),"",AVERAGEIFS(計分!S$2:S$501,計分!$AQ$2:$AQ$501,"高")) | F29: =IF(OR(C29="",$C$8<2),"",AVERAGEIFS(計分!S$2:S$501,計分!$AQ$2:$AQ$501,"低")) | G29: =IF(OR(E29="",F29=""),"",IF(K29/$C$7+L29/$C$8=0,"",(E29-F29)/SQRT(K29/$C$7+L29/$C$8))) | H29: =IF(C29="","",CORREL(計分!S$2:S$501,校正總分!S$2:S$501)) | I29: =IF(OR(C29="",$C$9=""),"",(COUNT($C$12:$C$51)-1)/(COUNT($C$12:$C$51)-2)*(1-(SUMSQ($D$12:$D$51)-D29^2)/VAR(校正總分!S$2:S$501))) | J29: =IF(OR(G29="",H29=""),"",IF(H29<0,"檢查：負相關，確認是否漏了反向計分",IF(AND(G29>=3,H29>=0.3),IF(I29>$C$9,"保留；刪除後 α 略升，對照因素分析","保留"),IF(H29<0.3,"檢查：校正題總相關低於 .30","檢查：決斷值低於 3.00")))) | K29: =IF(E29="","",(SUMIFS(平方!S$2:S$501,計分!$AQ$2:$AQ$501,"高")-$C$7*E29^2)/($C$7-1)) | L29: =IF(F29="","",(SUMIFS(平方!S$2:S$501,計分!$AQ$2:$AQ$501,"低")-$C$8*F29^2)/($C$8-1))
A30: =反向題設定!B23 | B30: =IF(A30="","",IF(反向題設定!C23="是","是","")) | C30: =IF(OR(A30="",COUNT(計分!T$2:T$501)<2),"",AVERAGE(計分!T$2:T$501)) | D30: =IF(C30="","",STDEV(計分!T$2:T$501)) | E30: =IF(OR(C30="",$C$7<2),"",AVERAGEIFS(計分!T$2:T$501,計分!$AQ$2:$AQ$501,"高")) | F30: =IF(OR(C30="",$C$8<2),"",AVERAGEIFS(計分!T$2:T$501,計分!$AQ$2:$AQ$501,"低")) | G30: =IF(OR(E30="",F30=""),"",IF(K30/$C$7+L30/$C$8=0,"",(E30-F30)/SQRT(K30/$C$7+L30/$C$8))) | H30: =IF(C30="","",CORREL(計分!T$2:T$501,校正總分!T$2:T$501)) | I30: =IF(OR(C30="",$C$9=""),"",(COUNT($C$12:$C$51)-1)/(COUNT($C$12:$C$51)-2)*(1-(SUMSQ($D$12:$D$51)-D30^2)/VAR(校正總分!T$2:T$501))) | J30: =IF(OR(G30="",H30=""),"",IF(H30<0,"檢查：負相關，確認是否漏了反向計分",IF(AND(G30>=3,H30>=0.3),IF(I30>$C$9,"保留；刪除後 α 略升，對照因素分析","保留"),IF(H30<0.3,"檢查：校正題總相關低於 .30","檢查：決斷值低於 3.00")))) | K30: =IF(E30="","",(SUMIFS(平方!T$2:T$501,計分!$AQ$2:$AQ$501,"高")-$C$7*E30^2)/($C$7-1)) | L30: =IF(F30="","",(SUMIFS(平方!T$2:T$501,計分!$AQ$2:$AQ$501,"低")-$C$8*F30^2)/($C$8-1))
A31: =反向題設定!B24 | B31: =IF(A31="","",IF(反向題設定!C24="是","是","")) | C31: =IF(OR(A31="",COUNT(計分!U$2:U$501)<2),"",AVERAGE(計分!U$2:U$501)) | D31: =IF(C31="","",STDEV(計分!U$2:U$501)) | E31: =IF(OR(C31="",$C$7<2),"",AVERAGEIFS(計分!U$2:U$501,計分!$AQ$2:$AQ$501,"高")) | F31: =IF(OR(C31="",$C$8<2),"",AVERAGEIFS(計分!U$2:U$501,計分!$AQ$2:$AQ$501,"低")) | G31: =IF(OR(E31="",F31=""),"",IF(K31/$C$7+L31/$C$8=0,"",(E31-F31)/SQRT(K31/$C$7+L31/$C$8))) | H31: =IF(C31="","",CORREL(計分!U$2:U$501,校正總分!U$2:U$501)) | I31: =IF(OR(C31="",$C$9=""),"",(COUNT($C$12:$C$51)-1)/(COUNT($C$12:$C$51)-2)*(1-(SUMSQ($D$12:$D$51)-D31^2)/VAR(校正總分!U$2:U$501))) | J31: =IF(OR(G31="",H31=""),"",IF(H31<0,"檢查：負相關，確認是否漏了反向計分",IF(AND(G31>=3,H31>=0.3),IF(I31>$C$9,"保留；刪除後 α 略升，對照因素分析","保留"),IF(H31<0.3,"檢查：校正題總相關低於 .30","檢查：決斷值低於 3.00")))) | K31: =IF(E31="","",(SUMIFS(平方!U$2:U$501,計分!$AQ$2:$AQ$501,"高")-$C$7*E31^2)/($C$7-1)) | L31: =IF(F31="","",(SUMIFS(平方!U$2:U$501,計分!$AQ$2:$AQ$501,"低")-$C$8*F31^2)/($C$8-1))
A32: =反向題設定!B25 | B32: =IF(A32="","",IF(反向題設定!C25="是","是","")) | C32: =IF(OR(A32="",COUNT(計分!V$2:V$501)<2),"",AVERAGE(計分!V$2:V$501)) | D32: =IF(C32="","",STDEV(計分!V$2:V$501)) | E32: =IF(OR(C32="",$C$7<2),"",AVERAGEIFS(計分!V$2:V$501,計分!$AQ$2:$AQ$501,"高")) | F32: =IF(OR(C32="",$C$8<2),"",AVERAGEIFS(計分!V$2:V$501,計分!$AQ$2:$AQ$501,"低")) | G32: =IF(OR(E32="",F32=""),"",IF(K32/$C$7+L32/$C$8=0,"",(E32-F32)/SQRT(K32/$C$7+L32/$C$8))) | H32: =IF(C32="","",CORREL(計分!V$2:V$501,校正總分!V$2:V$501)) | I32: =IF(OR(C32="",$C$9=""),"",(COUNT($C$12:$C$51)-1)/(COUNT($C$12:$C$51)-2)*(1-(SUMSQ($D$12:$D$51)-D32^2)/VAR(校正總分!V$2:V$501))) | J32: =IF(OR(G32="",H32=""),"",IF(H32<0,"檢查：負相關，確認是否漏了反向計分",IF(AND(G32>=3,H32>=0.3),IF(I32>$C$9,"保留；刪除後 α 略升，對照因素分析","保留"),IF(H32<0.3,"檢查：校正題總相關低於 .30","檢查：決斷值低於 3.00")))) | K32: =IF(E32="","",(SUMIFS(平方!V$2:V$501,計分!$AQ$2:$AQ$501,"高")-$C$7*E32^2)/($C$7-1)) | L32: =IF(F32="","",(SUMIFS(平方!V$2:V$501,計分!$AQ$2:$AQ$501,"低")-$C$8*F32^2)/($C$8-1))
A33: =反向題設定!B26 | B33: =IF(A33="","",IF(反向題設定!C26="是","是","")) | C33: =IF(OR(A33="",COUNT(計分!W$2:W$501)<2),"",AVERAGE(計分!W$2:W$501)) | D33: =IF(C33="","",STDEV(計分!W$2:W$501)) | E33: =IF(OR(C33="",$C$7<2),"",AVERAGEIFS(計分!W$2:W$501,計分!$AQ$2:$AQ$501,"高")) | F33: =IF(OR(C33="",$C$8<2),"",AVERAGEIFS(計分!W$2:W$501,計分!$AQ$2:$AQ$501,"低")) | G33: =IF(OR(E33="",F33=""),"",IF(K33/$C$7+L33/$C$8=0,"",(E33-F33)/SQRT(K33/$C$7+L33/$C$8))) | H33: =IF(C33="","",CORREL(計分!W$2:W$501,校正總分!W$2:W$501)) | I33: =IF(OR(C33="",$C$9=""),"",(COUNT($C$12:$C$51)-1)/(COUNT($C$12:$C$51)-2)*(1-(SUMSQ($D$12:$D$51)-D33^2)/VAR(校正總分!W$2:W$501))) | J33: =IF(OR(G33="",H33=""),"",IF(H33<0,"檢查：負相關，確認是否漏了反向計分",IF(AND(G33>=3,H33>=0.3),IF(I33>$C$9,"保留；刪除後 α 略升，對照因素分析","保留"),IF(H33<0.3,"檢查：校正題總相關低於 .30","檢查：決斷值低於 3.00")))) | K33: =IF(E33="","",(SUMIFS(平方!W$2:W$501,計分!$AQ$2:$AQ$501,"高")-$C$7*E33^2)/($C$7-1)) | L33: =IF(F33="","",(SUMIFS(平方!W$2:W$501,計分!$AQ$2:$AQ$501,"低")-$C$8*F33^2)/($C$8-1))
A34: =反向題設定!B27 | B34: =IF(A34="","",IF(反向題設定!C27="是","是","")) | C34: =IF(OR(A34="",COUNT(計分!X$2:X$501)<2),"",AVERAGE(計分!X$2:X$501)) | D34: =IF(C34="","",STDEV(計分!X$2:X$501)) | E34: =IF(OR(C34="",$C$7<2),"",AVERAGEIFS(計分!X$2:X$501,計分!$AQ$2:$AQ$501,"高")) | F34: =IF(OR(C34="",$C$8<2),"",AVERAGEIFS(計分!X$2:X$501,計分!$AQ$2:$AQ$501,"低")) | G34: =IF(OR(E34="",F34=""),"",IF(K34/$C$7+L34/$C$8=0,"",(E34-F34)/SQRT(K34/$C$7+L34/$C$8))) | H34: =IF(C34="","",CORREL(計分!X$2:X$501,校正總分!X$2:X$501)) | I34: =IF(OR(C34="",$C$9=""),"",(COUNT($C$12:$C$51)-1)/(COUNT($C$12:$C$51)-2)*(1-(SUMSQ($D$12:$D$51)-D34^2)/VAR(校正總分!X$2:X$501))) | J34: =IF(OR(G34="",H34=""),"",IF(H34<0,"檢查：負相關，確認是否漏了反向計分",IF(AND(G34>=3,H34>=0.3),IF(I34>$C$9,"保留；刪除後 α 略升，對照因素分析","保留"),IF(H34<0.3,"檢查：校正題總相關低於 .30","檢查：決斷值低於 3.00")))) | K34: =IF(E34="","",(SUMIFS(平方!X$2:X$501,計分!$AQ$2:$AQ$501,"高")-$C$7*E34^2)/($C$7-1)) | L34: =IF(F34="","",(SUMIFS(平方!X$2:X$501,計分!$AQ$2:$AQ$501,"低")-$C$8*F34^2)/($C$8-1))
A35: =反向題設定!B28 | B35: =IF(A35="","",IF(反向題設定!C28="是","是","")) | C35: =IF(OR(A35="",COUNT(計分!Y$2:Y$501)<2),"",AVERAGE(計分!Y$2:Y$501)) | D35: =IF(C35="","",STDEV(計分!Y$2:Y$501)) | E35: =IF(OR(C35="",$C$7<2),"",AVERAGEIFS(計分!Y$2:Y$501,計分!$AQ$2:$AQ$501,"高")) | F35: =IF(OR(C35="",$C$8<2),"",AVERAGEIFS(計分!Y$2:Y$501,計分!$AQ$2:$AQ$501,"低")) | G35: =IF(OR(E35="",F35=""),"",IF(K35/$C$7+L35/$C$8=0,"",(E35-F35)/SQRT(K35/$C$7+L35/$C$8))) | H35: =IF(C35="","",CORREL(計分!Y$2:Y$501,校正總分!Y$2:Y$501)) | I35: =IF(OR(C35="",$C$9=""),"",(COUNT($C$12:$C$51)-1)/(COUNT($C$12:$C$51)-2)*(1-(SUMSQ($D$12:$D$51)-D35^2)/VAR(校正總分!Y$2:Y$501))) | J35: =IF(OR(G35="",H35=""),"",IF(H35<0,"檢查：負相關，確認是否漏了反向計分",IF(AND(G35>=3,H35>=0.3),IF(I35>$C$9,"保留；刪除後 α 略升，對照因素分析","保留"),IF(H35<0.3,"檢查：校正題總相關低於 .30","檢查：決斷值低於 3.00")))) | K35: =IF(E35="","",(SUMIFS(平方!Y$2:Y$501,計分!$AQ$2:$AQ$501,"高")-$C$7*E35^2)/($C$7-1)) | L35: =IF(F35="","",(SUMIFS(平方!Y$2:Y$501,計分!$AQ$2:$AQ$501,"低")-$C$8*F35^2)/($C$8-1))
A36: =反向題設定!B29 | B36: =IF(A36="","",IF(反向題設定!C29="是","是","")) | C36: =IF(OR(A36="",COUNT(計分!Z$2:Z$501)<2),"",AVERAGE(計分!Z$2:Z$501)) | D36: =IF(C36="","",STDEV(計分!Z$2:Z$501)) | E36: =IF(OR(C36="",$C$7<2),"",AVERAGEIFS(計分!Z$2:Z$501,計分!$AQ$2:$AQ$501,"高")) | F36: =IF(OR(C36="",$C$8<2),"",AVERAGEIFS(計分!Z$2:Z$501,計分!$AQ$2:$AQ$501,"低")) | G36: =IF(OR(E36="",F36=""),"",IF(K36/$C$7+L36/$C$8=0,"",(E36-F36)/SQRT(K36/$C$7+L36/$C$8))) | H36: =IF(C36="","",CORREL(計分!Z$2:Z$501,校正總分!Z$2:Z$501)) | I36: =IF(OR(C36="",$C$9=""),"",(COUNT($C$12:$C$51)-1)/(COUNT($C$12:$C$51)-2)*(1-(SUMSQ($D$12:$D$51)-D36^2)/VAR(校正總分!Z$2:Z$501))) | J36: =IF(OR(G36="",H36=""),"",IF(H36<0,"檢查：負相關，確認是否漏了反向計分",IF(AND(G36>=3,H36>=0.3),IF(I36>$C$9,"保留；刪除後 α 略升，對照因素分析","保留"),IF(H36<0.3,"檢查：校正題總相關低於 .30","檢查：決斷值低於 3.00")))) | K36: =IF(E36="","",(SUMIFS(平方!Z$2:Z$501,計分!$AQ$2:$AQ$501,"高")-$C$7*E36^2)/($C$7-1)) | L36: =IF(F36="","",(SUMIFS(平方!Z$2:Z$501,計分!$AQ$2:$AQ$501,"低")-$C$8*F36^2)/($C$8-1))
A37: =反向題設定!B30 | B37: =IF(A37="","",IF(反向題設定!C30="是","是","")) | C37: =IF(OR(A37="",COUNT(計分!AA$2:AA$501)<2),"",AVERAGE(計分!AA$2:AA$501)) | D37: =IF(C37="","",STDEV(計分!AA$2:AA$501)) | E37: =IF(OR(C37="",$C$7<2),"",AVERAGEIFS(計分!AA$2:AA$501,計分!$AQ$2:$AQ$501,"高")) | F37: =IF(OR(C37="",$C$8<2),"",AVERAGEIFS(計分!AA$2:AA$501,計分!$AQ$2:$AQ$501,"低")) | G37: =IF(OR(E37="",F37=""),"",IF(K37/$C$7+L37/$C$8=0,"",(E37-F37)/SQRT(K37/$C$7+L37/$C$8))) | H37: =IF(C37="","",CORREL(計分!AA$2:AA$501,校正總分!AA$2:AA$501)) | I37: =IF(OR(C37="",$C$9=""),"",(COUNT($C$12:$C$51)-1)/(COUNT($C$12:$C$51)-2)*(1-(SUMSQ($D$12:$D$51)-D37^2)/VAR(校正總分!AA$2:AA$501))) | J37: =IF(OR(G37="",H37=""),"",IF(H37<0,"檢查：負相關，確認是否漏了反向計分",IF(AND(G37>=3,H37>=0.3),IF(I37>$C$9,"保留；刪除後 α 略升，對照因素分析","保留"),IF(H37<0.3,"檢查：校正題總相關低於 .30","檢查：決斷值低於 3.00")))) | K37: =IF(E37="","",(SUMIFS(平方!AA$2:AA$501,計分!$AQ$2:$AQ$501,"高")-$C$7*E37^2)/($C$7-1)) | L37: =IF(F37="","",(SUMIFS(平方!AA$2:AA$501,計分!$AQ$2:$AQ$501,"低")-$C$8*F37^2)/($C$8-1))
A38: =反向題設定!B31 | B38: =IF(A38="","",IF(反向題設定!C31="是","是","")) | C38: =IF(OR(A38="",COUNT(計分!AB$2:AB$501)<2),"",AVERAGE(計分!AB$2:AB$501)) | D38: =IF(C38="","",STDEV(計分!AB$2:AB$501)) | E38: =IF(OR(C38="",$C$7<2),"",AVERAGEIFS(計分!AB$2:AB$501,計分!$AQ$2:$AQ$501,"高")) | F38: =IF(OR(C38="",$C$8<2),"",AVERAGEIFS(計分!AB$2:AB$501,計分!$AQ$2:$AQ$501,"低")) | G38: =IF(OR(E38="",F38=""),"",IF(K38/$C$7+L38/$C$8=0,"",(E38-F38)/SQRT(K38/$C$7+L38/$C$8))) | H38: =IF(C38="","",CORREL(計分!AB$2:AB$501,校正總分!AB$2:AB$501)) | I38: =IF(OR(C38="",$C$9=""),"",(COUNT($C$12:$C$51)-1)/(COUNT($C$12:$C$51)-2)*(1-(SUMSQ($D$12:$D$51)-D38^2)/VAR(校正總分!AB$2:AB$501))) | J38: =IF(OR(G38="",H38=""),"",IF(H38<0,"檢查：負相關，確認是否漏了反向計分",IF(AND(G38>=3,H38>=0.3),IF(I38>$C$9,"保留；刪除後 α 略升，對照因素分析","保留"),IF(H38<0.3,"檢查：校正題總相關低於 .30","檢查：決斷值低於 3.00")))) | K38: =IF(E38="","",(SUMIFS(平方!AB$2:AB$501,計分!$AQ$2:$AQ$501,"高")-$C$7*E38^2)/($C$7-1)) | L38: =IF(F38="","",(SUMIFS(平方!AB$2:AB$501,計分!$AQ$2:$AQ$501,"低")-$C$8*F38^2)/($C$8-1))
A39: =反向題設定!B32 | B39: =IF(A39="","",IF(反向題設定!C32="是","是","")) | C39: =IF(OR(A39="",COUNT(計分!AC$2:AC$501)<2),"",AVERAGE(計分!AC$2:AC$501)) | D39: =IF(C39="","",STDEV(計分!AC$2:AC$501)) | E39: =IF(OR(C39="",$C$7<2),"",AVERAGEIFS(計分!AC$2:AC$501,計分!$AQ$2:$AQ$501,"高")) | F39: =IF(OR(C39="",$C$8<2),"",AVERAGEIFS(計分!AC$2:AC$501,計分!$AQ$2:$AQ$501,"低")) | G39: =IF(OR(E39="",F39=""),"",IF(K39/$C$7+L39/$C$8=0,"",(E39-F39)/SQRT(K39/$C$7+L39/$C$8))) | H39: =IF(C39="","",CORREL(計分!AC$2:AC$501,校正總分!AC$2:AC$501)) | I39: =IF(OR(C39="",$C$9=""),"",(COUNT($C$12:$C$51)-1)/(COUNT($C$12:$C$51)-2)*(1-(SUMSQ($D$12:$D$51)-D39^2)/VAR(校正總分!AC$2:AC$501))) | J39: =IF(OR(G39="",H39=""),"",IF(H39<0,"檢查：負相關，確認是否漏了反向計分",IF(AND(G39>=3,H39>=0.3),IF(I39>$C$9,"保留；刪除後 α 略升，對照因素分析","保留"),IF(H39<0.3,"檢查：校正題總相關低於 .30","檢查：決斷值低於 3.00")))) | K39: =IF(E39="","",(SUMIFS(平方!AC$2:AC$501,計分!$AQ$2:$AQ$501,"高")-$C$7*E39^2)/($C$7-1)) | L39: =IF(F39="","",(SUMIFS(平方!AC$2:AC$501,計分!$AQ$2:$AQ$501,"低")-$C$8*F39^2)/($C$8-1))
A40: =反向題設定!B33 | B40: =IF(A40="","",IF(反向題設定!C33="是","是","")) | C40: =IF(OR(A40="",COUNT(計分!AD$2:AD$501)<2),"",AVERAGE(計分!AD$2:AD$501)) | D40: =IF(C40="","",STDEV(計分!AD$2:AD$501)) | E40: =IF(OR(C40="",$C$7<2),"",AVERAGEIFS(計分!AD$2:AD$501,計分!$AQ$2:$AQ$501,"高")) | F40: =IF(OR(C40="",$C$8<2),"",AVERAGEIFS(計分!AD$2:AD$501,計分!$AQ$2:$AQ$501,"低")) | G40: =IF(OR(E40="",F40=""),"",IF(K40/$C$7+L40/$C$8=0,"",(E40-F40)/SQRT(K40/$C$7+L40/$C$8))) | H40: =IF(C40="","",CORREL(計分!AD$2:AD$501,校正總分!AD$2:AD$501)) | I40: =IF(OR(C40="",$C$9=""),"",(COUNT($C$12:$C$51)-1)/(COUNT($C$12:$C$51)-2)*(1-(SUMSQ($D$12:$D$51)-D40^2)/VAR(校正總分!AD$2:AD$501))) | J40: =IF(OR(G40="",H40=""),"",IF(H40<0,"檢查：負相關，確認是否漏了反向計分",IF(AND(G40>=3,H40>=0.3),IF(I40>$C$9,"保留；刪除後 α 略升，對照因素分析","保留"),IF(H40<0.3,"檢查：校正題總相關低於 .30","檢查：決斷值低於 3.00")))) | K40: =IF(E40="","",(SUMIFS(平方!AD$2:AD$501,計分!$AQ$2:$AQ$501,"高")-$C$7*E40^2)/($C$7-1)) | L40: =IF(F40="","",(SUMIFS(平方!AD$2:AD$501,計分!$AQ$2:$AQ$501,"低")-$C$8*F40^2)/($C$8-1))
A41: =反向題設定!B34 | B41: =IF(A41="","",IF(反向題設定!C34="是","是","")) | C41: =IF(OR(A41="",COUNT(計分!AE$2:AE$501)<2),"",AVERAGE(計分!AE$2:AE$501)) | D41: =IF(C41="","",STDEV(計分!AE$2:AE$501)) | E41: =IF(OR(C41="",$C$7<2),"",AVERAGEIFS(計分!AE$2:AE$501,計分!$AQ$2:$AQ$501,"高")) | F41: =IF(OR(C41="",$C$8<2),"",AVERAGEIFS(計分!AE$2:AE$501,計分!$AQ$2:$AQ$501,"低")) | G41: =IF(OR(E41="",F41=""),"",IF(K41/$C$7+L41/$C$8=0,"",(E41-F41)/SQRT(K41/$C$7+L41/$C$8))) | H41: =IF(C41="","",CORREL(計分!AE$2:AE$501,校正總分!AE$2:AE$501)) | I41: =IF(OR(C41="",$C$9=""),"",(COUNT($C$12:$C$51)-1)/(COUNT($C$12:$C$51)-2)*(1-(SUMSQ($D$12:$D$51)-D41^2)/VAR(校正總分!AE$2:AE$501))) | J41: =IF(OR(G41="",H41=""),"",IF(H41<0,"檢查：負相關，確認是否漏了反向計分",IF(AND(G41>=3,H41>=0.3),IF(I41>$C$9,"保留；刪除後 α 略升，對照因素分析","保留"),IF(H41<0.3,"檢查：校正題總相關低於 .30","檢查：決斷值低於 3.00")))) | K41: =IF(E41="","",(SUMIFS(平方!AE$2:AE$501,計分!$AQ$2:$AQ$501,"高")-$C$7*E41^2)/($C$7-1)) | L41: =IF(F41="","",(SUMIFS(平方!AE$2:AE$501,計分!$AQ$2:$AQ$501,"低")-$C$8*F41^2)/($C$8-1))
...

Sheet 計分
A1: 編號 | B1: =IF(原始資料!B1="","",原始資料!B1) | C1: =IF(原始資料!C1="","",原始資料!C1) | D1: =IF(原始資料!D1="","",原始資料!D1) | E1: =IF(原始資料!E1="","",原始資料!E1) | F1: =IF(原始資料!F1="","",原始資料!F1) | G1: =IF(原始資料!G1="","",原始資料!G1) | H1: =IF(原始資料!H1="","",原始資料!H1) | I1: =IF(原始資料!I1="","",原始資料!I1) | ... AO1: =IF(原始資料!AO1="","",原始資料!AO1) | AP1: 總分 | AQ1: 組別
A2: =IF(原始資料!A2="","",原始資料!A2) | B2: =IF(原始資料!B2="","",IF(反向題設定!$C$5="是",反向題設定!$B$2+1-原始資料!B2,原始資料!B2)) | C2: =IF(原始資料!C2="","",IF(反向題設定!$C$6="是",反向題設定!$B$2+1-原始資料!C2,原始資料!C2)) | D2: =IF(原始資料!D2="","",IF(反向題設定!$C$7="是",反向題設定!$B$2+1-原始資料!D2,原始資料!D2)) | E2: =IF(原始資料!E2="","",IF(反向題設定!$C$8="是",反向題設定!$B$2+1-原始資料!E2,原始資料!E2)) | F2: =IF(原始資料!F2="","",IF(反向題設定!$C$9="是",反向題設定!$B$2+1-原始資料!F2,原始資料!F2)) | G2: =IF(原始資料!G2="","",IF(反向題設定!$C$10="是",反向題設定!$B$2+1-原始資料!G2,原始資料!G2)) | H2: =IF(原始資料!H2="","",IF(反向題設定!$C$11="是",反向題設定!$B$2+1-原始資料!H2,原始資料!H2)) | I2: =IF(原始資料!I2="","",IF(反向題設定!$C$12="是",反向題設定!$B$2+1-原始資料!I2,原始資料!I2)) | J2: =IF(原始資料!J2="","",IF(反向題設定!$C$13="是",反向題設定!$B$2+1-原始資料!J2,原始資料!J2)) | K2: =IF(原始資料!K2="","",IF(反向題設定!$C$14="是",反向題設定!$B$2+1-原始資料!K2,原始資料!K2)) | L2: =IF(原始資料!L2="","",IF(反向題設定!$C$15="是",反向題設定!$B$2+1-原始資料!L2,原始資料!L2)) | M2: =IF(原始資料!M2="","",IF(反向題設定!$C$16="是",反向題設定!$B$2+1-原始資料!M2,原始資料!M2)) | N2: =IF(原始資料!N2="","",IF(反向題設定!$C$17="是",反向題設定!$B$2+1-原始資料!N2,原始資料!N2)) | O2: =IF(原始資料!O2="","",IF(反向題設定!$C$18="是",反向題設定!$B$2+1-原始資料!O2,原始資料!O2)) | P2: =IF(原始資料!P2="","",IF(反向題設定!$C$19="是",反向題設定!$B$2+1-原始資料!P2,原始資料!P2)) | Q2: =IF(原始資料!Q2="","",IF(反向題設定!$C$20="是",反向題設定!$B$2+1-原始資料!Q2,原始資料!Q2)) | R2: =IF(原始資料!R2="","",IF(反向題設定!$C$21="是",反向題設定!$B$2+1-原始資料!R2,原始資料!R2)) | S2: =IF(原始資料!S2="","",IF(反向題設定!$C$22="是",反向題設定!$B$2+1-原始資料!S2,原始資料!S2)) | T2: =IF(原始資料!T2="","",IF(反向題設定!$C$23="是",反向題設定!$B$2+1-原始資料!T2,原始資料!T2)) | U2: =IF(原始資料!U2="","",IF(反向題設定!$C$24="是",反向題設定!$B$2+1-原始資料!U2,原始資料!U2)) | V2: =IF(原始資料!V2="","",IF(反向題設定!$C$25="是",反向題設定!$B$2+1-原始資料!V2,原始資料!V2)) | W2: =IF(原始資料!W2="","",IF(反向題設定!$C$26="是",反向題設定!$B$2+1-原始資料!W2,原始資料!W2)) | X2: =IF(原始資料!X2="","",IF(反向題設定!$C$27="是",反向題設定!$B$2+1-原始資料!X2,原始資料!X2)) | Y2: =IF(原始資料!Y2="","",IF(反向題設定!$C$28="是",反向題設定!$B$2+1-原始資料!Y2,原始資料!Y2)) | Z2: =IF(原始資料!Z2="","",IF(反向題設定!$C$29="是",反向題設定!$B$2+1-原始資料!Z2,原始資料!Z2)) | AA2: =IF(原始資料!AA2="","",IF(反向題設定!$C$30="是",反向題設定!$B$2+1-原始資料!AA2,原始資料!AA2)) | AB2: =IF(原始資料!AB2="","",IF(反向題設定!$C$31="是",反向題設定!$B$2+1-原始資料!AB2,原始資料!AB2)) | AC2: =IF(原始資料!AC2="","",IF(反向題設定!$C$32="是",反向題設定!$B$2+1-原始資料!AC2,原始資料!AC2)) | AD2: =IF(原始資料!AD2="","",IF(反向題設定!$C$33="是",反向題設定!$B$2+1-原始資料!AD2,原始資料!AD2)) | AE2: =IF(原始資料!AE2="","",IF(反向題設定!$C$34="是",反向題設定!$B$2+1-原始資料!AE2,原始資料!AE2)) | AF2: =IF(原始資料!AF2="","",IF(反向題設定!$C$35="是",反向題設定!$B$2+1-原始資料!AF2,原始資料!AF2)) | AG2: =IF(原始資料!AG2="","",IF(反向題設定!$C$36="是",反向題設定!$B$2+1-原始資料!AG2,原始資料!AG2)) | AH2: =IF(原始資料!AH2="","",IF(反向題設定!$C$37="是",反向題設定!$B$2+1-原始資料!AH2,原始資料!AH2)) | AI2: =IF(原始資料!AI2="","",IF(反向題設定!$C$38="是",反向題設定!$B$2+1-原始資料!AI2,原始資料!AI2)) | AJ2: =IF(原始資料!AJ2="","",IF(反向題設定!$C$39="是",反向題設定!$B$2+1-原始資料!AJ2,原始資料!AJ2)) | AK2: =IF(原始資料!AK2="","",IF(反向題設定!$C$40="是",反向題設定!$B$2+1-原始資料!AK2,原始資料!AK2)) | AL2: =IF(原始資料!AL2="","",IF(反向題設定!$C$41="是",反向題設定!$B$2+1-原始資料!AL2,原始資料!AL2)) | AM2: =IF(原始資料!AM2="","",IF(反向題設定!$C$42="是",反向題設定!$B$2+1-原始資料!AM2,原始資料!AM2)) | AN2: =IF(原始資料!AN2="","",IF(反向題設定!$C$43="是",反向題設定!$B$2+1-原始資料!AN2,原始資料!AN2)) | AO2: =IF(原始資料!AO2="","",IF(反向題設定!$C$44="是",反向題設定!$B$2+1-原始資料!AO2,原始資料!AO2)) | AP2: =IF(COUNT(B2:AO2)=0,"",SUM(B2:AO2)) | AQ2: =IF(AP2="","",IF(AP2>=項目分析!$C$5,"高",IF(AP2<=項目分析!$C$6,"低","")))
A3: =IF(原始資料!A3="","",原始資料!A3) | B3: =IF(原始資料!B3="","",IF(反向題設定!$C$5="是",反向題設定!$B$2+1-原始資料!B3,原始資料!B3)) | C3: =IF(原始資料!C3="","",IF(反向題設定!$C$6="是",反向題設定!$B$2+1-原始資料!C3,原始資料!C3)) | D3: =IF(原始資料!D3="","",IF(反向題設定!$C$7="是",反向題設定!$B$2+1-原始資料!D3,原始資料!D3)) | E3: =IF(原始資料!E3="","",IF(反向題設定!$C$8="是",反向題設定!$B$2+1-原始資料!E3,原始資料!E3)) | F3: =IF(原始資料!F3="","",IF(反向題設定!$C$9="是",反向題設定!$B$2+1-原始資料!F3,原始資料!F3)) | G3: =IF(原始資料!G3="","",IF(反向題設定!$C$10="是",反向題設定!$B$2+1-原始資料!G3,原始資料!G3)) | H3: =IF(原始資料!H3="","",IF(反向題設定!$C$11="是",反向題設定!$B$2+1-原始資料!H3,原始資料!H3)) | I3: =IF(原始資料!I3="","",IF(反向題設定!$C$12="是",反向題設定!$B$2+1-原始資料!I3,原始資料!I3)) | J3: =IF(原始資料!J3="","",IF(反向題設定!$C$13="是",反向題設定!$B$2+1-原始資料!J3,原始資料!J3)) | K3: =IF(原始資料!K3="","",IF(反向題設定!$C$14="是",反向題設定!$B$2+1-原始資料!K3,原始資料!K3)) | L3: =IF(原始資料!L3="","",IF(反向題設定!$C$15="是",反向題設定!$B$2+1-原始資料!L3,原始資料!L3)) | M3: =IF(原始資料!M3="","",IF(反向題設定!$C$16="是",反向題設定!$B$2+1-原始資料!M3,原始資料!M3)) | N3: =IF(原始資料!N3="","",IF(反向題設定!$C$17="是",反向題設定!$B$2+1-原始資料!N3,原始資料!N3)) | O3: =IF(原始資料!O3="","",IF(反向題設定!$C$18="是",反向題設定!$B$2+1-原始資料!O3,原始資料!O3)) | P3: =IF(原始資料!P3="","",IF(反向題設定!$C$19="是",反向題設定!$B$2+1-原始資料!P3,原始資料!P3)) | Q3: =IF(原始資料!Q3="","",IF(反向題設定!$C$20="是",反向題設定!$B$2+1-原始資料!Q3,原始資料!Q3)) | R3: =IF(原始資料!R3="","",IF(反向題設定!$C$21="是",反向題設定!$B$2+1-原始資料!R3,原始資料!R3)) | S3: =IF(原始資料!S3="","",IF(反向題設定!$C$22="是",反向題設定!$B$2+1-原始資料!S3,原始資料!S3)) | T3: =IF(原始資料!T3="","",IF(反向題設定!$C$23="是",反向題設定!$B$2+1-原始資料!T3,原始資料!T3)) | U3: =IF(原始資料!U3="","",IF(反向題設定!$C$24="是",反向題設定!$B$2+1-原始資料!U3,原始資料!U3)) | V3: =IF(原始資料!V3="","",IF(反向題設定!$C$25="是",反向題設定!$B$2+1-原始資料!V3,原始資料!V3)) | W3: =IF(原始資料!W3="","",IF(反向題設定!$C$26="是",反向題設定!$B$2+1-原始資料!W3,原始資料!W3)) | X3: =IF(原始資料!X3="","",IF(反向題設定!$C$27="是",反向題設定!$B$2+1-原始資料!X3,原始資料!X3)) | Y3: =IF(原始資料!Y3="","",IF(反向題設定!$C$28="是",反向題設定!$B$2+1-原始資料!Y3,原始資料!Y3)) | Z3: =IF(原始資料!Z3="","",IF(反向題設定!$C$29="是",反向題設定!$B$2+1-原始資料!Z3,原始資料!Z3)) | AA3: =IF(原始資料!AA3="","",IF(反向題設定!$C$30="是",反向題設定!$B$2+1-原始資料!AA3,原始資料!AA3)) | AB3: =IF(原始資料!AB3="","",IF(反向題設定!$C$31="是",反向題設定!$B$2+1-原始資料!AB3,原始資料!AB3)) | AC3: =IF(原始資料!AC3="","",IF(反向題設定!$C$32="是",反向題設定!$B$2+1-原始資料!AC3,原始資料!AC3)) | AD3: =IF(原始資料!AD3="","",IF(反向題設定!$C$33="是",反向題設定!$B$2+1-原始資料!AD3,原始資料!AD3)) | AE3: =IF(原始資料!AE3="","",IF(反向題設定!$C$34="是",反向題設定!$B$2+1-原始資料!AE3,原始資料!AE3)) | AF3: =IF(原始資料!AF3="","",IF(反向題設定!$C$35="是",反向題設定!$B$2+1-原始資料!AF3,原始資料!AF3)) | AG3: =IF(原始資料!AG3="","",IF(反向題設定!$C$36="是",反向題設定!$B$2+1-原始資料!AG3,原始資料!AG3)) | AH3: =IF(原始資料!AH3="","",IF(反向題設定!$C$37="是",反向題設定!$B$2+1-原始資料!AH3,原始資料!AH3)) | AI3: =IF(原始資料!AI3="","",IF(反向題設定!$C$38="是",反向題設定!$B$2+1-原始資料!AI3,原始資料!AI3)) | AJ3: =IF(原始資料!AJ3="","",IF(反向題設定!$C$39="是",反向題設定!$B$2+1-原始資料!AJ3,原始資料!AJ3)) | AK3: =IF(原始資料!AK3="","",IF(反向題設定!$C$40="是",反向題設定!$B$2+1-原始資料!AK3,原始資料!AK3)) | AL3: =IF(原始資料!AL3="","",IF(反向題設定!$C$41="是",反向題設定!$B$2+1-原始資料!AL3,原始資料!AL3)) | AM3: =IF(原始資料!AM3="","",IF(反向題設定!$C$42="是",反向題設定!$B$2+1-原始資料!AM3,原始資料!AM3)) | AN3: =IF(原始資料!AN3="","",IF(反向題設定!$C$43="是",反向題設定!$B$2+1-原始資料!AN3,原始資料!AN3)) | AO3: =IF(原始資料!AO3="","",IF(反向題設定!$C$44="是",反向題設定!$B$2+1-原始資料!AO3,原始資料!AO3)) | AP3: =IF(COUNT(B3:AO3)=0,"",SUM(B3:AO3)) | AQ3: =IF(AP3="","",IF(AP3>=項目分析!$C$5,"高",IF(AP3<=項目分析!$C$6,"低","")))
A4: =IF(原始資料!A4="","",原始資料!A4) | B4: =IF(原始資料!B4="","",IF(反向題設定!$C$5="是",反向題設定!$B$2+1-原始資料!B4,原始資料!B4)) | C4: =IF(原始資料!C4="","",IF(反向題設定!$C$6="是",反向題設定!$B$2+1-原始資料!C4,原始資料!C4)) | D4: =IF(原始資料!D4="","",IF(反向題設定!$C$7="是",反向題設定!$B$2+1-原始資料!D4,原始資料!D4)) | E4: =IF(原始資料!E4="","",IF(反向題設定!$C$8="是",反向題設定!$B$2+1-原始資料!E4,原始資料!E4)) | F4: =IF(原始資料!F4="","",IF(反向題設定!$C$9="是",反向題設定!$B$2+1-原始資料!F4,原始資料!F4)) | G4: =IF(原始資料!G4="","",IF(反向題設定!$C$10="是",反向題設定!$B$2+1-原始資料!G4,原始資料!G4)) | H4: =IF(原始資料!H4="","",IF(反向題設定!$C$11="是",反向題設定!$B$2+1-原始資料!H4,原始資料!H4)) | I4: =IF(原始資料!I4="","",IF(反向題設定!$C$12="是",反向題設定!$B$2+1-原始資料!I4,原始資料!I4)) | J4: =IF(原始資料!J4="","",IF(反向題設定!$C$13="是",反向題設定!$B$2+1-原始資料!J4,原始資料!J4)) | K4: =IF(原始資料!K4="","",IF(反向題設定!$C$14="是",反向題設定!$B$2+1-原始資料!K4,原始資料!K4)) | L4: =IF(原始資料!L4="","",IF(反向題設定!$C$15="是",反向題設定!$B$2+1-原始資料!L4,原始資料!L4)) | M4: =IF(原始資料!M4="","",IF(反向題設定!$C$16="是",反向題設定!$B$2+1-原始資料!M4,原始資料!M4)) | N4: =IF(原始資料!N4="","",IF(反向題設定!$C$17="是",反向題設定!$B$2+1-原始資料!N4,原始資料!N4)) | O4: =IF(原始資料!O4="","",IF(反向題設定!$C$18="是",反向題設定!$B$2+1-原始資料!O4,原始資料!O4)) | P4: =IF(原始資料!P4="","",IF(反向題設定!$C$19="是",反向題設定!$B$2+1-原始資料!P4,原始資料!P4)) | Q4: =IF(原始資料!Q4="","",IF(反向題設定!$C$20="是",反向題設定!$B$2+1-原始資料!Q4,原始資料!Q4)) | R4: =IF(原始資料!R4="","",IF(反向題設定!$C$21="是",反向題設定!$B$2+1-原始資料!R4,原始資料!R4)) | S4: =IF(原始資料!S4="","",IF(反向題設定!$C$22="是",反向題設定!$B$2+1-原始資料!S4,原始資料!S4)) | T4: =IF(原始資料!T4="","",IF(反向題設定!$C$23="是",反向題設定!$B$2+1-原始資料!T4,原始資料!T4)) | U4: =IF(原始資料!U4="","",IF(反向題設定!$C$24="是",反向題設定!$B$2+1-原始資料!U4,原始資料!U4)) | V4: =IF(原始資料!V4="","",IF(反向題設定!$C$25="是",反向題設定!$B$2+1-原始資料!V4,原始資料!V4)) | W4: =IF(原始資料!W4="","",IF(反向題設定!$C$26="是",反向題設定!$B$2+1-原始資料!W4,原始資料!W4)) | X4: =IF(原始資料!X4="","",IF(反向題設定!$C$27="是",反向題設定!$B$2+1-原始資料!X4,原始資料!X4)) | Y4: =IF(原始資料!Y4="","",IF(反向題設定!$C$28="是",反向題設定!$B$2+1-原始資料!Y4,原始資料!Y4)) | Z4: =IF(原始資料!Z4="","",IF(反向題設定!$C$29="是",反向題設定!$B$2+1-原始資料!Z4,原始資料!Z4)) | AA4: =IF(原始資料!AA4="","",IF(反向題設定!$C$30="是",反向題設定!$B$2+1-原始資料!AA4,原始資料!AA4)) | AB4: =IF(原始資料!AB4="","",IF(反向題設定!$C$31="是",反向題設定!$B$2+1-原始資料!AB4,原始資料!AB4)) | AC4: =IF(原始資料!AC4="","",IF(反向題設定!$C$32="是",反向題設定!$B$2+1-原始資料!AC4,原始資料!AC4)) | AD4: =IF(原始資料!AD4="","",IF(反向題設定!$C$33="是",反向題設定!$B$2+1-原始資料!AD4,原始資料!AD4)) | AE4: =IF(原始資料!AE4="","",IF(反向題設定!$C$34="是",反向題設定!$B$2+1-原始資料!AE4,原始資料!AE4)) | AF4: =IF(原始資料!AF4="","",IF(反向題設定!$C$35="是",反向題設定!$B$2+1-原始資料!AF4,原始資料!AF4)) | AG4: =IF(原始資料!AG4="","",IF(反向題設定!$C$36="是",反向題設定!$B$2+1-原始資料!AG4,原始資料!AG4)) | AH4: =IF(原始資料!AH4="","",IF(反向題設定!$C$37="是",反向題設定!$B$2+1-原始資料!AH4,原始資料!AH4)) | AI4: =IF(原始資料!AI4="","",IF(反向題設定!$C$38="是",反向題設定!$B$2+1-原始資料!AI4,原始資料!AI4)) | AJ4: =IF(原始資料!AJ4="","",IF(反向題設定!$C$39="是",反向題設定!$B$2+1-原始資料!AJ4,原始資料!AJ4)) | AK4: =IF(原始資料!AK4="","",IF(反向題設定!$C$40="是",反向題設定!$B$2+1-原始資料!AK4,原始資料!AK4)) | AL4: =IF(原始資料!AL4="","",IF(反向題設定!$C$41="是",反向題設定!$B$2+1-原始資料!AL4,原始資料!AL4)) | AM4: =IF(原始資料!AM4="","",IF(反向題設定!$C$42="是",反向題設定!$B$2+1-原始資料!AM4,原始資料!AM4)) | AN4: =IF(原始資料!AN4="","",IF(反向題設定!$C$43="是",反向題設定!$B$2+1-原始資料!AN4,原始資料!AN4)) | AO4: =IF(原始資料!AO4="","",IF(反向題設定!$C$44="是",反向題設定!$B$2+1-原始資料!AO4,原始資料!AO4)) | AP4: =IF(COUNT(B4:AO4)=0,"",SUM(B4:AO4)) | AQ4: =IF(AP4="","",IF(AP4>=項目分析!$C$5,"高",IF(AP4<=項目分析!$C$6,"低","")))
A5: =IF(原始資料!A5="","",原始資料!A5) | B5: =IF(原始資料!B5="","",IF(反向題設定!$C$5="是",反向題設定!$B$2+1-原始資料!B5,原始資料!B5)) | C5: =IF(原始資料!C5="","",IF(反向題設定!$C$6="是",反向題設定!$B$2+1-原始資料!C5,原始資料!C5)) | D5: =IF(原始資料!D5="","",IF(反向題設定!$C$7="是",反向題設定!$B$2+1-原始資料!D5,原始資料!D5)) | E5: =IF(原始資料!E5="","",IF(反向題設定!$C$8="是",反向題設定!$B$2+1-原始資料!E5,原始資料!E5)) | F5: =IF(原始資料!F5="","",IF(反向題設定!$C$9="是",反向題設定!$B$2+1-原始資料!F5,原始資料!F5)) | G5: =IF(原始資料!G5="","",IF(反向題設定!$C$10="是",反向題設定!$B$2+1-原始資料!G5,原始資料!G5)) | H5: =IF(原始資料!H5="","",IF(反向題設定!$C$11="是",反向題設定!$B$2+1-原始資料!H5,原始資料!H5)) | I5: =IF(原始資料!I5="","",IF(反向題設定!$C$12="是",反向題設定!$B$2+1-原始資料!I5,原始資料!I5)) | J5: =IF(原始資料!J5="","",IF(反向題設定!$C$13="是",反向題設定!$B$2+1-原始資料!J5,原始資料!J5)) | K5: =IF(原始資料!K5="","",IF(反向題設定!$C$14="是",反向題設定!$B$2+1-原始資料!K5,原始資料!K5)) | L5: =IF(原始資料!L5="","",IF(反向題設定!$C$15="是",反向題設定!$B$2+1-原始資料!L5,原始資料!L5)) | M5: =IF(原始資料!M5="","",IF(反向題設定!$C$16="是",反向題設定!$B$2+1-原始資料!M5,原始資料!M5)) | N5: =IF(原始資料!N5="","",IF(反向題設定!$C$17="是",反向題設定!$B$2+1-原始資料!N5,原始資料!N5)) | O5: =IF(原始資料!O5="","",IF(反向題設定!$C$18="是",反向題設定!$B$2+1-原始資料!O5,原始資料!O5)) | P5: =IF(原始資料!P5="","",IF(反向題設定!$C$19="是",反向題設定!$B$2+1-原始資料!P5,原始資料!P5)) | Q5: =IF(原始資料!Q5="","",IF(反向題設定!$C$20="是",反向題設定!$B$2+1-原始資料!Q5,原始資料!Q5)) | R5: =IF(原始資料!R5="","",IF(反向題設定!$C$21="是",反向題設定!$B$2+1-原始資料!R5,原始資料!R5)) | S5: =IF(原始資料!S5="","",IF(反向題設定!$C$22="是",反向題設定!$B$2+1-原始資料!S5,原始資料!S5)) | T5: =IF(原始資料!T5="","",IF(反向題設定!$C$23="是",反向題設定!$B$2+1-原始資料!T5,原始資料!T5)) | U5: =IF(原始資料!U5="","",IF(反向題設定!$C$24="是",反向題設定!$B$2+1-原始資料!U5,原始資料!U5)) | V5: =IF(原始資料!V5="","",IF(反向題設定!$C$25="是",反向題設定!$B$2+1-原始資料!V5,原始資料!V5)) | W5: =IF(原始資料!W5="","",IF(反向題設定!$C$26="是",反向題設定!$B$2+1-原始資料!W5,原始資料!W5)) | X5: =IF(原始資料!X5="","",IF(反向題設定!$C$27="是",反向題設定!$B$2+1-原始資料!X5,原始資料!X5)) | Y5: =IF(原始資料!Y5="","",IF(反向題設定!$C$28="是",反向題設定!$B$2+1-原始資料!Y5,原始資料!Y5)) | Z5: =IF(原始資料!Z5="","",IF(反向題設定!$C$29="是",反向題設定!$B$2+1-原始資料!Z5,原始資料!Z5)) | AA5: =IF(原始資料!AA5="","",IF(反向題設定!$C$30="是",反向題設定!$B$2+1-原始資料!AA5,原始資料!AA5)) | AB5: =IF(原始資料!AB5="","",IF(反向題設定!$C$31="是",反向題設定!$B$2+1-原始資料!AB5,原始資料!AB5)) | AC5: =IF(原始資料!AC5="","",IF(反向題設定!$C$32="是",反向題設定!$B$2+1-原始資料!AC5,原始資料!AC5)) | AD5: =IF(原始資料!AD5="","",IF(反向題設定!$C$33="是",反向題設定!$B$2+1-原始資料!AD5,原始資料!AD5)) | AE5: =IF(原始資料!AE5="","",IF(反向題設定!$C$34="是",反向題設定!$B$2+1-原始資料!AE5,原始資料!AE5)) | AF5: =IF(原始資料!AF5="","",IF(反向題設定!$C$35="是",反向題設定!$B$2+1-原始資料!AF5,原始資料!AF5)) | AG5: =IF(原始資料!AG5="","",IF(反向題設定!$C$36="是",反向題設定!$B$2+1-原始資料!AG5,原始資料!AG5)) | AH5: =IF(原始資料!AH5="","",IF(反向題設定!$C$37="是",反向題設定!$B$2+1-原始資料!AH5,原始資料!AH5)) | AI5: =IF(原始資料!AI5="","",IF(反向題設定!$C$38="是",反向題設定!$B$2+1-原始資料!AI5,原始資料!AI5)) | AJ5: =IF(原始資料!AJ5="","",IF(反向題設定!$C$39="是",反向題設定!$B$2+1-原始資料!AJ5,原始資料!AJ5)) | AK5: =IF(原始資料!AK5="","",IF(反向題設定!$C$40="是",反向題設定!$B$2+1-原始資料!AK5,原始資料!AK5)) | AL5: =IF(原始資料!AL5="","",IF(反向題設定!$C$41="是",反向題設定!$B$2+1-原始資料!AL5,原始資料!AL5)) | AM5: =IF(原始資料!AM5="","",IF(反向題設定!$C$42="是",反向題設定!$B$2+1-原始資料!AM5,原始資料!AM5)) | AN5: =IF(原始資料!AN5="","",IF(反向題設定!$C$43="是",反向題設定!$B$2+1-原始資料!AN5,原始資料!AN5)) | AO5: =IF(原始資料!AO5="","",IF(反向題設定!$C$44="是",反向題設定!$B$2+1-原始資料!AO5,原始資料!AO5)) | AP5: =IF(COUNT(B5:AO5)=0,"",SUM(B5:AO5)) | AQ5: =IF(AP5="","",IF(AP5>=項目分析!$C$5,"高",IF(AP5<=項目分析!$C$6,"低","")))
A6: =IF(原始資料!A6="","",原始資料!A6) | B6: =IF(原始資料!B6="","",IF(反向題設定!$C$5="是",反向題設定!$B$2+1-原始資料!B6,原始資料!B6)) | C6: =IF(原始資料!C6="","",IF(反向題設定!$C$6="是",反向題設定!$B$2+1-原始資料!C6,原始資料!C6)) | D6: =IF(原始資料!D6="","",IF(反向題設定!$C$7="是",反向題設定!$B$2+1-原始資料!D6,原始資料!D6)) | E6: =IF(原始資料!E6="","",IF(反向題設定!$C$8="是",反向題設定!$B$2+1-原始資料!E6,原始資料!E6)) | F6: =IF(原始資料!F6="","",IF(反向題設定!$C$9="是",反向題設定!$B$2+1-原始資料!F6,原始資料!F6)) | G6: =IF(原始資料!G6="","",IF(反向題設定!$C$10="是",反向題設定!$B$2+1-原始資料!G6,原始資料!G6)) | H6: =IF(原始資料!H6="","",IF(反向題設定!$C$11="是",反向題設定!$B$2+1-原始資料!H6,原始資料!H6)) | I6: =IF(原始資料!I6="","",IF(反向題設定!$C$12="是",反向題設定!$B$2+1-原始資料!I6,原始資料!I6)) | J6: =IF(原始資料!J6="","",IF(反向題設定!$C$13="是",反向題設定!$B$2+1-原始資料!J6,原始資料!J6)) | K6: =IF(原始資料!K6="","",IF(反向題設定!$C$14="是",反向題設定!$B$2+1-原始資料!K6,原始資料!K6)) | L6: =IF(原始資料!L6="","",IF(反向題設定!$C$15="是",反向題設定!$B$2+1-原始資料!L6,原始資料!L6)) | M6: =IF(原始資料!M6="","",IF(反向題設定!$C$16="是",反向題設定!$B$2+1-原始資料!M6,原始資料!M6)) | N6: =IF(原始資料!N6="","",IF(反向題設定!$C$17="是",反向題設定!$B$2+1-原始資料!N6,原始資料!N6)) | O6: =IF(原始資料!O6="","",IF(反向題設定!$C$18="是",反向題設定!$B$2+1-原始資料!O6,原始資料!O6)) | P6: =IF(原始資料!P6="","",IF(反向題設定!$C$19="是",反向題設定!$B$2+1-原始資料!P6,原始資料!P6)) | Q6: =IF(原始資料!Q6="","",IF(反向題設定!$C$20="是",反向題設定!$B$2+1-原始資料!Q6,原始資料!Q6)) | R6: =IF(原始資料!R6="","",IF(反向題設定!$C$21="是",反向題設定!$B$2+1-原始資料!R6,原始資料!R6)) | S6: =IF(原始資料!S6="","",IF(反向題設定!$C$22="是",反向題設定!$B$2+1-原始資料!S6,原始資料!S6)) | T6: =IF(原始資料!T6="","",IF(反向題設定!$C$23="是",反向題設定!$B$2+1-原始資料!T6,原始資料!T6)) | U6: =IF(原始資料!U6="","",IF(反向題設定!$C$24="是",反向題設定!$B$2+1-原始資料!U6,原始資料!U6)) | V6: =IF(原始資料!V6="","",IF(反向題設定!$C$25="是",反向題設定!$B$2+1-原始資料!V6,原始資料!V6)) | W6: =IF(原始資料!W6="","",IF(反向題設定!$C$26="是",反向題設定!$B$2+1-原始資料!W6,原始資料!W6)) | X6: =IF(原始資料!X6="","",IF(反向題設定!$C$27="是",反向題設定!$B$2+1-原始資料!X6,原始資料!X6)) | Y6: =IF(原始資料!Y6="","",IF(反向題設定!$C$28="是",反向題設定!$B$2+1-原始資料!Y6,原始資料!Y6)) | Z6: =IF(原始資料!Z6="","",IF(反向題設定!$C$29="是",反向題設定!$B$2+1-原始資料!Z6,原始資料!Z6)) | AA6: =IF(原始資料!AA6="","",IF(反向題設定!$C$30="是",反向題設定!$B$2+1-原始資料!AA6,原始資料!AA6)) | AB6: =IF(原始資料!AB6="","",IF(反向題設定!$C$31="是",反向題設定!$B$2+1-原始資料!AB6,原始資料!AB6)) | AC6: =IF(原始資料!AC6="","",IF(反向題設定!$C$32="是",反向題設定!$B$2+1-原始資料!AC6,原始資料!AC6)) | AD6: =IF(原始資料!AD6="","",IF(反向題設定!$C$33="是",反向題設定!$B$2+1-原始資料!AD6,原始資料!AD6)) | AE6: =IF(原始資料!AE6="","",IF(反向題設定!$C$34="是",反向題設定!$B$2+1-原始資料!AE6,原始資料!AE6)) | AF6: =IF(原始資料!AF6="","",IF(反向題設定!$C$35="是",反向題設定!$B$2+1-原始資料!AF6,原始資料!AF6)) | AG6: =IF(原始資料!AG6="","",IF(反向題設定!$C$36="是",反向題設定!$B$2+1-原始資料!AG6,原始資料!AG6)) | AH6: =IF(原始資料!AH6="","",IF(反向題設定!$C$37="是",反向題設定!$B$2+1-原始資料!AH6,原始資料!AH6)) | AI6: =IF(原始資料!AI6="","",IF(反向題設定!$C$38="是",反向題設定!$B$2+1-原始資料!AI6,原始資料!AI6)) | AJ6: =IF(原始資料!AJ6="","",IF(反向題設定!$C$39="是",反向題設定!$B$2+1-原始資料!AJ6,原始資料!AJ6)) | AK6: =IF(原始資料!AK6="","",IF(反向題設定!$C$40="是",反向題設定!$B$2+1-原始資料!AK6,原始資料!AK6)) | AL6: =IF(原始資料!AL6="","",IF(反向題設定!$C$41="是",反向題設定!$B$2+1-原始資料!AL6,原始資料!AL6)) | AM6: =IF(原始資料!AM6="","",IF(反向題設定!$C$42="是",反向題設定!$B$2+1-原始資料!AM6,原始資料!AM6)) | AN6: =IF(原始資料!AN6="","",IF(反向題設定!$C$43="是",反向題設定!$B$2+1-原始資料!AN6,原始資料!AN6)) | AO6: =IF(原始資料!AO6="","",IF(反向題設定!$C$44="是",反向題設定!$B$2+1-原始資料!AO6,原始資料!AO6)) | AP6: =IF(COUNT(B6:AO6)=0,"",SUM(B6:AO6)) | AQ6: =IF(AP6="","",IF(AP6>=項目分析!$C$5,"高",IF(AP6<=項目分析!$C$6,"低","")))
A7: =IF(原始資料!A7="","",原始資料!A7) | B7: =IF(原始資料!B7="","",IF(反向題設定!$C$5="是",反向題設定!$B$2+1-原始資料!B7,原始資料!B7)) | C7: =IF(原始資料!C7="","",IF(反向題設定!$C$6="是",反向題設定!$B$2+1-原始資料!C7,原始資料!C7)) | D7: =IF(原始資料!D7="","",IF(反向題設定!$C$7="是",反向題設定!$B$2+1-原始資料!D7,原始資料!D7)) | E7: =IF(原始資料!E7="","",IF(反向題設定!$C$8="是",反向題設定!$B$2+1-原始資料!E7,原始資料!E7)) | F7: =IF(原始資料!F7="","",IF(反向題設定!$C$9="是",反向題設定!$B$2+1-原始資料!F7,原始資料!F7)) | G7: =IF(原始資料!G7="","",IF(反向題設定!$C$10="是",反向題設定!$B$2+1-原始資料!G7,原始資料!G7)) | H7: =IF(原始資料!H7="","",IF(反向題設定!$C$11="是",反向題設定!$B$2+1-原始資料!H7,原始資料!H7)) | I7: =IF(原始資料!I7="","",IF(反向題設定!$C$12="是",反向題設定!$B$2+1-原始資料!I7,原始資料!I7)) | J7: =IF(原始資料!J7="","",IF(反向題設定!$C$13="是",反向題設定!$B$2+1-原始資料!J7,原始資料!J7)) | K7: =IF(原始資料!K7="","",IF(反向題設定!$C$14="是",反向題設定!$B$2+1-原始資料!K7,原始資料!K7)) | L7: =IF(原始資料!L7="","",IF(反向題設定!$C$15="是",反向題設定!$B$2+1-原始資料!L7,原始資料!L7)) | M7: =IF(原始資料!M7="","",IF(反向題設定!$C$16="是",反向題設定!$B$2+1-原始資料!M7,原始資料!M7)) | N7: =IF(原始資料!N7="","",IF(反向題設定!$C$17="是",反向題設定!$B$2+1-原始資料!N7,原始資料!N7)) | O7: =IF(原始資料!O7="","",IF(反向題設定!$C$18="是",反向題設定!$B$2+1-原始資料!O7,原始資料!O7)) | P7: =IF(原始資料!P7="","",IF(反向題設定!$C$19="是",反向題設定!$B$2+1-原始資料!P7,原始資料!P7)) | Q7: =IF(原始資料!Q7="","",IF(反向題設定!$C$20="是",反向題設定!$B$2+1-原始資料!Q7,原始資料!Q7)) | R7: =IF(原始資料!R7="","",IF(反向題設定!$C$21="是",反向題設定!$B$2+1-原始資料!R7,原始資料!R7)) | S7: =IF(原始資料!S7="","",IF(反向題設定!$C$22="是",反向題設定!$B$2+1-原始資料!S7,原始資料!S7)) | T7: =IF(原始資料!T7="","",IF(反向題設定!$C$23="是",反向題設定!$B$2+1-原始資料!T7,原始資料!T7)) | U7: =IF(原始資料!U7="","",IF(反向題設定!$C$24="是",反向題設定!$B$2+1-原始資料!U7,原始資料!U7)) | V7: =IF(原始資料!V7="","",IF(反向題設定!$C$25="是",反向題設定!$B$2+1-原始資料!V7,原始資料!V7)) | W7: =IF(原始資料!W7="","",IF(反向題設定!$C$26="是",反向題設定!$B$2+1-原始資料!W7,原始資料!W7)) | X7: =IF(原始資料!X7="","",IF(反向題設定!$C$27="是",反向題設定!$B$2+1-原始資料!X7,原始資料!X7)) | Y7: =IF(原始資料!Y7="","",IF(反向題設定!$C$28="是",反向題設定!$B$2+1-原始資料!Y7,原始資料!Y7)) | Z7: =IF(原始資料!Z7="","",IF(反向題設定!$C$29="是",反向題設定!$B$2+1-原始資料!Z7,原始資料!Z7)) | AA7: =IF(原始資料!AA7="","",IF(反向題設定!$C$30="是",反向題設定!$B$2+1-原始資料!AA7,原始資料!AA7)) | AB7: =IF(原始資料!AB7="","",IF(反向題設定!$C$31="是",反向題設定!$B$2+1-原始資料!AB7,原始資料!AB7)) | AC7: =IF(原始資料!AC7="","",IF(反向題設定!$C$32="是",反向題設定!$B$2+1-原始資料!AC7,原始資料!AC7)) | AD7: =IF(原始資料!AD7="","",IF(反向題設定!$C$33="是",反向題設定!$B$2+1-原始資料!AD7,原始資料!AD7)) | AE7: =IF(原始資料!AE7="","",IF(反向題設定!$C$34="是",反向題設定!$B$2+1-原始資料!AE7,原始資料!AE7)) | AF7: =IF(原始資料!AF7="","",IF(反向題設定!$C$35="是",反向題設定!$B$2+1-原始資料!AF7,原始資料!AF7)) | AG7: =IF(原始資料!AG7="","",IF(反向題設定!$C$36="是",反向題設定!$B$2+1-原始資料!AG7,原始資料!AG7)) | AH7: =IF(原始資料!AH7="","",IF(反向題設定!$C$37="是",反向題設定!$B$2+1-原始資料!AH7,原始資料!AH7)) | AI7: =IF(原始資料!AI7="","",IF(反向題設定!$C$38="是",反向題設定!$B$2+1-原始資料!AI7,原始資料!AI7)) | AJ7: =IF(原始資料!AJ7="","",IF(反向題設定!$C$39="是",反向題設定!$B$2+1-原始資料!AJ7,原始資料!AJ7)) | AK7: =IF(原始資料!AK7="","",IF(反向題設定!$C$40="是",反向題設定!$B$2+1-原始資料!AK7,原始資料!AK7)) | AL7: =IF(原始資料!AL7="","",IF(反向題設定!$C$41="是",反向題設定!$B$2+1-原始資料!AL7,原始資料!AL7)) | AM7: =IF(原始資料!AM7="","",IF(反向題設定!$C$42="是",反向題設定!$B$2+1-原始資料!AM7,原始資料!AM7)) | AN7: =IF(原始資料!AN7="","",IF(反向題設定!$C$43="是",反向題設定!$B$2+1-原始資料!AN7,原始資料!AN7)) | AO7: =IF(原始資料!AO7="","",IF(反向題設定!$C$44="是",反向題設定!$B$2+1-原始資料!AO7,原始資料!AO7)) | AP7: =IF(COUNT(B7:AO7)=0,"",SUM(B7:AO7)) | AQ7: =IF(AP7="","",IF(AP7>=項目分析!$C$5,"高",IF(AP7<=項目分析!$C$6,"低","")))
A8: =IF(原始資料!A8="","",原始資料!A8) | B8: =IF(原始資料!B8="","",IF(反向題設定!$C$5="是",反向題設定!$B$2+1-原始資料!B8,原始資料!B8)) | C8: =IF(原始資料!C8="","",IF(反向題設定!$C$6="是",反向題設定!$B$2+1-原始資料!C8,原始資料!C8)) | D8: =IF(原始資料!D8="","",IF(反向題設定!$C$7="是",反向題設定!$B$2+1-原始資料!D8,原始資料!D8)) | E8: =IF(原始資料!E8="","",IF(反向題設定!$C$8="是",反向題設定!$B$2+1-原始資料!E8,原始資料!E8)) | F8: =IF(原始資料!F8="","",IF(反向題設定!$C$9="是",反向題設定!$B$2+1-原始資料!F8,原始資料!F8)) | G8: =IF(原始資料!G8="","",IF(反向題設定!$C$10="是",反向題設定!$B$2+1-原始資料!G8,原始資料!G8)) | H8: =IF(原始資料!H8="","",IF(反向題設定!$C$11="是",反向題設定!$B$2+1-原始資料!H8,原始資料!H8)) | I8: =IF(原始資料!I8="","",IF(反向題設定!$C$12="是",反向題設定!$B$2+1-原始資料!I8,原始資料!I8)) | J8: =IF(原始資料!J8="","",IF(反向題設定!$C$13="是",反向題設定!$B$2+1-原始資料!J8,原始資料!J8)) | K8: =IF(原始資料!K8="","",IF(反向題設定!$C$14="是",反向題設定!$B$2+1-原始資料!K8,原始資料!K8)) | L8: =IF(原始資料!L8="","",IF(反向題設定!$C$15="是",反向題設定!$B$2+1-原始資料!L8,原始資料!L8)) | M8: =IF(原始資料!M8="","",IF(反向題設定!$C$16="是",反向題設定!$B$2+1-原始資料!M8,原始資料!M8)) | N8: =IF(原始資料!N8="","",IF(反向題設定!$C$17="是",反向題設定!$B$2+1-原始資料!N8,原始資料!N8)) | O8: =IF(原始資料!O8="","",IF(反向題設定!$C$18="是",反向題設定!$B$2+1-原始資料!O8,原始資料!O8)) | P8: =IF(原始資料!P8="","",IF(反向題設定!$C$19="是",反向題設定!$B$2+1-原始資料!P8,原始資料!P8)) | Q8: =IF(原始資料!Q8="","",IF(反向題設定!$C$20="是",反向題設定!$B$2+1-原始資料!Q8,原始資料!Q8)) | R8: =IF(原始資料!R8="","",IF(反向題設定!$C$21="是",反向題設定!$B$2+1-原始資料!R8,原始資料!R8)) | S8: =IF(原始資料!S8="","",IF(反向題設定!$C$22="是",反向題設定!$B$2+1-原始資料!S8,原始資料!S8)) | T8: =IF(原始資料!T8="","",IF(反向題設定!$C$23="是",反向題設定!$B$2+1-原始資料!T8,原始資料!T8)) | U8: =IF(原始資料!U8="","",IF(反向題設定!$C$24="是",反向題設定!$B$2+1-原始資料!U8,原始資料!U8)) | V8: =IF(原始資料!V8="","",IF(反向題設定!$C$25="是",反向題設定!$B$2+1-原始資料!V8,原始資料!V8)) | W8: =IF(原始資料!W8="","",IF(反向題設定!$C$26="是",反向題設定!$B$2+1-原始資料!W8,原始資料!W8)) | X8: =IF(原始資料!X8="","",IF(反向題設定!$C$27="是",反向題設定!$B$2+1-原始資料!X8,原始資料!X8)) | Y8: =IF(原始資料!Y8="","",IF(反向題設定!$C$28="是",反向題設定!$B$2+1-原始資料!Y8,原始資料!Y8)) | Z8: =IF(原始資料!Z8="","",IF(反向題設定!$C$29="是",反向題設定!$B$2+1-原始資料!Z8,原始資料!Z8)) | AA8: =IF(原始資料!AA8="","",IF(反向題設定!$C$30="是",反向題設定!$B$2+1-原始資料!AA8,原始資料!AA8)) | AB8: =IF(原始資料!AB8="","",IF(反向題設定!$C$31="是",反向題設定!$B$2+1-原始資料!AB8,原始資料!AB8)) | AC8: =IF(原始資料!AC8="","",IF(反向題設定!$C$32="是",反向題設定!$B$2+1-原始資料!AC8,原始資料!AC8)) | AD8: =IF(原始資料!AD8="","",IF(反向題設定!$C$33="是",反向題設定!$B$2+1-原始資料!AD8,原始資料!AD8)) | AE8: =IF(原始資料!AE8="","",IF(反向題設定!$C$34="是",反向題設定!$B$2+1-原始資料!AE8,原始資料!AE8)) | AF8: =IF(原始資料!AF8="","",IF(反向題設定!$C$35="是",反向題設定!$B$2+1-原始資料!AF8,原始資料!AF8)) | AG8: =IF(原始資料!AG8="","",IF(反向題設定!$C$36="是",反向題設定!$B$2+1-原始資料!AG8,原始資料!AG8)) | AH8: =IF(原始資料!AH8="","",IF(反向題設定!$C$37="是",反向題設定!$B$2+1-原始資料!AH8,原始資料!AH8)) | AI8: =IF(原始資料!AI8="","",IF(反向題設定!$C$38="是",反向題設定!$B$2+1-原始資料!AI8,原始資料!AI8)) | AJ8: =IF(原始資料!AJ8="","",IF(反向題設定!$C$39="是",反向題設定!$B$2+1-原始資料!AJ8,原始資料!AJ8)) | AK8: =IF(原始資料!AK8="","",IF(反向題設定!$C$40="是",反向題設定!$B$2+1-原始資料!AK8,原始資料!AK8)) | AL8: =IF(原始資料!AL8="","",IF(反向題設定!$C$41="是",反向題設定!$B$2+1-原始資料!AL8,原始資料!AL8)) | AM8: =IF(原始資料!AM8="","",IF(反向題設定!$C$42="是",反向題設定!$B$2+1-原始資料!AM8,原始資料!AM8)) | AN8: =IF(原始資料!AN8="","",IF(反向題設定!$C$43="是",反向題設定!$B$2+1-原始資料!AN8,原始資料!AN8)) | AO8: =IF(原始資料!AO8="","",IF(反向題設定!$C$44="是",反向題設定!$B$2+1-原始資料!AO8,原始資料!AO8)) | AP8: =IF(COUNT(B8:AO8)=0,"",SUM(B8:AO8)) | AQ8: =IF(AP8="","",IF(AP8>=項目分析!$C$5,"高",IF(AP8<=項目分析!$C$6,"低","")))
A9: =IF(原始資料!A9="","",原始資料!A9) | B9: =IF(原始資料!B9="","",IF(反向題設定!$C$5="是",反向題設定!$B$2+1-原始資料!B9,原始資料!B9)) | C9: =IF(原始資料!C9="","",IF(反向題設定!$C$6="是",反向題設定!$B$2+1-原始資料!C9,原始資料!C9)) | D9: =IF(原始資料!D9="","",IF(反向題設定!$C$7="是",反向題設定!$B$2+1-原始資料!D9,原始資料!D9)) | E9: =IF(原始資料!E9="","",IF(反向題設定!$C$8="是",反向題設定!$B$2+1-原始資料!E9,原始資料!E9)) | F9: =IF(原始資料!F9="","",IF(反向題設定!$C$9="是",反向題設定!$B$2+1-原始資料!F9,原始資料!F9)) | G9: =IF(原始資料!G9="","",IF(反向題設定!$C$10="是",反向題設定!$B$2+1-原始資料!G9,原始資料!G9)) | H9: =IF(原始資料!H9="","",IF(反向題設定!$C$11="是",反向題設定!$B$2+1-原始資料!H9,原始資料!H9)) | I9: =IF(原始資料!I9="","",IF(反向題設定!$C$12="是",反向題設定!$B$2+1-原始資料!I9,原始資料!I9)) | J9: =IF(原始資料!J9="","",IF(反向題設定!$C$13="是",反向題設定!$B$2+1-原始資料!J9,原始資料!J9)) | K9: =IF(原始資料!K9="","",IF(反向題設定!$C$14="是",反向題設定!$B$2+1-原始資料!K9,原始資料!K9)) | L9: =IF(原始資料!L9="","",IF(反向題設定!$C$15="是",反向題設定!$B$2+1-原始資料!L9,原始資料!L9)) | M9: =IF(原始資料!M9="","",IF(反向題設定!$C$16="是",反向題設定!$B$2+1-原始資料!M9,原始資料!M9)) | N9: =IF(原始資料!N9="","",IF(反向題設定!$C$17="是",反向題設定!$B$2+1-原始資料!N9,原始資料!N9)) | O9: =IF(原始資料!O9="","",IF(反向題設定!$C$18="是",反向題設定!$B$2+1-原始資料!O9,原始資料!O9)) | P9: =IF(原始資料!P9="","",IF(反向題設定!$C$19="是",反向題設定!$B$2+1-原始資料!P9,原始資料!P9)) | Q9: =IF(原始資料!Q9="","",IF(反向題設定!$C$20="是",反向題設定!$B$2+1-原始資料!Q9,原始資料!Q9)) | R9: =IF(原始資料!R9="","",IF(反向題設定!$C$21="是",反向題設定!$B$2+1-原始資料!R9,原始資料!R9)) | S9: =IF(原始資料!S9="","",IF(反向題設定!$C$22="是",反向題設定!$B$2+1-原始資料!S9,原始資料!S9)) | T9: =IF(原始資料!T9="","",IF(反向題設定!$C$23="是",反向題設定!$B$2+1-原始資料!T9,原始資料!T9)) | U9: =IF(原始資料!U9="","",IF(反向題設定!$C$24="是",反向題設定!$B$2+1-原始資料!U9,原始資料!U9)) | V9: =IF(原始資料!V9="","",IF(反向題設定!$C$25="是",反向題設定!$B$2+1-原始資料!V9,原始資料!V9)) | W9: =IF(原始資料!W9="","",IF(反向題設定!$C$26="是",反向題設定!$B$2+1-原始資料!W9,原始資料!W9)) | X9: =IF(原始資料!X9="","",IF(反向題設定!$C$27="是",反向題設定!$B$2+1-原始資料!X9,原始資料!X9)) | Y9: =IF(原始資料!Y9="","",IF(反向題設定!$C$28="是",反向題設定!$B$2+1-原始資料!Y9,原始資料!Y9)) | Z9: =IF(原始資料!Z9="","",IF(反向題設定!$C$29="是",反向題設定!$B$2+1-原始資料!Z9,原始資料!Z9)) | AA9: =IF(原始資料!AA9="","",IF(反向題設定!$C$30="是",反向題設定!$B$2+1-原始資料!AA9,原始資料!AA9)) | AB9: =IF(原始資料!AB9="","",IF(反向題設定!$C$31="是",反向題設定!$B$2+1-原始資料!AB9,原始資料!AB9)) | AC9: =IF(原始資料!AC9="","",IF(反向題設定!$C$32="是",反向題設定!$B$2+1-原始資料!AC9,原始資料!AC9)) | AD9: =IF(原始資料!AD9="","",IF(反向題設定!$C$33="是",反向題設定!$B$2+1-原始資料!AD9,原始資料!AD9)) | AE9: =IF(原始資料!AE9="","",IF(反向題設定!$C$34="是",反向題設定!$B$2+1-原始資料!AE9,原始資料!AE9)) | AF9: =IF(原始資料!AF9="","",IF(反向題設定!$C$35="是",反向題設定!$B$2+1-原始資料!AF9,原始資料!AF9)) | AG9: =IF(原始資料!AG9="","",IF(反向題設定!$C$36="是",反向題設定!$B$2+1-原始資料!AG9,原始資料!AG9)) | AH9: =IF(原始資料!AH9="","",IF(反向題設定!$C$37="是",反向題設定!$B$2+1-原始資料!AH9,原始資料!AH9)) | AI9: =IF(原始資料!AI9="","",IF(反向題設定!$C$38="是",反向題設定!$B$2+1-原始資料!AI9,原始資料!AI9)) | AJ9: =IF(原始資料!AJ9="","",IF(反向題設定!$C$39="是",反向題設定!$B$2+1-原始資料!AJ9,原始資料!AJ9)) | AK9: =IF(原始資料!AK9="","",IF(反向題設定!$C$40="是",反向題設定!$B$2+1-原始資料!AK9,原始資料!AK9)) | AL9: =IF(原始資料!AL9="","",IF(反向題設定!$C$41="是",反向題設定!$B$2+1-原始資料!AL9,原始資料!AL9)) | AM9: =IF(原始資料!AM9="","",IF(反向題設定!$C$42="是",反向題設定!$B$2+1-原始資料!AM9,原始資料!AM9)) | AN9: =IF(原始資料!AN9="","",IF(反向題設定!$C$43="是",反向題設定!$B$2+1-原始資料!AN9,原始資料!AN9)) | AO9: =IF(原始資料!AO9="","",IF(反向題設定!$C$44="是",反向題設定!$B$2+1-原始資料!AO9,原始資料!AO9)) | AP9: =IF(COUNT(B9:AO9)=0,"",SUM(B9:AO9)) | AQ9: =IF(AP9="","",IF(AP9>=項目分析!$C$5,"高",IF(AP9<=項目分析!$C$6,"低","")))
