Workbook

Sheet 使用說明
B1: 期中團體作業 草率作答篩檢範本
B2: 員工意向調查 HRM922 2026 Fall 國立中山大學人力資源管理研究所 王豫萱
B5: 使用前
B6: 剔除標準要在收資料之前寫好（Topic 04），不要看了資料再調整門檻；本範本只負責依照寫好的標準計算
B8: 操作步驟
B9: 1 設定：填題數、檢核題正確答案、最短作答秒數、連續相同門檻（黃色格）；不使用的標準留空，該項就不判定
B10: 2 原始資料：從 A1 貼上。A 欄編號、B 欄作答秒數、C 欄檢核題，D 欄起依序是題目；第 1 列為欄位名稱，最多 60 題、500 人
B11: 3 判定：自動標示每一位填答者符合哪幾條標準；開放題經兩位組員複核為 AI 代答者，在「人工剔除」欄填「是」
B12: 4 統計：依企劃書 4.4 的格式列出各標準剔除人數與有效樣本，可以直接抄進企劃書
B13: 5 有效樣本：自動列出保留的填答者，只含編號與題目。選取有內容的範圍 → 複製 → 新活頁簿「貼上值」→ 另存為 CSV UTF-8（逗號分隔），交給 JASP 或項目分析範本
B14: 6 有效樣本不做反向計分：分析前依投影片步驟把反向題改為（量尺點數＋1）－原始分數，或貼進項目分析範本，在「反向題設定」標示
B16: 計算方式
... B23: 把課堂練習資料「期中作業_玻璃心預試練習資料.csv」貼進原始資料，設定維持 15、5、30、10，應得到檢核題 4、過快 4、直線 5，剔除 13 人、有效樣本 172

Sheet 設定
A1: 篩檢設定
A2: 項目 | B2: 設定值 | C2: 說明
A3: 題數 | B3: 15 | C3: 題目欄數（D 欄起），1 到 60
A4: 檢核題正確答案 | B4: 5 | C4: 例如「本題請選同意」填 5；沒有檢核題時留空
A5: 最短作答秒數 | B5: 30 | C5: 低於此秒數剔除；建議題數 × 2 秒。沒有作答時間時留空
A6: 連續相同門檻 | B6: 10 | C6: 連續選同一個選項達此題數即剔除；建議約為題數的三分之二。不使用時留空
A8: 預試最低人數 | B8: =IF(B3="","",MAX(B3*5,100)) | C8: 題數 × 5，且不低於 100 人（自動計算）

Sheet 原始資料
A1: 編號 | B1: 作答秒數 | C1: 檢核題 | D1: 題1 | E1: 題2 | F1: 題3 | G1: 題4 | H1: 題5 | I1: 題6 | J1: 題7 | K1: 題8 | L1: 題9 | M1: 題10 | N1: 題11 | O1: 題12 | P1: 題13 | Q1: 題14 | R1: 題15 | S1: 題16 | T1: 題17 | U1: 題18 | V1: 題19 | W1: 題20 | X1: 題21 | Y1: 題22 | Z1: 題23 | AA1: 題24 | AB1: 題25 | AC1: 題26 | AD1: 題27 | AE1: 題28 | AF1: 題29 | AG1: 題30 | AH1: 題31 | AI1: 題32 | AJ1: 題33 | AK1: 題34 | AL1: 題35 | AM1: 題36 | AN1: 題37 | AO1: 題38 | AP1: 題39 | AQ1: 題40 | AR1: 題41 | AS1: 題42 | AT1: 題43 | AU1: 題44 | AV1: 題45 | AW1: 題46 | AX1: 題47 | AY1: 題48 | AZ1: 題49 | BA1: 題50 | BB1: 題51 | BC1: 題52 | BD1: 題53 | BE1: 題54 | BF1: 題55 | BG1: 題56 | BH1: 題57 | BI1: 題58 | BJ1: 題59 | BK1: 題60

Sheet 連續計數
A1: 編號 | B1: 連1 | C1: 連2 | D1: 連3 | E1: 連4 | F1: 連5 | G1: 連6 | H1: 連7 | I1: 連8 | J1: 連9 | K1: 連10 | L1: 連11 | M1: 連12 | N1: 連13 | O1: 連14 | P1: 連15 | Q1: 連16 | R1: 連17 | S1: 連18 | T1: 連19 | U1: 連20 | V1: 連21 | W1: 連22 | X1: 連23 | Y1: 連24 | Z1: 連25 | AA1: 連26 | AB1: 連27 | AC1: 連28 | AD1: 連29 | AE1: 連30 | AF1: 連31 | AG1: 連32 | AH1: 連33 | AI1: 連34 | AJ1: 連35 | AK1: 連36 | AL1: 連37 | AM1: 連38 | AN1: 連39 | AO1: 連40 | AP1: 連41 | AQ1: 連42 | AR1: 連43 | AS1: 連44 | AT1: 連45 | AU1: 連46 | AV1: 連47 | AW1: 連48 | AX1: 連49 | AY1: 連50 | AZ1: 連51 | BA1: 連52 | BB1: 連53 | BC1: 連54 | BD1: 連55 | BE1: 連56 | BF1: 連57 | BG1: 連58 | BH1: 連59 | BI1: 連60
A2: =IF(原始資料!$A2="","",原始資料!$A2) | B2: =IF(OR(原始資料!$A2="",1>設定!$B$3,原始資料!D2=""),"",1) | C2: =IF(OR(原始資料!$A2="",2>設定!$B$3,原始資料!E2=""),"",IF(AND(原始資料!D2<>"",原始資料!E2=原始資料!D2),N(B2)+1,1)) | D2: =IF(OR(原始資料!$A2="",3>設定!$B$3,原始資料!F2=""),"",IF(AND(原始資料!E2<>"",原始資料!F2=原始資料!E2),N(C2)+1,1)) | E2: =IF(OR(原始資料!$A2="",4>設定!$B$3,原始資料!G2=""),"",IF(AND(原始資料!F2<>"",原始資料!G2=原始資料!F2),N(D2)+1,1)) | F2: =IF(OR(原始資料!$A2="",5>設定!$B$3,原始資料!H2=""),"",IF(AND(原始資料!G2<>"",原始資料!H2=原始資料!G2),N(E2)+1,1)) | G2: =IF(OR(原始資料!$A2="",6>設定!$B$3,原始資料!I2=""),"",IF(AND(原始資料!H2<>"",原始資料!I2=原始資料!H2),N(F2)+1,1)) | H2: =IF(OR(原始資料!$A2="",7>設定!$B$3,原始資料!J2=""),"",IF(AND(原始資料!I2<>"",原始資料!J2=原始資料!I2),N(G2)+1,1)) | I2: =IF(OR(原始資料!$A2="",8>設定!$B$3,原始資料!K2=""),"",IF(AND(原始資料!J2<>"",原始資料!K2=原始資料!J2),N(H2)+1,1)) | J2: =IF(OR(原始資料!$A2="",9>設定!$B$3,原始資料!L2=""),"",IF(AND(原始資料!K2<>"",原始資料!L2=原始資料!K2),N(I2)+1,1)) | K2: =IF(OR(原始資料!$A2="",10>設定!$B$3,原始資料!M2=""),"",IF(AND(原始資料!L2<>"",原始資料!M2=原始資料!L2),N(J2)+1,1)) | L2: =IF(OR(原始資料!$A2="",11>設定!$B$3,原始資料!N2=""),"",IF(AND(原始資料!M2<>"",原始資料!N2=原始資料!M2),N(K2)+1,1)) | M2: =IF(OR(原始資料!$A2="",12>設定!$B$3,原始資料!O2=""),"",IF(AND(原始資料!N2<>"",原始資料!O2=原始資料!N2),N(L2)+1,1)) | N2: =IF(OR(原始資料!$A2="",13>設定!$B$3,原始資料!P2=""),"",IF(AND(原始資料!O2<>"",原始資料!P2=原始資料!O2),N(M2)+1,1)) | O2: =IF(OR(原始資料!$A2="",14>設定!$B$3,原始資料!Q2=""),"",IF(AND(原始資料!P2<>"",原始資料!Q2=原始資料!P2),N(N2)+1,1)) | P2: =IF(OR(原始資料!$A2="",15>設定!$B$3,原始資料!R2=""),"",IF(AND(原始資料!Q2<>"",原始資料!R2=原始資料!Q2),N(O2)+1,1)) | Q2: =IF(OR(原始資料!$A2="",16>設定!$B$3,原始資料!S2=""),"",IF(AND(原始資料!R2<>"",原始資料!S2=原始資料!R2),N(P2)+1,1)) | R2: =IF(OR(原始資料!$A2="",17>設定!$B$3,原始資料!T2=""),"",IF(AND(原始資料!S2<>"",原始資料!T2=原始資料!S2),N(Q2)+1,1)) | S2: =IF(OR(原始資料!$A2="",18>設定!$B$3,原始資料!U2=""),"",IF(AND(原始資料!T2<>"",原始資料!U2=原始資料!T2),N(R2)+1,1)) | T2: =IF(OR(原始資料!$A2="",19>設定!$B$3,原始資料!V2=""),"",IF(AND(原始資料!U2<>"",原始資料!V2=原始資料!U2),N(S2)+1,1)) | U2: =IF(OR(原始資料!$A2="",20>設定!$B$3,原始資料!W2=""),"",IF(AND(原始資料!V2<>"",原始資料!W2=原始資料!V2),N(T2)+1,1)) | V2: =IF(OR(原始資料!$A2="",21>設定!$B$3,原始資料!X2=""),"",IF(AND(原始資料!W2<>"",原始資料!X2=原始資料!W2),N(U2)+1,1)) | W2: =IF(OR(原始資料!$A2="",22>設定!$B$3,原始資料!Y2=""),"",IF(AND(原始資料!X2<>"",原始資料!Y2=原始資料!X2),N(V2)+1,1)) | X2: =IF(OR(原始資料!$A2="",23>設定!$B$3,原始資料!Z2=""),"",IF(AND(原始資料!Y2<>"",原始資料!Z2=原始資料!Y2),N(W2)+1,1)) | Y2: =IF(OR(原始資料!$A2="",24>設定!$B$3,原始資料!AA2=""),"",IF(AND(原始資料!Z2<>"",原始資料!AA2=原始資料!Z2),N(X2)+1,1)) | Z2: =IF(OR(原始資料!$A2="",25>設定!$B$3,原始資料!AB2=""),"",IF(AND(原始資料!AA2<>"",原始資料!AB2=原始資料!AA2),N(Y2)+1,1)) | AA2: =IF(OR(原始資料!$A2="",26>設定!$B$3,原始資料!AC2=""),"",IF(AND(原始資料!AB2<>"",原始資料!AC2=原始資料!AB2),N(Z2)+1,1)) | AB2: =IF(OR(原始資料!$A2="",27>設定!$B$3,原始資料!AD2=""),"",IF(AND(原始資料!AC2<>"",原始資料!AD2=原始資料!AC2),N(AA2)+1,1)) | AC2: =IF(OR(原始資料!$A2="",28>設定!$B$3,原始資料!AE2=""),"",IF(AND(原始資料!AD2<>"",原始資料!AE2=原始資料!AD2),N(AB2)+1,1)) | AD2: =IF(OR(原始資料!$A2="",29>設定!$B$3,原始資料!AF2=""),"",IF(AND(原始資料!AE2<>"",原始資料!AF2=原始資料!AE2),N(AC2)+1,1)) | AE2: =IF(OR(原始資料!$A2="",30>設定!$B$3,原始資料!AG2=""),"",IF(AND(原始資料!AF2<>"",原始資料!AG2=原始資料!AF2),N(AD2)+1,1)) | AF2: =IF(OR(原始資料!$A2="",31>設定!$B$3,原始資料!AH2=""),"",IF(AND(原始資料!AG2<>"",原始資料!AH2=原始資料!AG2),N(AE2)+1,1)) | AG2: =IF(OR(原始資料!$A2="",32>設定!$B$3,原始資料!AI2=""),"",IF(AND(原始資料!AH2<>"",原始資料!AI2=原始資料!AH2),N(AF2)+1,1)) | AH2: =IF(OR(原始資料!$A2="",33>設定!$B$3,原始資料!AJ2=""),"",IF(AND(原始資料!AI2<>"",原始資料!AJ2=原始資料!AI2),N(AG2)+1,1)) | AI2: =IF(OR(原始資料!$A2="",34>設定!$B$3,原始資料!AK2=""),"",IF(AND(原始資料!AJ2<>"",原始資料!AK2=原始資料!AJ2),N(AH2)+1,1)) | AJ2: =IF(OR(原始資料!$A2="",35>設定!$B$3,原始資料!AL2=""),"",IF(AND(原始資料!AK2<>"",原始資料!AL2=原始資料!AK2),N(AI2)+1,1)) | AK2: =IF(OR(原始資料!$A2="",36>設定!$B$3,原始資料!AM2=""),"",IF(AND(原始資料!AL2<>"",原始資料!AM2=原始資料!AL2),N(AJ2)+1,1)) | AL2: =IF(OR(原始資料!$A2="",37>設定!$B$3,原始資料!AN2=""),"",IF(AND(原始資料!AM2<>"",原始資料!AN2=原始資料!AM2),N(AK2)+1,1)) | AM2: =IF(OR(原始資料!$A2="",38>設定!$B$3,原始資料!AO2=""),"",IF(AND(原始資料!AN2<>"",原始資料!AO2=原始資料!AN2),N(AL2)+1,1)) | AN2: =IF(OR(原始資料!$A2="",39>設定!$B$3,原始資料!AP2=""),"",IF(AND(原始資料!AO2<>"",原始資料!AP2=原始資料!AO2),N(AM2)+1,1)) | AO2: =IF(OR(原始資料!$A2="",40>設定!$B$3,原始資料!AQ2=""),"",IF(AND(原始資料!AP2<>"",原始資料!AQ2=原始資料!AP2),N(AN2)+1,1)) | AP2: =IF(OR(原始資料!$A2="",41>設定!$B$3,原始資料!AR2=""),"",IF(AND(原始資料!AQ2<>"",原始資料!AR2=原始資料!AQ2),N(AO2)+1,1)) | AQ2: =IF(OR(原始資料!$A2="",42>設定!$B$3,原始資料!AS2=""),"",IF(AND(原始資料!AR2<>"",原始資料!AS2=原始資料!AR2),N(AP2)+1,1)) | AR2: =IF(OR(原始資料!$A2="",43>設定!$B$3,原始資料!AT2=""),"",IF(AND(原始資料!AS2<>"",原始資料!AT2=原始資料!AS2),N(AQ2)+1,1)) | AS2: =IF(OR(原始資料!$A2="",44>設定!$B$3,原始資料!AU2=""),"",IF(AND(原始資料!AT2<>"",原始資料!AU2=原始資料!AT2),N(AR2)+1,1)) | AT2: =IF(OR(原始資料!$A2="",45>設定!$B$3,原始資料!AV2=""),"",IF(AND(原始資料!AU2<>"",原始資料!AV2=原始資料!AU2),N(AS2)+1,1)) | AU2: =IF(OR(原始資料!$A2="",46>設定!$B$3,原始資料!AW2=""),"",IF(AND(原始資料!AV2<>"",原始資料!AW2=原始資料!AV2),N(AT2)+1,1)) | AV2: =IF(OR(原始資料!$A2="",47>設定!$B$3,原始資料!AX2=""),"",IF(AND(原始資料!AW2<>"",原始資料!AX2=原始資料!AW2),N(AU2)+1,1)) | AW2: =IF(OR(原始資料!$A2="",48>設定!$B$3,原始資料!AY2=""),"",IF(AND(原始資料!AX2<>"",原始資料!AY2=原始資料!AX2),N(AV2)+1,1)) | AX2: =IF(OR(原始資料!$A2="",49>設定!$B$3,原始資料!AZ2=""),"",IF(AND(原始資料!AY2<>"",原始資料!AZ2=原始資料!AY2),N(AW2)+1,1)) | AY2: =IF(OR(原始資料!$A2="",50>設定!$B$3,原始資料!BA2=""),"",IF(AND(原始資料!AZ2<>"",原始資料!BA2=原始資料!AZ2),N(AX2)+1,1)) | AZ2: =IF(OR(原始資料!$A2="",51>設定!$B$3,原始資料!BB2=""),"",IF(AND(原始資料!BA2<>"",原始資料!BB2=原始資料!BA2),N(AY2)+1,1)) | BA2: =IF(OR(原始資料!$A2="",52>設定!$B$3,原始資料!BC2=""),"",IF(AND(原始資料!BB2<>"",原始資料!BC2=原始資料!BB2),N(AZ2)+1,1)) | BB2: =IF(OR(原始資料!$A2="",53>設定!$B$3,原始資料!BD2=""),"",IF(AND(原始資料!BC2<>"",原始資料!BD2=原始資料!BC2),N(BA2)+1,1)) | BC2: =IF(OR(原始資料!$A2="",54>設定!$B$3,原始資料!BE2=""),"",IF(AND(原始資料!BD2<>"",原始資料!BE2=原始資料!BD2),N(BB2)+1,1)) | BD2: =IF(OR(原始資料!$A2="",55>設定!$B$3,原始資料!BF2=""),"",IF(AND(原始資料!BE2<>"",原始資料!BF2=原始資料!BE2),N(BC2)+1,1)) | BE2: =IF(OR(原始資料!$A2="",56>設定!$B$3,原始資料!BG2=""),"",IF(AND(原始資料!BF2<>"",原始資料!BG2=原始資料!BF2),N(BD2)+1,1)) | BF2: =IF(OR(原始資料!$A2="",57>設定!$B$3,原始資料!BH2=""),"",IF(AND(原始資料!BG2<>"",原始資料!BH2=原始資料!BG2),N(BE2)+1,1)) | BG2: =IF(OR(原始資料!$A2="",58>設定!$B$3,原始資料!BI2=""),"",IF(AND(原始資料!BH2<>"",原始資料!BI2=原始資料!BH2),N(BF2)+1,1)) | BH2: =IF(OR(原始資料!$A2="",59>設定!$B$3,原始資料!BJ2=""),"",IF(AND(原始資料!BI2<>"",原始資料!BJ2=原始資料!BI2),N(BG2)+1,1)) | BI2: =IF(OR(原始資料!$A2="",60>設定!$B$3,原始資料!BK2=""),"",IF(AND(原始資料!BJ2<>"",原始資料!BK2=原始資料!BJ2),N(BH2)+1,1))
A3: =IF(原始資料!$A3="","",原始資料!$A3) | B3: =IF(OR(原始資料!$A3="",1>設定!$B$3,原始資料!D3=""),"",1) | C3: =IF(OR(原始資料!$A3="",2>設定!$B$3,原始資料!E3=""),"",IF(AND(原始資料!D3<>"",原始資料!E3=原始資料!D3),N(B3)+1,1)) | D3: =IF(OR(原始資料!$A3="",3>設定!$B$3,原始資料!F3=""),"",IF(AND(原始資料!E3<>"",原始資料!F3=原始資料!E3),N(C3)+1,1)) | E3: =IF(OR(原始資料!$A3="",4>設定!$B$3,原始資料!G3=""),"",IF(AND(原始資料!F3<>"",原始資料!G3=原始資料!F3),N(D3)+1,1)) | F3: =IF(OR(原始資料!$A3="",5>設定!$B$3,原始資料!H3=""),"",IF(AND(原始資料!G3<>"",原始資料!H3=原始資料!G3),N(E3)+1,1)) | G3: =IF(OR(原始資料!$A3="",6>設定!$B$3,原始資料!I3=""),"",IF(AND(原始資料!H3<>"",原始資料!I3=原始資料!H3),N(F3)+1,1)) | H3: =IF(OR(原始資料!$A3="",7>設定!$B$3,原始資料!J3=""),"",IF(AND(原始資料!I3<>"",原始資料!J3=原始資料!I3),N(G3)+1,1)) | I3: =IF(OR(原始資料!$A3="",8>設定!$B$3,原始資料!K3=""),"",IF(AND(原始資料!J3<>"",原始資料!K3=原始資料!J3),N(H3)+1,1)) | J3: =IF(OR(原始資料!$A3="",9>設定!$B$3,原始資料!L3=""),"",IF(AND(原始資料!K3<>"",原始資料!L3=原始資料!K3),N(I3)+1,1)) | K3: =IF(OR(原始資料!$A3="",10>設定!$B$3,原始資料!M3=""),"",IF(AND(原始資料!L3<>"",原始資料!M3=原始資料!L3),N(J3)+1,1)) | L3: =IF(OR(原始資料!$A3="",11>設定!$B$3,原始資料!N3=""),"",IF(AND(原始資料!M3<>"",原始資料!N3=原始資料!M3),N(K3)+1,1)) | M3: =IF(OR(原始資料!$A3="",12>設定!$B$3,原始資料!O3=""),"",IF(AND(原始資料!N3<>"",原始資料!O3=原始資料!N3),N(L3)+1,1)) | N3: =IF(OR(原始資料!$A3="",13>設定!$B$3,原始資料!P3=""),"",IF(AND(原始資料!O3<>"",原始資料!P3=原始資料!O3),N(M3)+1,1)) | O3: =IF(OR(原始資料!$A3="",14>設定!$B$3,原始資料!Q3=""),"",IF(AND(原始資料!P3<>"",原始資料!Q3=原始資料!P3),N(N3)+1,1)) | P3: =IF(OR(原始資料!$A3="",15>設定!$B$3,原始資料!R3=""),"",IF(AND(原始資料!Q3<>"",原始資料!R3=原始資料!Q3),N(O3)+1,1)) | Q3: =IF(OR(原始資料!$A3="",16>設定!$B$3,原始資料!S3=""),"",IF(AND(原始資料!R3<>"",原始資料!S3=原始資料!R3),N(P3)+1,1)) | R3: =IF(OR(原始資料!$A3="",17>設定!$B$3,原始資料!T3=""),"",IF(AND(原始資料!S3<>"",原始資料!T3=原始資料!S3),N(Q3)+1,1)) | S3: =IF(OR(原始資料!$A3="",18>設定!$B$3,原始資料!U3=""),"",IF(AND(原始資料!T3<>"",原始資料!U3=原始資料!T3),N(R3)+1,1)) | T3: =IF(OR(原始資料!$A3="",19>設定!$B$3,原始資料!V3=""),"",IF(AND(原始資料!U3<>"",原始資料!V3=原始資料!U3),N(S3)+1,1)) | U3: =IF(OR(原始資料!$A3="",20>設定!$B$3,原始資料!W3=""),"",IF(AND(原始資料!V3<>"",原始資料!W3=原始資料!V3),N(T3)+1,1)) | V3: =IF(OR(原始資料!$A3="",21>設定!$B$3,原始資料!X3=""),"",IF(AND(原始資料!W3<>"",原始資料!X3=原始資料!W3),N(U3)+1,1)) | W3: =IF(OR(原始資料!$A3="",22>設定!$B$3,原始資料!Y3=""),"",IF(AND(原始資料!X3<>"",原始資料!Y3=原始資料!X3),N(V3)+1,1)) | X3: =IF(OR(原始資料!$A3="",23>設定!$B$3,原始資料!Z3=""),"",IF(AND(原始資料!Y3<>"",原始資料!Z3=原始資料!Y3),N(W3)+1,1)) | Y3: =IF(OR(原始資料!$A3="",24>設定!$B$3,原始資料!AA3=""),"",IF(AND(原始資料!Z3<>"",原始資料!AA3=原始資料!Z3),N(X3)+1,1)) | Z3: =IF(OR(原始資料!$A3="",25>設定!$B$3,原始資料!AB3=""),"",IF(AND(原始資料!AA3<>"",原始資料!AB3=原始資料!AA3),N(Y3)+1,1)) | AA3: =IF(OR(原始資料!$A3="",26>設定!$B$3,原始資料!AC3=""),"",IF(AND(原始資料!AB3<>"",原始資料!AC3=原始資料!AB3),N(Z3)+1,1)) | AB3: =IF(OR(原始資料!$A3="",27>設定!$B$3,原始資料!AD3=""),"",IF(AND(原始資料!AC3<>"",原始資料!AD3=原始資料!AC3),N(AA3)+1,1)) | AC3: =IF(OR(原始資料!$A3="",28>設定!$B$3,原始資料!AE3=""),"",IF(AND(原始資料!AD3<>"",原始資料!AE3=原始資料!AD3),N(AB3)+1,1)) | AD3: =IF(OR(原始資料!$A3="",29>設定!$B$3,原始資料!AF3=""),"",IF(AND(原始資料!AE3<>"",原始資料!AF3=原始資料!AE3),N(AC3)+1,1)) | AE3: =IF(OR(原始資料!$A3="",30>設定!$B$3,原始資料!AG3=""),"",IF(AND(原始資料!AF3<>"",原始資料!AG3=原始資料!AF3),N(AD3)+1,1)) | AF3: =IF(OR(原始資料!$A3="",31>設定!$B$3,原始資料!AH3=""),"",IF(AND(原始資料!AG3<>"",原始資料!AH3=原始資料!AG3),N(AE3)+1,1)) | AG3: =IF(OR(原始資料!$A3="",32>設定!$B$3,原始資料!AI3=""),"",IF(AND(原始資料!AH3<>"",原始資料!AI3=原始資料!AH3),N(AF3)+1,1)) | AH3: =IF(OR(原始資料!$A3="",33>設定!$B$3,原始資料!AJ3=""),"",IF(AND(原始資料!AI3<>"",原始資料!AJ3=原始資料!AI3),N(AG3)+1,1)) | AI3: =IF(OR(原始資料!$A3="",34>設定!$B$3,原始資料!AK3=""),"",IF(AND(原始資料!AJ3<>"",原始資料!AK3=原始資料!AJ3),N(AH3)+1,1)) | AJ3: =IF(OR(原始資料!$A3="",35>設定!$B$3,原始資料!AL3=""),"",IF(AND(原始資料!AK3<>"",原始資料!AL3=原始資料!AK3),N(AI3)+1,1)) | AK3: =IF(OR(原始資料!$A3="",36>設定!$B$3,原始資料!AM3=""),"",IF(AND(原始資料!AL3<>"",原始資料!AM3=原始資料!AL3),N(AJ3)+1,1)) | AL3: =IF(OR(原始資料!$A3="",37>設定!$B$3,原始資料!AN3=""),"",IF(AND(原始資料!AM3<>"",原始資料!AN3=原始資料!AM3),N(AK3)+1,1)) | AM3: =IF(OR(原始資料!$A3="",38>設定!$B$3,原始資料!AO3=""),"",IF(AND(原始資料!AN3<>"",原始資料!AO3=原始資料!AN3),N(AL3)+1,1)) | AN3: =IF(OR(原始資料!$A3="",39>設定!$B$3,原始資料!AP3=""),"",IF(AND(原始資料!AO3<>"",原始資料!AP3=原始資料!AO3),N(AM3)+1,1)) | AO3: =IF(OR(原始資料!$A3="",40>設定!$B$3,原始資料!AQ3=""),"",IF(AND(原始資料!AP3<>"",原始資料!AQ3=原始資料!AP3),N(AN3)+1,1)) | AP3: =IF(OR(原始資料!$A3="",41>設定!$B$3,原始資料!AR3=""),"",IF(AND(原始資料!AQ3<>"",原始資料!AR3=原始資料!AQ3),N(AO3)+1,1)) | AQ3: =IF(OR(原始資料!$A3="",42>設定!$B$3,原始資料!AS3=""),"",IF(AND(原始資料!AR3<>"",原始資料!AS3=原始資料!AR3),N(AP3)+1,1)) | AR3: =IF(OR(原始資料!$A3="",43>設定!$B$3,原始資料!AT3=""),"",IF(AND(原始資料!AS3<>"",原始資料!AT3=原始資料!AS3),N(AQ3)+1,1)) | AS3: =IF(OR(原始資料!$A3="",44>設定!$B$3,原始資料!AU3=""),"",IF(AND(原始資料!AT3<>"",原始資料!AU3=原始資料!AT3),N(AR3)+1,1)) | AT3: =IF(OR(原始資料!$A3="",45>設定!$B$3,原始資料!AV3=""),"",IF(AND(原始資料!AU3<>"",原始資料!AV3=原始資料!AU3),N(AS3)+1,1)) | AU3: =IF(OR(原始資料!$A3="",46>設定!$B$3,原始資料!AW3=""),"",IF(AND(原始資料!AV3<>"",原始資料!AW3=原始資料!AV3),N(AT3)+1,1)) | AV3: =IF(OR(原始資料!$A3="",47>設定!$B$3,原始資料!AX3=""),"",IF(AND(原始資料!AW3<>"",原始資料!AX3=原始資料!AW3),N(AU3)+1,1)) | AW3: =IF(OR(原始資料!$A3="",48>設定!$B$3,原始資料!AY3=""),"",IF(AND(原始資料!AX3<>"",原始資料!AY3=原始資料!AX3),N(AV3)+1,1)) | AX3: =IF(OR(原始資料!$A3="",49>設定!$B$3,原始資料!AZ3=""),"",IF(AND(原始資料!AY3<>"",原始資料!AZ3=原始資料!AY3),N(AW3)+1,1)) | AY3: =IF(OR(原始資料!$A3="",50>設定!$B$3,原始資料!BA3=""),"",IF(AND(原始資料!AZ3<>"",原始資料!BA3=原始資料!AZ3),N(AX3)+1,1)) | AZ3: =IF(OR(原始資料!$A3="",51>設定!$B$3,原始資料!BB3=""),"",IF(AND(原始資料!BA3<>"",原始資料!BB3=原始資料!BA3),N(AY3)+1,1)) | BA3: =IF(OR(原始資料!$A3="",52>設定!$B$3,原始資料!BC3=""),"",IF(AND(原始資料!BB3<>"",原始資料!BC3=原始資料!BB3),N(AZ3)+1,1)) | BB3: =IF(OR(原始資料!$A3="",53>設定!$B$3,原始資料!BD3=""),"",IF(AND(原始資料!BC3<>"",原始資料!BD3=原始資料!BC3),N(BA3)+1,1)) | BC3: =IF(OR(原始資料!$A3="",54>設定!$B$3,原始資料!BE3=""),"",IF(AND(原始資料!BD3<>"",原始資料!BE3=原始資料!BD3),N(BB3)+1,1)) | BD3: =IF(OR(原始資料!$A3="",55>設定!$B$3,原始資料!BF3=""),"",IF(AND(原始資料!BE3<>"",原始資料!BF3=原始資料!BE3),N(BC3)+1,1)) | BE3: =IF(OR(原始資料!$A3="",56>設定!$B$3,原始資料!BG3=""),"",IF(AND(原始資料!BF3<>"",原始資料!BG3=原始資料!BF3),N(BD3)+1,1)) | BF3: =IF(OR(原始資料!$A3="",57>設定!$B$3,原始資料!BH3=""),"",IF(AND(原始資料!BG3<>"",原始資料!BH3=原始資料!BG3),N(BE3)+1,1)) | BG3: =IF(OR(原始資料!$A3="",58>設定!$B$3,原始資料!BI3=""),"",IF(AND(原始資料!BH3<>"",原始資料!BI3=原始資料!BH3),N(BF3)+1,1)) | BH3: =IF(OR(原始資料!$A3="",59>設定!$B$3,原始資料!BJ3=""),"",IF(AND(原始資料!BI3<>"",原始資料!BJ3=原始資料!BI3),N(BG3)+1,1)) | BI3: =IF(OR(原始資料!$A3="",60>設定!$B$3,原始資料!BK3=""),"",IF(AND(原始資料!BJ3<>"",原始資料!BK3=原始資料!BJ3),N(BH3)+1,1))
A4: =IF(原始資料!$A4="","",原始資料!$A4) | B4: =IF(OR(原始資料!$A4="",1>設定!$B$3,原始資料!D4=""),"",1) | C4: =IF(OR(原始資料!$A4="",2>設定!$B$3,原始資料!E4=""),"",IF(AND(原始資料!D4<>"",原始資料!E4=原始資料!D4),N(B4)+1,1)) | D4: =IF(OR(原始資料!$A4="",3>設定!$B$3,原始資料!F4=""),"",IF(AND(原始資料!E4<>"",原始資料!F4=原始資料!E4),N(C4)+1,1)) | E4: =IF(OR(原始資料!$A4="",4>設定!$B$3,原始資料!G4=""),"",IF(AND(原始資料!F4<>"",原始資料!G4=原始資料!F4),N(D4)+1,1)) | F4: =IF(OR(原始資料!$A4="",5>設定!$B$3,原始資料!H4=""),"",IF(AND(原始資料!G4<>"",原始資料!H4=原始資料!G4),N(E4)+1,1)) | G4: =IF(OR(原始資料!$A4="",6>設定!$B$3,原始資料!I4=""),"",IF(AND(原始資料!H4<>"",原始資料!I4=原始資料!H4),N(F4)+1,1)) | H4: =IF(OR(原始資料!$A4="",7>設定!$B$3,原始資料!J4=""),"",IF(AND(原始資料!I4<>"",原始資料!J4=原始資料!I4),N(G4)+1,1)) | I4: =IF(OR(原始資料!$A4="",8>設定!$B$3,原始資料!K4=""),"",IF(AND(原始資料!J4<>"",原始資料!K4=原始資料!J4),N(H4)+1,1)) | J4: =IF(OR(原始資料!$A4="",9>設定!$B$3,原始資料!L4=""),"",IF(AND(原始資料!K4<>"",原始資料!L4=原始資料!K4),N(I4)+1,1)) | K4: =IF(OR(原始資料!$A4="",10>設定!$B$3,原始資料!M4=""),"",IF(AND(原始資料!L4<>"",原始資料!M4=原始資料!L4),N(J4)+1,1)) | L4: =IF(OR(原始資料!$A4="",11>設定!$B$3,原始資料!N4=""),"",IF(AND(原始資料!M4<>"",原始資料!N4=原始資料!M4),N(K4)+1,1)) | M4: =IF(OR(原始資料!$A4="",12>設定!$B$3,原始資料!O4=""),"",IF(AND(原始資料!N4<>"",原始資料!O4=原始資料!N4),N(L4)+1,1)) | N4: =IF(OR(原始資料!$A4="",13>設定!$B$3,原始資料!P4=""),"",IF(AND(原始資料!O4<>"",原始資料!P4=原始資料!O4),N(M4)+1,1)) | O4: =IF(OR(原始資料!$A4="",14>設定!$B$3,原始資料!Q4=""),"",IF(AND(原始資料!P4<>"",原始資料!Q4=原始資料!P4),N(N4)+1,1)) | P4: =IF(OR(原始資料!$A4="",15>設定!$B$3,原始資料!R4=""),"",IF(AND(原始資料!Q4<>"",原始資料!R4=原始資料!Q4),N(O4)+1,1)) | Q4: =IF(OR(原始資料!$A4="",16>設定!$B$3,原始資料!S4=""),"",IF(AND(原始資料!R4<>"",原始資料!S4=原始資料!R4),N(P4)+1,1)) | R4: =IF(OR(原始資料!$A4="",17>設定!$B$3,原始資料!T4=""),"",IF(AND(原始資料!S4<>"",原始資料!T4=原始資料!S4),N(Q4)+1,1)) | S4: =IF(OR(原始資料!$A4="",18>設定!$B$3,原始資料!U4=""),"",IF(AND(原始資料!T4<>"",原始資料!U4=原始資料!T4),N(R4)+1,1)) | T4: =IF(OR(原始資料!$A4="",19>設定!$B$3,原始資料!V4=""),"",IF(AND(原始資料!U4<>"",原始資料!V4=原始資料!U4),N(S4)+1,1)) | U4: =IF(OR(原始資料!$A4="",20>設定!$B$3,原始資料!W4=""),"",IF(AND(原始資料!V4<>"",原始資料!W4=原始資料!V4),N(T4)+1,1)) | V4: =IF(OR(原始資料!$A4="",21>設定!$B$3,原始資料!X4=""),"",IF(AND(原始資料!W4<>"",原始資料!X4=原始資料!W4),N(U4)+1,1)) | W4: =IF(OR(原始資料!$A4="",22>設定!$B$3,原始資料!Y4=""),"",IF(AND(原始資料!X4<>"",原始資料!Y4=原始資料!X4),N(V4)+1,1)) | X4: =IF(OR(原始資料!$A4="",23>設定!$B$3,原始資料!Z4=""),"",IF(AND(原始資料!Y4<>"",原始資料!Z4=原始資料!Y4),N(W4)+1,1)) | Y4: =IF(OR(原始資料!$A4="",24>設定!$B$3,原始資料!AA4=""),"",IF(AND(原始資料!Z4<>"",原始資料!AA4=原始資料!Z4),N(X4)+1,1)) | Z4: =IF(OR(原始資料!$A4="",25>設定!$B$3,原始資料!AB4=""),"",IF(AND(原始資料!AA4<>"",原始資料!AB4=原始資料!AA4),N(Y4)+1,1)) | AA4: =IF(OR(原始資料!$A4="",26>設定!$B$3,原始資料!AC4=""),"",IF(AND(原始資料!AB4<>"",原始資料!AC4=原始資料!AB4),N(Z4)+1,1)) | AB4: =IF(OR(原始資料!$A4="",27>設定!$B$3,原始資料!AD4=""),"",IF(AND(原始資料!AC4<>"",原始資料!AD4=原始資料!AC4),N(AA4)+1,1)) | AC4: =IF(OR(原始資料!$A4="",28>設定!$B$3,原始資料!AE4=""),"",IF(AND(原始資料!AD4<>"",原始資料!AE4=原始資料!AD4),N(AB4)+1,1)) | AD4: =IF(OR(原始資料!$A4="",29>設定!$B$3,原始資料!AF4=""),"",IF(AND(原始資料!AE4<>"",原始資料!AF4=原始資料!AE4),N(AC4)+1,1)) | AE4: =IF(OR(原始資料!$A4="",30>設定!$B$3,原始資料!AG4=""),"",IF(AND(原始資料!AF4<>"",原始資料!AG4=原始資料!AF4),N(AD4)+1,1)) | AF4: =IF(OR(原始資料!$A4="",31>設定!$B$3,原始資料!AH4=""),"",IF(AND(原始資料!AG4<>"",原始資料!AH4=原始資料!AG4),N(AE4)+1,1)) | AG4: =IF(OR(原始資料!$A4="",32>設定!$B$3,原始資料!AI4=""),"",IF(AND(原始資料!AH4<>"",原始資料!AI4=原始資料!AH4),N(AF4)+1,1)) | AH4: =IF(OR(原始資料!$A4="",33>設定!$B$3,原始資料!AJ4=""),"",IF(AND(原始資料!AI4<>"",原始資料!AJ4=原始資料!AI4),N(AG4)+1,1)) | AI4: =IF(OR(原始資料!$A4="",34>設定!$B$3,原始資料!AK4=""),"",IF(AND(原始資料!AJ4<>"",原始資料!AK4=原始資料!AJ4),N(AH4)+1,1)) | AJ4: =IF(OR(原始資料!$A4="",35>設定!$B$3,原始資料!AL4=""),"",IF(AND(原始資料!AK4<>"",原始資料!AL4=原始資料!AK4),N(AI4)+1,1)) | AK4: =IF(OR(原始資料!$A4="",36>設定!$B$3,原始資料!AM4=""),"",IF(AND(原始資料!AL4<>"",原始資料!AM4=原始資料!AL4),N(AJ4)+1,1)) | AL4: =IF(OR(原始資料!$A4="",37>設定!$B$3,原始資料!AN4=""),"",IF(AND(原始資料!AM4<>"",原始資料!AN4=原始資料!AM4),N(AK4)+1,1)) | AM4: =IF(OR(原始資料!$A4="",38>設定!$B$3,原始資料!AO4=""),"",IF(AND(原始資料!AN4<>"",原始資料!AO4=原始資料!AN4),N(AL4)+1,1)) | AN4: =IF(OR(原始資料!$A4="",39>設定!$B$3,原始資料!AP4=""),"",IF(AND(原始資料!AO4<>"",原始資料!AP4=原始資料!AO4),N(AM4)+1,1)) | AO4: =IF(OR(原始資料!$A4="",40>設定!$B$3,原始資料!AQ4=""),"",IF(AND(原始資料!AP4<>"",原始資料!AQ4=原始資料!AP4),N(AN4)+1,1)) | AP4: =IF(OR(原始資料!$A4="",41>設定!$B$3,原始資料!AR4=""),"",IF(AND(原始資料!AQ4<>"",原始資料!AR4=原始資料!AQ4),N(AO4)+1,1)) | AQ4: =IF(OR(原始資料!$A4="",42>設定!$B$3,原始資料!AS4=""),"",IF(AND(原始資料!AR4<>"",原始資料!AS4=原始資料!AR4),N(AP4)+1,1)) | AR4: =IF(OR(原始資料!$A4="",43>設定!$B$3,原始資料!AT4=""),"",IF(AND(原始資料!AS4<>"",原始資料!AT4=原始資料!AS4),N(AQ4)+1,1)) | AS4: =IF(OR(原始資料!$A4="",44>設定!$B$3,原始資料!AU4=""),"",IF(AND(原始資料!AT4<>"",原始資料!AU4=原始資料!AT4),N(AR4)+1,1)) | AT4: =IF(OR(原始資料!$A4="",45>設定!$B$3,原始資料!AV4=""),"",IF(AND(原始資料!AU4<>"",原始資料!AV4=原始資料!AU4),N(AS4)+1,1)) | AU4: =IF(OR(原始資料!$A4="",46>設定!$B$3,原始資料!AW4=""),"",IF(AND(原始資料!AV4<>"",原始資料!AW4=原始資料!AV4),N(AT4)+1,1)) | AV4: =IF(OR(原始資料!$A4="",47>設定!$B$3,原始資料!AX4=""),"",IF(AND(原始資料!AW4<>"",原始資料!AX4=原始資料!AW4),N(AU4)+1,1)) | AW4: =IF(OR(原始資料!$A4="",48>設定!$B$3,原始資料!AY4=""),"",IF(AND(原始資料!AX4<>"",原始資料!AY4=原始資料!AX4),N(AV4)+1,1)) | AX4: =IF(OR(原始資料!$A4="",49>設定!$B$3,原始資料!AZ4=""),"",IF(AND(原始資料!AY4<>"",原始資料!AZ4=原始資料!AY4),N(AW4)+1,1)) | AY4: =IF(OR(原始資料!$A4="",50>設定!$B$3,原始資料!BA4=""),"",IF(AND(原始資料!AZ4<>"",原始資料!BA4=原始資料!AZ4),N(AX4)+1,1)) | AZ4: =IF(OR(原始資料!$A4="",51>設定!$B$3,原始資料!BB4=""),"",IF(AND(原始資料!BA4<>"",原始資料!BB4=原始資料!BA4),N(AY4)+1,1)) | BA4: =IF(OR(原始資料!$A4="",52>設定!$B$3,原始資料!BC4=""),"",IF(AND(原始資料!BB4<>"",原始資料!BC4=原始資料!BB4),N(AZ4)+1,1)) | BB4: =IF(OR(原始資料!$A4="",53>設定!$B$3,原始資料!BD4=""),"",IF(AND(原始資料!BC4<>"",原始資料!BD4=原始資料!BC4),N(BA4)+1,1)) | BC4: =IF(OR(原始資料!$A4="",54>設定!$B$3,原始資料!BE4=""),"",IF(AND(原始資料!BD4<>"",原始資料!BE4=原始資料!BD4),N(BB4)+1,1)) | BD4: =IF(OR(原始資料!$A4="",55>設定!$B$3,原始資料!BF4=""),"",IF(AND(原始資料!BE4<>"",原始資料!BF4=原始資料!BE4),N(BC4)+1,1)) | BE4: =IF(OR(原始資料!$A4="",56>設定!$B$3,原始資料!BG4=""),"",IF(AND(原始資料!BF4<>"",原始資料!BG4=原始資料!BF4),N(BD4)+1,1)) | BF4: =IF(OR(原始資料!$A4="",57>設定!$B$3,原始資料!BH4=""),"",IF(AND(原始資料!BG4<>"",原始資料!BH4=原始資料!BG4),N(BE4)+1,1)) | BG4: =IF(OR(原始資料!$A4="",58>設定!$B$3,原始資料!BI4=""),"",IF(AND(原始資料!BH4<>"",原始資料!BI4=原始資料!BH4),N(BF4)+1,1)) | BH4: =IF(OR(原始資料!$A4="",59>設定!$B$3,原始資料!BJ4=""),"",IF(AND(原始資料!BI4<>"",原始資料!BJ4=原始資料!BI4),N(BG4)+1,1)) | BI4: =IF(OR(原始資料!$A4="",60>設定!$B$3,原始資料!BK4=""),"",IF(AND(原始資料!BJ4<>"",原始資料!BK4=原始資料!BJ4),N(BH4)+1,1))
A5: =IF(原始資料!$A5="","",原始資料!$A5) | B5: =IF(OR(原始資料!$A5="",1>設定!$B$3,原始資料!D5=""),"",1) | C5: =IF(OR(原始資料!$A5="",2>設定!$B$3,原始資料!E5=""),"",IF(AND(原始資料!D5<>"",原始資料!E5=原始資料!D5),N(B5)+1,1)) | D5: =IF(OR(原始資料!$A5="",3>設定!$B$3,原始資料!F5=""),"",IF(AND(原始資料!E5<>"",原始資料!F5=原始資料!E5),N(C5)+1,1)) | E5: =IF(OR(原始資料!$A5="",4>設定!$B$3,原始資料!G5=""),"",IF(AND(原始資料!F5<>"",原始資料!G5=原始資料!F5),N(D5)+1,1)) | F5: =IF(OR(原始資料!$A5="",5>設定!$B$3,原始資料!H5=""),"",IF(AND(原始資料!G5<>"",原始資料!H5=原始資料!G5),N(E5)+1,1)) | G5: =IF(OR(原始資料!$A5="",6>設定!$B$3,原始資料!I5=""),"",IF(AND(原始資料!H5<>"",原始資料!I5=原始資料!H5),N(F5)+1,1)) | H5: =IF(OR(原始資料!$A5="",7>設定!$B$3,原始資料!J5=""),"",IF(AND(原始資料!I5<>"",原始資料!J5=原始資料!I5),N(G5)+1,1)) | I5: =IF(OR(原始資料!$A5="",8>設定!$B$3,原始資料!K5=""),"",IF(AND(原始資料!J5<>"",原始資料!K5=原始資料!J5),N(H5)+1,1)) | J5: =IF(OR(原始資料!$A5="",9>設定!$B$3,原始資料!L5=""),"",IF(AND(原始資料!K5<>"",原始資料!L5=原始資料!K5),N(I5)+1,1)) | K5: =IF(OR(原始資料!$A5="",10>設定!$B$3,原始資料!M5=""),"",IF(AND(原始資料!L5<>"",原始資料!M5=原始資料!L5),N(J5)+1,1)) | L5: =IF(OR(原始資料!$A5="",11>設定!$B$3,原始資料!N5=""),"",IF(AND(原始資料!M5<>"",原始資料!N5=原始資料!M5),N(K5)+1,1)) | M5: =IF(OR(原始資料!$A5="",12>設定!$B$3,原始資料!O5=""),"",IF(AND(原始資料!N5<>"",原始資料!O5=原始資料!N5),N(L5)+1,1)) | N5: =IF(OR(原始資料!$A5="",13>設定!$B$3,原始資料!P5=""),"",IF(AND(原始資料!O5<>"",原始資料!P5=原始資料!O5),N(M5)+1,1)) | O5: =IF(OR(原始資料!$A5="",14>設定!$B$3,原始資料!Q5=""),"",IF(AND(原始資料!P5<>"",原始資料!Q5=原始資料!P5),N(N5)+1,1)) | P5: =IF(OR(原始資料!$A5="",15>設定!$B$3,原始資料!R5=""),"",IF(AND(原始資料!Q5<>"",原始資料!R5=原始資料!Q5),N(O5)+1,1)) | Q5: =IF(OR(原始資料!$A5="",16>設定!$B$3,原始資料!S5=""),"",IF(AND(原始資料!R5<>"",原始資料!S5=原始資料!R5),N(P5)+1,1)) | R5: =IF(OR(原始資料!$A5="",17>設定!$B$3,原始資料!T5=""),"",IF(AND(原始資料!S5<>"",原始資料!T5=原始資料!S5),N(Q5)+1,1)) | S5: =IF(OR(原始資料!$A5="",18>設定!$B$3,原始資料!U5=""),"",IF(AND(原始資料!T5<>"",原始資料!U5=原始資料!T5),N(R5)+1,1)) | T5: =IF(OR(原始資料!$A5="",19>設定!$B$3,原始資料!V5=""),"",IF(AND(原始資料!U5<>"",原始資料!V5=原始資料!U5),N(S5)+1,1)) | U5: =IF(OR(原始資料!$A5="",20>設定!$B$3,原始資料!W5=""),"",IF(AND(原始資料!V5<>"",原始資料!W5=原始資料!V5),N(T5)+1,1)) | V5: =IF(OR(原始資料!$A5="",21>設定!$B$3,原始資料!X5=""),"",IF(AND(原始資料!W5<>"",原始資料!X5=原始資料!W5),N(U5)+1,1)) | W5: =IF(OR(原始資料!$A5="",22>設定!$B$3,原始資料!Y5=""),"",IF(AND(原始資料!X5<>"",原始資料!Y5=原始資料!X5),N(V5)+1,1)) | X5: =IF(OR(原始資料!$A5="",23>設定!$B$3,原始資料!Z5=""),"",IF(AND(原始資料!Y5<>"",原始資料!Z5=原始資料!Y5),N(W5)+1,1)) | Y5: =IF(OR(原始資料!$A5="",24>設定!$B$3,原始資料!AA5=""),"",IF(AND(原始資料!Z5<>"",原始資料!AA5=原始資料!Z5),N(X5)+1,1)) | Z5: =IF(OR(原始資料!$A5="",25>設定!$B$3,原始資料!AB5=""),"",IF(AND(原始資料!AA5<>"",原始資料!AB5=原始資料!AA5),N(Y5)+1,1)) | AA5: =IF(OR(原始資料!$A5="",26>設定!$B$3,原始資料!AC5=""),"",IF(AND(原始資料!AB5<>"",原始資料!AC5=原始資料!AB5),N(Z5)+1,1)) | AB5: =IF(OR(原始資料!$A5="",27>設定!$B$3,原始資料!AD5=""),"",IF(AND(原始資料!AC5<>"",原始資料!AD5=原始資料!AC5),N(AA5)+1,1)) | AC5: =IF(OR(原始資料!$A5="",28>設定!$B$3,原始資料!AE5=""),"",IF(AND(原始資料!AD5<>"",原始資料!AE5=原始資料!AD5),N(AB5)+1,1)) | AD5: =IF(OR(原始資料!$A5="",29>設定!$B$3,原始資料!AF5=""),"",IF(AND(原始資料!AE5<>"",原始資料!AF5=原始資料!AE5),N(AC5)+1,1)) | AE5: =IF(OR(原始資料!$A5="",30>設定!$B$3,原始資料!AG5=""),"",IF(AND(原始資料!AF5<>"",原始資料!AG5=原始資料!AF5),N(AD5)+1,1)) | AF5: =IF(OR(原始資料!$A5="",31>設定!$B$3,原始資料!AH5=""),"",IF(AND(原始資料!AG5<>"",原始資料!AH5=原始資料!AG5),N(AE5)+1,1)) | AG5: =IF(OR(原始資料!$A5="",32>設定!$B$3,原始資料!AI5=""),"",IF(AND(原始資料!AH5<>"",原始資料!AI5=原始資料!AH5),N(AF5)+1,1)) | AH5: =IF(OR(原始資料!$A5="",33>設定!$B$3,原始資料!AJ5=""),"",IF(AND(原始資料!AI5<>"",原始資料!AJ5=原始資料!AI5),N(AG5)+1,1)) | AI5: =IF(OR(原始資料!$A5="",34>設定!$B$3,原始資料!AK5=""),"",IF(AND(原始資料!AJ5<>"",原始資料!AK5=原始資料!AJ5),N(AH5)+1,1)) | AJ5: =IF(OR(原始資料!$A5="",35>設定!$B$3,原始資料!AL5=""),"",IF(AND(原始資料!AK5<>"",原始資料!AL5=原始資料!AK5),N(AI5)+1,1)) | AK5: =IF(OR(原始資料!$A5="",36>設定!$B$3,原始資料!AM5=""),"",IF(AND(原始資料!AL5<>"",原始資料!AM5=原始資料!AL5),N(AJ5)+1,1)) | AL5: =IF(OR(原始資料!$A5="",37>設定!$B$3,原始資料!AN5=""),"",IF(AND(原始資料!AM5<>"",原始資料!AN5=原始資料!AM5),N(AK5)+1,1)) | AM5: =IF(OR(原始資料!$A5="",38>設定!$B$3,原始資料!AO5=""),"",IF(AND(原始資料!AN5<>"",原始資料!AO5=原始資料!AN5),N(AL5)+1,1)) | AN5: =IF(OR(原始資料!$A5="",39>設定!$B$3,原始資料!AP5=""),"",IF(AND(原始資料!AO5<>"",原始資料!AP5=原始資料!AO5),N(AM5)+1,1)) | AO5: =IF(OR(原始資料!$A5="",40>設定!$B$3,原始資料!AQ5=""),"",IF(AND(原始資料!AP5<>"",原始資料!AQ5=原始資料!AP5),N(AN5)+1,1)) | AP5: =IF(OR(原始資料!$A5="",41>設定!$B$3,原始資料!AR5=""),"",IF(AND(原始資料!AQ5<>"",原始資料!AR5=原始資料!AQ5),N(AO5)+1,1)) | AQ5: =IF(OR(原始資料!$A5="",42>設定!$B$3,原始資料!AS5=""),"",IF(AND(原始資料!AR5<>"",原始資料!AS5=原始資料!AR5),N(AP5)+1,1)) | AR5: =IF(OR(原始資料!$A5="",43>設定!$B$3,原始資料!AT5=""),"",IF(AND(原始資料!AS5<>"",原始資料!AT5=原始資料!AS5),N(AQ5)+1,1)) | AS5: =IF(OR(原始資料!$A5="",44>設定!$B$3,原始資料!AU5=""),"",IF(AND(原始資料!AT5<>"",原始資料!AU5=原始資料!AT5),N(AR5)+1,1)) | AT5: =IF(OR(原始資料!$A5="",45>設定!$B$3,原始資料!AV5=""),"",IF(AND(原始資料!AU5<>"",原始資料!AV5=原始資料!AU5),N(AS5)+1,1)) | AU5: =IF(OR(原始資料!$A5="",46>設定!$B$3,原始資料!AW5=""),"",IF(AND(原始資料!AV5<>"",原始資料!AW5=原始資料!AV5),N(AT5)+1,1)) | AV5: =IF(OR(原始資料!$A5="",47>設定!$B$3,原始資料!AX5=""),"",IF(AND(原始資料!AW5<>"",原始資料!AX5=原始資料!AW5),N(AU5)+1,1)) | AW5: =IF(OR(原始資料!$A5="",48>設定!$B$3,原始資料!AY5=""),"",IF(AND(原始資料!AX5<>"",原始資料!AY5=原始資料!AX5),N(AV5)+1,1)) | AX5: =IF(OR(原始資料!$A5="",49>設定!$B$3,原始資料!AZ5=""),"",IF(AND(原始資料!AY5<>"",原始資料!AZ5=原始資料!AY5),N(AW5)+1,1)) | AY5: =IF(OR(原始資料!$A5="",50>設定!$B$3,原始資料!BA5=""),"",IF(AND(原始資料!AZ5<>"",原始資料!BA5=原始資料!AZ5),N(AX5)+1,1)) | AZ5: =IF(OR(原始資料!$A5="",51>設定!$B$3,原始資料!BB5=""),"",IF(AND(原始資料!BA5<>"",原始資料!BB5=原始資料!BA5),N(AY5)+1,1)) | BA5: =IF(OR(原始資料!$A5="",52>設定!$B$3,原始資料!BC5=""),"",IF(AND(原始資料!BB5<>"",原始資料!BC5=原始資料!BB5),N(AZ5)+1,1)) | BB5: =IF(OR(原始資料!$A5="",53>設定!$B$3,原始資料!BD5=""),"",IF(AND(原始資料!BC5<>"",原始資料!BD5=原始資料!BC5),N(BA5)+1,1)) | BC5: =IF(OR(原始資料!$A5="",54>設定!$B$3,原始資料!BE5=""),"",IF(AND(原始資料!BD5<>"",原始資料!BE5=原始資料!BD5),N(BB5)+1,1)) | BD5: =IF(OR(原始資料!$A5="",55>設定!$B$3,原始資料!BF5=""),"",IF(AND(原始資料!BE5<>"",原始資料!BF5=原始資料!BE5),N(BC5)+1,1)) | BE5: =IF(OR(原始資料!$A5="",56>設定!$B$3,原始資料!BG5=""),"",IF(AND(原始資料!BF5<>"",原始資料!BG5=原始資料!BF5),N(BD5)+1,1)) | BF5: =IF(OR(原始資料!$A5="",57>設定!$B$3,原始資料!BH5=""),"",IF(AND(原始資料!BG5<>"",原始資料!BH5=原始資料!BG5),N(BE5)+1,1)) | BG5: =IF(OR(原始資料!$A5="",58>設定!$B$3,原始資料!BI5=""),"",IF(AND(原始資料!BH5<>"",原始資料!BI5=原始資料!BH5),N(BF5)+1,1)) | BH5: =IF(OR(原始資料!$A5="",59>設定!$B$3,原始資料!BJ5=""),"",IF(AND(原始資料!BI5<>"",原始資料!BJ5=原始資料!BI5),N(BG5)+1,1)) | BI5: =IF(OR(原始資料!$A5="",60>設定!$B$3,原始資料!BK5=""),"",IF(AND(原始資料!BJ5<>"",原始資料!BK5=原始資料!BJ5),N(BH5)+1,1))
A6: =IF(原始資料!$A6="","",原始資料!$A6) | B6: =IF(OR(原始資料!$A6="",1>設定!$B$3,原始資料!D6=""),"",1) | C6: =IF(OR(原始資料!$A6="",2>設定!$B$3,原始資料!E6=""),"",IF(AND(原始資料!D6<>"",原始資料!E6=原始資料!D6),N(B6)+1,1)) | D6: =IF(OR(原始資料!$A6="",3>設定!$B$3,原始資料!F6=""),"",IF(AND(原始資料!E6<>"",原始資料!F6=原始資料!E6),N(C6)+1,1)) | E6: =IF(OR(原始資料!$A6="",4>設定!$B$3,原始資料!G6=""),"",IF(AND(原始資料!F6<>"",原始資料!G6=原始資料!F6),N(D6)+1,1)) | F6: =IF(OR(原始資料!$A6="",5>設定!$B$3,原始資料!H6=""),"",IF(AND(原始資料!G6<>"",原始資料!H6=原始資料!G6),N(E6)+1,1)) | G6: =IF(OR(原始資料!$A6="",6>設定!$B$3,原始資料!I6=""),"",IF(AND(原始資料!H6<>"",原始資料!I6=原始資料!H6),N(F6)+1,1)) | H6: =IF(OR(原始資料!$A6="",7>設定!$B$3,原始資料!J6=""),"",IF(AND(原始資料!I6<>"",原始資料!J6=原始資料!I6),N(G6)+1,1)) | I6: =IF(OR(原始資料!$A6="",8>設定!$B$3,原始資料!K6=""),"",IF(AND(原始資料!J6<>"",原始資料!K6=原始資料!J6),N(H6)+1,1)) | J6: =IF(OR(原始資料!$A6="",9>設定!$B$3,原始資料!L6=""),"",IF(AND(原始資料!K6<>"",原始資料!L6=原始資料!K6),N(I6)+1,1)) | K6: =IF(OR(原始資料!$A6="",10>設定!$B$3,原始資料!M6=""),"",IF(AND(原始資料!L6<>"",原始資料!M6=原始資料!L6),N(J6)+1,1)) | L6: =IF(OR(原始資料!$A6="",11>設定!$B$3,原始資料!N6=""),"",IF(AND(原始資料!M6<>"",原始資料!N6=原始資料!M6),N(K6)+1,1)) | M6: =IF(OR(原始資料!$A6="",12>設定!$B$3,原始資料!O6=""),"",IF(AND(原始資料!N6<>"",原始資料!O6=原始資料!N6),N(L6)+1,1)) | N6: =IF(OR(原始資料!$A6="",13>設定!$B$3,原始資料!P6=""),"",IF(AND(原始資料!O6<>"",原始資料!P6=原始資料!O6),N(M6)+1,1)) | O6: =IF(OR(原始資料!$A6="",14>設定!$B$3,原始資料!Q6=""),"",IF(AND(原始資料!P6<>"",原始資料!Q6=原始資料!P6),N(N6)+1,1)) | P6: =IF(OR(原始資料!$A6="",15>設定!$B$3,原始資料!R6=""),"",IF(AND(原始資料!Q6<>"",原始資料!R6=原始資料!Q6),N(O6)+1,1)) | Q6: =IF(OR(原始資料!$A6="",16>設定!$B$3,原始資料!S6=""),"",IF(AND(原始資料!R6<>"",原始資料!S6=原始資料!R6),N(P6)+1,1)) | R6: =IF(OR(原始資料!$A6="",17>設定!$B$3,原始資料!T6=""),"",IF(AND(原始資料!S6<>"",原始資料!T6=原始資料!S6),N(Q6)+1,1)) | S6: =IF(OR(原始資料!$A6="",18>設定!$B$3,原始資料!U6=""),"",IF(AND(原始資料!T6<>"",原始資料!U6=原始資料!T6),N(R6)+1,1)) | T6: =IF(OR(原始資料!$A6="",19>設定!$B$3,原始資料!V6=""),"",IF(AND(原始資料!U6<>"",原始資料!V6=原始資料!U6),N(S6)+1,1)) | U6: =IF(OR(原始資料!$A6="",20>設定!$B$3,原始資料!W6=""),"",IF(AND(原始資料!V6<>"",原始資料!W6=原始資料!V6),N(T6)+1,1)) | V6: =IF(OR(原始資料!$A6="",21>設定!$B$3,原始資料!X6=""),"",IF(AND(原始資料!W6<>"",原始資料!X6=原始資料!W6),N(U6)+1,1)) | W6: =IF(OR(原始資料!$A6="",22>設定!$B$3,原始資料!Y6=""),"",IF(AND(原始資料!X6<>"",原始資料!Y6=原始資料!X6),N(V6)+1,1)) | X6: =IF(OR(原始資料!$A6="",23>設定!$B$3,原始資料!Z6=""),"",IF(AND(原始資料!Y6<>"",原始資料!Z6=原始資料!Y6),N(W6)+1,1)) | Y6: =IF(OR(原始資料!$A6="",24>設定!$B$3,原始資料!AA6=""),"",IF(AND(原始資料!Z6<>"",原始資料!AA6=原始資料!Z6),N(X6)+1,1)) | Z6: =IF(OR(原始資料!$A6="",25>設定!$B$3,原始資料!AB6=""),"",IF(AND(原始資料!AA6<>"",原始資料!AB6=原始資料!AA6),N(Y6)+1,1)) | AA6: =IF(OR(原始資料!$A6="",26>設定!$B$3,原始資料!AC6=""),"",IF(AND(原始資料!AB6<>"",原始資料!AC6=原始資料!AB6),N(Z6)+1,1)) | AB6: =IF(OR(原始資料!$A6="",27>設定!$B$3,原始資料!AD6=""),"",IF(AND(原始資料!AC6<>"",原始資料!AD6=原始資料!AC6),N(AA6)+1,1)) | AC6: =IF(OR(原始資料!$A6="",28>設定!$B$3,原始資料!AE6=""),"",IF(AND(原始資料!AD6<>"",原始資料!AE6=原始資料!AD6),N(AB6)+1,1)) | AD6: =IF(OR(原始資料!$A6="",29>設定!$B$3,原始資料!AF6=""),"",IF(AND(原始資料!AE6<>"",原始資料!AF6=原始資料!AE6),N(AC6)+1,1)) | AE6: =IF(OR(原始資料!$A6="",30>設定!$B$3,原始資料!AG6=""),"",IF(AND(原始資料!AF6<>"",原始資料!AG6=原始資料!AF6),N(AD6)+1,1)) | AF6: =IF(OR(原始資料!$A6="",31>設定!$B$3,原始資料!AH6=""),"",IF(AND(原始資料!AG6<>"",原始資料!AH6=原始資料!AG6),N(AE6)+1,1)) | AG6: =IF(OR(原始資料!$A6="",32>設定!$B$3,原始資料!AI6=""),"",IF(AND(原始資料!AH6<>"",原始資料!AI6=原始資料!AH6),N(AF6)+1,1)) | AH6: =IF(OR(原始資料!$A6="",33>設定!$B$3,原始資料!AJ6=""),"",IF(AND(原始資料!AI6<>"",原始資料!AJ6=原始資料!AI6),N(AG6)+1,1)) | AI6: =IF(OR(原始資料!$A6="",34>設定!$B$3,原始資料!AK6=""),"",IF(AND(原始資料!AJ6<>"",原始資料!AK6=原始資料!AJ6),N(AH6)+1,1)) | AJ6: =IF(OR(原始資料!$A6="",35>設定!$B$3,原始資料!AL6=""),"",IF(AND(原始資料!AK6<>"",原始資料!AL6=原始資料!AK6),N(AI6)+1,1)) | AK6: =IF(OR(原始資料!$A6="",36>設定!$B$3,原始資料!AM6=""),"",IF(AND(原始資料!AL6<>"",原始資料!AM6=原始資料!AL6),N(AJ6)+1,1)) | AL6: =IF(OR(原始資料!$A6="",37>設定!$B$3,原始資料!AN6=""),"",IF(AND(原始資料!AM6<>"",原始資料!AN6=原始資料!AM6),N(AK6)+1,1)) | AM6: =IF(OR(原始資料!$A6="",38>設定!$B$3,原始資料!AO6=""),"",IF(AND(原始資料!AN6<>"",原始資料!AO6=原始資料!AN6),N(AL6)+1,1)) | AN6: =IF(OR(原始資料!$A6="",39>設定!$B$3,原始資料!AP6=""),"",IF(AND(原始資料!AO6<>"",原始資料!AP6=原始資料!AO6),N(AM6)+1,1)) | AO6: =IF(OR(原始資料!$A6="",40>設定!$B$3,原始資料!AQ6=""),"",IF(AND(原始資料!AP6<>"",原始資料!AQ6=原始資料!AP6),N(AN6)+1,1)) | AP6: =IF(OR(原始資料!$A6="",41>設定!$B$3,原始資料!AR6=""),"",IF(AND(原始資料!AQ6<>"",原始資料!AR6=原始資料!AQ6),N(AO6)+1,1)) | AQ6: =IF(OR(原始資料!$A6="",42>設定!$B$3,原始資料!AS6=""),"",IF(AND(原始資料!AR6<>"",原始資料!AS6=原始資料!AR6),N(AP6)+1,1)) | AR6: =IF(OR(原始資料!$A6="",43>設定!$B$3,原始資料!AT6=""),"",IF(AND(原始資料!AS6<>"",原始資料!AT6=原始資料!AS6),N(AQ6)+1,1)) | AS6: =IF(OR(原始資料!$A6="",44>設定!$B$3,原始資料!AU6=""),"",IF(AND(原始資料!AT6<>"",原始資料!AU6=原始資料!AT6),N(AR6)+1,1)) | AT6: =IF(OR(原始資料!$A6="",45>設定!$B$3,原始資料!AV6=""),"",IF(AND(原始資料!AU6<>"",原始資料!AV6=原始資料!AU6),N(AS6)+1,1)) | AU6: =IF(OR(原始資料!$A6="",46>設定!$B$3,原始資料!AW6=""),"",IF(AND(原始資料!AV6<>"",原始資料!AW6=原始資料!AV6),N(AT6)+1,1)) | AV6: =IF(OR(原始資料!$A6="",47>設定!$B$3,原始資料!AX6=""),"",IF(AND(原始資料!AW6<>"",原始資料!AX6=原始資料!AW6),N(AU6)+1,1)) | AW6: =IF(OR(原始資料!$A6="",48>設定!$B$3,原始資料!AY6=""),"",IF(AND(原始資料!AX6<>"",原始資料!AY6=原始資料!AX6),N(AV6)+1,1)) | AX6: =IF(OR(原始資料!$A6="",49>設定!$B$3,原始資料!AZ6=""),"",IF(AND(原始資料!AY6<>"",原始資料!AZ6=原始資料!AY6),N(AW6)+1,1)) | AY6: =IF(OR(原始資料!$A6="",50>設定!$B$3,原始資料!BA6=""),"",IF(AND(原始資料!AZ6<>"",原始資料!BA6=原始資料!AZ6),N(AX6)+1,1)) | AZ6: =IF(OR(原始資料!$A6="",51>設定!$B$3,原始資料!BB6=""),"",IF(AND(原始資料!BA6<>"",原始資料!BB6=原始資料!BA6),N(AY6)+1,1)) | BA6: =IF(OR(原始資料!$A6="",52>設定!$B$3,原始資料!BC6=""),"",IF(AND(原始資料!BB6<>"",原始資料!BC6=原始資料!BB6),N(AZ6)+1,1)) | BB6: =IF(OR(原始資料!$A6="",53>設定!$B$3,原始資料!BD6=""),"",IF(AND(原始資料!BC6<>"",原始資料!BD6=原始資料!BC6),N(BA6)+1,1)) | BC6: =IF(OR(原始資料!$A6="",54>設定!$B$3,原始資料!BE6=""),"",IF(AND(原始資料!BD6<>"",原始資料!BE6=原始資料!BD6),N(BB6)+1,1)) | BD6: =IF(OR(原始資料!$A6="",55>設定!$B$3,原始資料!BF6=""),"",IF(AND(原始資料!BE6<>"",原始資料!BF6=原始資料!BE6),N(BC6)+1,1)) | BE6: =IF(OR(原始資料!$A6="",56>設定!$B$3,原始資料!BG6=""),"",IF(AND(原始資料!BF6<>"",原始資料!BG6=原始資料!BF6),N(BD6)+1,1)) | BF6: =IF(OR(原始資料!$A6="",57>設定!$B$3,原始資料!BH6=""),"",IF(AND(原始資料!BG6<>"",原始資料!BH6=原始資料!BG6),N(BE6)+1,1)) | BG6: =IF(OR(原始資料!$A6="",58>設定!$B$3,原始資料!BI6=""),"",IF(AND(原始資料!BH6<>"",原始資料!BI6=原始資料!BH6),N(BF6)+1,1)) | BH6: =IF(OR(原始資料!$A6="",59>設定!$B$3,原始資料!BJ6=""),"",IF(AND(原始資料!BI6<>"",原始資料!BJ6=原始資料!BI6),N(BG6)+1,1)) | BI6: =IF(OR(原始資料!$A6="",60>設定!$B$3,原始資料!BK6=""),"",IF(AND(原始資料!BJ6<>"",原始資料!BK6=原始資料!BJ6),N(BH6)+1,1))
A7: =IF(原始資料!$A7="","",原始資料!$A7) | B7: =IF(OR(原始資料!$A7="",1>設定!$B$3,原始資料!D7=""),"",1) | C7: =IF(OR(原始資料!$A7="",2>設定!$B$3,原始資料!E7=""),"",IF(AND(原始資料!D7<>"",原始資料!E7=原始資料!D7),N(B7)+1,1)) | D7: =IF(OR(原始資料!$A7="",3>設定!$B$3,原始資料!F7=""),"",IF(AND(原始資料!E7<>"",原始資料!F7=原始資料!E7),N(C7)+1,1)) | E7: =IF(OR(原始資料!$A7="",4>設定!$B$3,原始資料!G7=""),"",IF(AND(原始資料!F7<>"",原始資料!G7=原始資料!F7),N(D7)+1,1)) | F7: =IF(OR(原始資料!$A7="",5>設定!$B$3,原始資料!H7=""),"",IF(AND(原始資料!G7<>"",原始資料!H7=原始資料!G7),N(E7)+1,1)) | G7: =IF(OR(原始資料!$A7="",6>設定!$B$3,原始資料!I7=""),"",IF(AND(原始資料!H7<>"",原始資料!I7=原始資料!H7),N(F7)+1,1)) | H7: =IF(OR(原始資料!$A7="",7>設定!$B$3,原始資料!J7=""),"",IF(AND(原始資料!I7<>"",原始資料!J7=原始資料!I7),N(G7)+1,1)) | I7: =IF(OR(原始資料!$A7="",8>設定!$B$3,原始資料!K7=""),"",IF(AND(原始資料!J7<>"",原始資料!K7=原始資料!J7),N(H7)+1,1)) | J7: =IF(OR(原始資料!$A7="",9>設定!$B$3,原始資料!L7=""),"",IF(AND(原始資料!K7<>"",原始資料!L7=原始資料!K7),N(I7)+1,1)) | K7: =IF(OR(原始資料!$A7="",10>設定!$B$3,原始資料!M7=""),"",IF(AND(原始資料!L7<>"",原始資料!M7=原始資料!L7),N(J7)+1,1)) | L7: =IF(OR(原始資料!$A7="",11>設定!$B$3,原始資料!N7=""),"",IF(AND(原始資料!M7<>"",原始資料!N7=原始資料!M7),N(K7)+1,1)) | M7: =IF(OR(原始資料!$A7="",12>設定!$B$3,原始資料!O7=""),"",IF(AND(原始資料!N7<>"",原始資料!O7=原始資料!N7),N(L7)+1,1)) | N7: =IF(OR(原始資料!$A7="",13>設定!$B$3,原始資料!P7=""),"",IF(AND(原始資料!O7<>"",原始資料!P7=原始資料!O7),N(M7)+1,1)) | O7: =IF(OR(原始資料!$A7="",14>設定!$B$3,原始資料!Q7=""),"",IF(AND(原始資料!P7<>"",原始資料!Q7=原始資料!P7),N(N7)+1,1)) | P7: =IF(OR(原始資料!$A7="",15>設定!$B$3,原始資料!R7=""),"",IF(AND(原始資料!Q7<>"",原始資料!R7=原始資料!Q7),N(O7)+1,1)) | Q7: =IF(OR(原始資料!$A7="",16>設定!$B$3,原始資料!S7=""),"",IF(AND(原始資料!R7<>"",原始資料!S7=原始資料!R7),N(P7)+1,1)) | R7: =IF(OR(原始資料!$A7="",17>設定!$B$3,原始資料!T7=""),"",IF(AND(原始資料!S7<>"",原始資料!T7=原始資料!S7),N(Q7)+1,1)) | S7: =IF(OR(原始資料!$A7="",18>設定!$B$3,原始資料!U7=""),"",IF(AND(原始資料!T7<>"",原始資料!U7=原始資料!T7),N(R7)+1,1)) | T7: =IF(OR(原始資料!$A7="",19>設定!$B$3,原始資料!V7=""),"",IF(AND(原始資料!U7<>"",原始資料!V7=原始資料!U7),N(S7)+1,1)) | U7: =IF(OR(原始資料!$A7="",20>設定!$B$3,原始資料!W7=""),"",IF(AND(原始資料!V7<>"",原始資料!W7=原始資料!V7),N(T7)+1,1)) | V7: =IF(OR(原始資料!$A7="",21>設定!$B$3,原始資料!X7=""),"",IF(AND(原始資料!W7<>"",原始資料!X7=原始資料!W7),N(U7)+1,1)) | W7: =IF(OR(原始資料!$A7="",22>設定!$B$3,原始資料!Y7=""),"",IF(AND(原始資料!X7<>"",原始資料!Y7=原始資料!X7),N(V7)+1,1)) | X7: =IF(OR(原始資料!$A7="",23>設定!$B$3,原始資料!Z7=""),"",IF(AND(原始資料!Y7<>"",原始資料!Z7=原始資料!Y7),N(W7)+1,1)) | Y7: =IF(OR(原始資料!$A7="",24>設定!$B$3,原始資料!AA7=""),"",IF(AND(原始資料!Z7<>"",原始資料!AA7=原始資料!Z7),N(X7)+1,1)) | Z7: =IF(OR(原始資料!$A7="",25>設定!$B$3,原始資料!AB7=""),"",IF(AND(原始資料!AA7<>"",原始資料!AB7=原始資料!AA7),N(Y7)+1,1)) | AA7: =IF(OR(原始資料!$A7="",26>設定!$B$3,原始資料!AC7=""),"",IF(AND(原始資料!AB7<>"",原始資料!AC7=原始資料!AB7),N(Z7)+1,1)) | AB7: =IF(OR(原始資料!$A7="",27>設定!$B$3,原始資料!AD7=""),"",IF(AND(原始資料!AC7<>"",原始資料!AD7=原始資料!AC7),N(AA7)+1,1)) | AC7: =IF(OR(原始資料!$A7="",28>設定!$B$3,原始資料!AE7=""),"",IF(AND(原始資料!AD7<>"",原始資料!AE7=原始資料!AD7),N(AB7)+1,1)) | AD7: =IF(OR(原始資料!$A7="",29>設定!$B$3,原始資料!AF7=""),"",IF(AND(原始資料!AE7<>"",原始資料!AF7=原始資料!AE7),N(AC7)+1,1)) | AE7: =IF(OR(原始資料!$A7="",30>設定!$B$3,原始資料!AG7=""),"",IF(AND(原始資料!AF7<>"",原始資料!AG7=原始資料!AF7),N(AD7)+1,1)) | AF7: =IF(OR(原始資料!$A7="",31>設定!$B$3,原始資料!AH7=""),"",IF(AND(原始資料!AG7<>"",原始資料!AH7=原始資料!AG7),N(AE7)+1,1)) | AG7: =IF(OR(原始資料!$A7="",32>設定!$B$3,原始資料!AI7=""),"",IF(AND(原始資料!AH7<>"",原始資料!AI7=原始資料!AH7),N(AF7)+1,1)) | AH7: =IF(OR(原始資料!$A7="",33>設定!$B$3,原始資料!AJ7=""),"",IF(AND(原始資料!AI7<>"",原始資料!AJ7=原始資料!AI7),N(AG7)+1,1)) | AI7: =IF(OR(原始資料!$A7="",34>設定!$B$3,原始資料!AK7=""),"",IF(AND(原始資料!AJ7<>"",原始資料!AK7=原始資料!AJ7),N(AH7)+1,1)) | AJ7: =IF(OR(原始資料!$A7="",35>設定!$B$3,原始資料!AL7=""),"",IF(AND(原始資料!AK7<>"",原始資料!AL7=原始資料!AK7),N(AI7)+1,1)) | AK7: =IF(OR(原始資料!$A7="",36>設定!$B$3,原始資料!AM7=""),"",IF(AND(原始資料!AL7<>"",原始資料!AM7=原始資料!AL7),N(AJ7)+1,1)) | AL7: =IF(OR(原始資料!$A7="",37>設定!$B$3,原始資料!AN7=""),"",IF(AND(原始資料!AM7<>"",原始資料!AN7=原始資料!AM7),N(AK7)+1,1)) | AM7: =IF(OR(原始資料!$A7="",38>設定!$B$3,原始資料!AO7=""),"",IF(AND(原始資料!AN7<>"",原始資料!AO7=原始資料!AN7),N(AL7)+1,1)) | AN7: =IF(OR(原始資料!$A7="",39>設定!$B$3,原始資料!AP7=""),"",IF(AND(原始資料!AO7<>"",原始資料!AP7=原始資料!AO7),N(AM7)+1,1)) | AO7: =IF(OR(原始資料!$A7="",40>設定!$B$3,原始資料!AQ7=""),"",IF(AND(原始資料!AP7<>"",原始資料!AQ7=原始資料!AP7),N(AN7)+1,1)) | AP7: =IF(OR(原始資料!$A7="",41>設定!$B$3,原始資料!AR7=""),"",IF(AND(原始資料!AQ7<>"",原始資料!AR7=原始資料!AQ7),N(AO7)+1,1)) | AQ7: =IF(OR(原始資料!$A7="",42>設定!$B$3,原始資料!AS7=""),"",IF(AND(原始資料!AR7<>"",原始資料!AS7=原始資料!AR7),N(AP7)+1,1)) | AR7: =IF(OR(原始資料!$A7="",43>設定!$B$3,原始資料!AT7=""),"",IF(AND(原始資料!AS7<>"",原始資料!AT7=原始資料!AS7),N(AQ7)+1,1)) | AS7: =IF(OR(原始資料!$A7="",44>設定!$B$3,原始資料!AU7=""),"",IF(AND(原始資料!AT7<>"",原始資料!AU7=原始資料!AT7),N(AR7)+1,1)) | AT7: =IF(OR(原始資料!$A7="",45>設定!$B$3,原始資料!AV7=""),"",IF(AND(原始資料!AU7<>"",原始資料!AV7=原始資料!AU7),N(AS7)+1,1)) | AU7: =IF(OR(原始資料!$A7="",46>設定!$B$3,原始資料!AW7=""),"",IF(AND(原始資料!AV7<>"",原始資料!AW7=原始資料!AV7),N(AT7)+1,1)) | AV7: =IF(OR(原始資料!$A7="",47>設定!$B$3,原始資料!AX7=""),"",IF(AND(原始資料!AW7<>"",原始資料!AX7=原始資料!AW7),N(AU7)+1,1)) | AW7: =IF(OR(原始資料!$A7="",48>設定!$B$3,原始資料!AY7=""),"",IF(AND(原始資料!AX7<>"",原始資料!AY7=原始資料!AX7),N(AV7)+1,1)) | AX7: =IF(OR(原始資料!$A7="",49>設定!$B$3,原始資料!AZ7=""),"",IF(AND(原始資料!AY7<>"",原始資料!AZ7=原始資料!AY7),N(AW7)+1,1)) | AY7: =IF(OR(原始資料!$A7="",50>設定!$B$3,原始資料!BA7=""),"",IF(AND(原始資料!AZ7<>"",原始資料!BA7=原始資料!AZ7),N(AX7)+1,1)) | AZ7: =IF(OR(原始資料!$A7="",51>設定!$B$3,原始資料!BB7=""),"",IF(AND(原始資料!BA7<>"",原始資料!BB7=原始資料!BA7),N(AY7)+1,1)) | BA7: =IF(OR(原始資料!$A7="",52>設定!$B$3,原始資料!BC7=""),"",IF(AND(原始資料!BB7<>"",原始資料!BC7=原始資料!BB7),N(AZ7)+1,1)) | BB7: =IF(OR(原始資料!$A7="",53>設定!$B$3,原始資料!BD7=""),"",IF(AND(原始資料!BC7<>"",原始資料!BD7=原始資料!BC7),N(BA7)+1,1)) | BC7: =IF(OR(原始資料!$A7="",54>設定!$B$3,原始資料!BE7=""),"",IF(AND(原始資料!BD7<>"",原始資料!BE7=原始資料!BD7),N(BB7)+1,1)) | BD7: =IF(OR(原始資料!$A7="",55>設定!$B$3,原始資料!BF7=""),"",IF(AND(原始資料!BE7<>"",原始資料!BF7=原始資料!BE7),N(BC7)+1,1)) | BE7: =IF(OR(原始資料!$A7="",56>設定!$B$3,原始資料!BG7=""),"",IF(AND(原始資料!BF7<>"",原始資料!BG7=原始資料!BF7),N(BD7)+1,1)) | BF7: =IF(OR(原始資料!$A7="",57>設定!$B$3,原始資料!BH7=""),"",IF(AND(原始資料!BG7<>"",原始資料!BH7=原始資料!BG7),N(BE7)+1,1)) | BG7: =IF(OR(原始資料!$A7="",58>設定!$B$3,原始資料!BI7=""),"",IF(AND(原始資料!BH7<>"",原始資料!BI7=原始資料!BH7),N(BF7)+1,1)) | BH7: =IF(OR(原始資料!$A7="",59>設定!$B$3,原始資料!BJ7=""),"",IF(AND(原始資料!BI7<>"",原始資料!BJ7=原始資料!BI7),N(BG7)+1,1)) | BI7: =IF(OR(原始資料!$A7="",60>設定!$B$3,原始資料!BK7=""),"",IF(AND(原始資料!BJ7<>"",原始資料!BK7=原始資料!BJ7),N(BH7)+1,1))
A8: =IF(原始資料!$A8="","",原始資料!$A8) | B8: =IF(OR(原始資料!$A8="",1>設定!$B$3,原始資料!D8=""),"",1) | C8: =IF(OR(原始資料!$A8="",2>設定!$B$3,原始資料!E8=""),"",IF(AND(原始資料!D8<>"",原始資料!E8=原始資料!D8),N(B8)+1,1)) | D8: =IF(OR(原始資料!$A8="",3>設定!$B$3,原始資料!F8=""),"",IF(AND(原始資料!E8<>"",原始資料!F8=原始資料!E8),N(C8)+1,1)) | E8: =IF(OR(原始資料!$A8="",4>設定!$B$3,原始資料!G8=""),"",IF(AND(原始資料!F8<>"",原始資料!G8=原始資料!F8),N(D8)+1,1)) | F8: =IF(OR(原始資料!$A8="",5>設定!$B$3,原始資料!H8=""),"",IF(AND(原始資料!G8<>"",原始資料!H8=原始資料!G8),N(E8)+1,1)) | G8: =IF(OR(原始資料!$A8="",6>設定!$B$3,原始資料!I8=""),"",IF(AND(原始資料!H8<>"",原始資料!I8=原始資料!H8),N(F8)+1,1)) | H8: =IF(OR(原始資料!$A8="",7>設定!$B$3,原始資料!J8=""),"",IF(AND(原始資料!I8<>"",原始資料!J8=原始資料!I8),N(G8)+1,1)) | I8: =IF(OR(原始資料!$A8="",8>設定!$B$3,原始資料!K8=""),"",IF(AND(原始資料!J8<>"",原始資料!K8=原始資料!J8),N(H8)+1,1)) | J8: =IF(OR(原始資料!$A8="",9>設定!$B$3,原始資料!L8=""),"",IF(AND(原始資料!K8<>"",原始資料!L8=原始資料!K8),N(I8)+1,1)) | K8: =IF(OR(原始資料!$A8="",10>設定!$B$3,原始資料!M8=""),"",IF(AND(原始資料!L8<>"",原始資料!M8=原始資料!L8),N(J8)+1,1)) | L8: =IF(OR(原始資料!$A8="",11>設定!$B$3,原始資料!N8=""),"",IF(AND(原始資料!M8<>"",原始資料!N8=原始資料!M8),N(K8)+1,1)) | M8: =IF(OR(原始資料!$A8="",12>設定!$B$3,原始資料!O8=""),"",IF(AND(原始資料!N8<>"",原始資料!O8=原始資料!N8),N(L8)+1,1)) | N8: =IF(OR(原始資料!$A8="",13>設定!$B$3,原始資料!P8=""),"",IF(AND(原始資料!O8<>"",原始資料!P8=原始資料!O8),N(M8)+1,1)) | O8: =IF(OR(原始資料!$A8="",14>設定!$B$3,原始資料!Q8=""),"",IF(AND(原始資料!P8<>"",原始資料!Q8=原始資料!P8),N(N8)+1,1)) | P8: =IF(OR(原始資料!$A8="",15>設定!$B$3,原始資料!R8=""),"",IF(AND(原始資料!Q8<>"",原始資料!R8=原始資料!Q8),N(O8)+1,1)) | Q8: =IF(OR(原始資料!$A8="",16>設定!$B$3,原始資料!S8=""),"",IF(AND(原始資料!R8<>"",原始資料!S8=原始資料!R8),N(P8)+1,1)) | R8: =IF(OR(原始資料!$A8="",17>設定!$B$3,原始資料!T8=""),"",IF(AND(原始資料!S8<>"",原始資料!T8=原始資料!S8),N(Q8)+1,1)) | S8: =IF(OR(原始資料!$A8="",18>設定!$B$3,原始資料!U8=""),"",IF(AND(原始資料!T8<>"",原始資料!U8=原始資料!T8),N(R8)+1,1)) | T8: =IF(OR(原始資料!$A8="",19>設定!$B$3,原始資料!V8=""),"",IF(AND(原始資料!U8<>"",原始資料!V8=原始資料!U8),N(S8)+1,1)) | U8: =IF(OR(原始資料!$A8="",20>設定!$B$3,原始資料!W8=""),"",IF(AND(原始資料!V8<>"",原始資料!W8=原始資料!V8),N(T8)+1,1)) | V8: =IF(OR(原始資料!$A8="",21>設定!$B$3,原始資料!X8=""),"",IF(AND(原始資料!W8<>"",原始資料!X8=原始資料!W8),N(U8)+1,1)) | W8: =IF(OR(原始資料!$A8="",22>設定!$B$3,原始資料!Y8=""),"",IF(AND(原始資料!X8<>"",原始資料!Y8=原始資料!X8),N(V8)+1,1)) | X8: =IF(OR(原始資料!$A8="",23>設定!$B$3,原始資料!Z8=""),"",IF(AND(原始資料!Y8<>"",原始資料!Z8=原始資料!Y8),N(W8)+1,1)) | Y8: =IF(OR(原始資料!$A8="",24>設定!$B$3,原始資料!AA8=""),"",IF(AND(原始資料!Z8<>"",原始資料!AA8=原始資料!Z8),N(X8)+1,1)) | Z8: =IF(OR(原始資料!$A8="",25>設定!$B$3,原始資料!AB8=""),"",IF(AND(原始資料!AA8<>"",原始資料!AB8=原始資料!AA8),N(Y8)+1,1)) | AA8: =IF(OR(原始資料!$A8="",26>設定!$B$3,原始資料!AC8=""),"",IF(AND(原始資料!AB8<>"",原始資料!AC8=原始資料!AB8),N(Z8)+1,1)) | AB8: =IF(OR(原始資料!$A8="",27>設定!$B$3,原始資料!AD8=""),"",IF(AND(原始資料!AC8<>"",原始資料!AD8=原始資料!AC8),N(AA8)+1,1)) | AC8: =IF(OR(原始資料!$A8="",28>設定!$B$3,原始資料!AE8=""),"",IF(AND(原始資料!AD8<>"",原始資料!AE8=原始資料!AD8),N(AB8)+1,1)) | AD8: =IF(OR(原始資料!$A8="",29>設定!$B$3,原始資料!AF8=""),"",IF(AND(原始資料!AE8<>"",原始資料!AF8=原始資料!AE8),N(AC8)+1,1)) | AE8: =IF(OR(原始資料!$A8="",30>設定!$B$3,原始資料!AG8=""),"",IF(AND(原始資料!AF8<>"",原始資料!AG8=原始資料!AF8),N(AD8)+1,1)) | AF8: =IF(OR(原始資料!$A8="",31>設定!$B$3,原始資料!AH8=""),"",IF(AND(原始資料!AG8<>"",原始資料!AH8=原始資料!AG8),N(AE8)+1,1)) | AG8: =IF(OR(原始資料!$A8="",32>設定!$B$3,原始資料!AI8=""),"",IF(AND(原始資料!AH8<>"",原始資料!AI8=原始資料!AH8),N(AF8)+1,1)) | AH8: =IF(OR(原始資料!$A8="",33>設定!$B$3,原始資料!AJ8=""),"",IF(AND(原始資料!AI8<>"",原始資料!AJ8=原始資料!AI8),N(AG8)+1,1)) | AI8: =IF(OR(原始資料!$A8="",34>設定!$B$3,原始資料!AK8=""),"",IF(AND(原始資料!AJ8<>"",原始資料!AK8=原始資料!AJ8),N(AH8)+1,1)) | AJ8: =IF(OR(原始資料!$A8="",35>設定!$B$3,原始資料!AL8=""),"",IF(AND(原始資料!AK8<>"",原始資料!AL8=原始資料!AK8),N(AI8)+1,1)) | AK8: =IF(OR(原始資料!$A8="",36>設定!$B$3,原始資料!AM8=""),"",IF(AND(原始資料!AL8<>"",原始資料!AM8=原始資料!AL8),N(AJ8)+1,1)) | AL8: =IF(OR(原始資料!$A8="",37>設定!$B$3,原始資料!AN8=""),"",IF(AND(原始資料!AM8<>"",原始資料!AN8=原始資料!AM8),N(AK8)+1,1)) | AM8: =IF(OR(原始資料!$A8="",38>設定!$B$3,原始資料!AO8=""),"",IF(AND(原始資料!AN8<>"",原始資料!AO8=原始資料!AN8),N(AL8)+1,1)) | AN8: =IF(OR(原始資料!$A8="",39>設定!$B$3,原始資料!AP8=""),"",IF(AND(原始資料!AO8<>"",原始資料!AP8=原始資料!AO8),N(AM8)+1,1)) | AO8: =IF(OR(原始資料!$A8="",40>設定!$B$3,原始資料!AQ8=""),"",IF(AND(原始資料!AP8<>"",原始資料!AQ8=原始資料!AP8),N(AN8)+1,1)) | AP8: =IF(OR(原始資料!$A8="",41>設定!$B$3,原始資料!AR8=""),"",IF(AND(原始資料!AQ8<>"",原始資料!AR8=原始資料!AQ8),N(AO8)+1,1)) | AQ8: =IF(OR(原始資料!$A8="",42>設定!$B$3,原始資料!AS8=""),"",IF(AND(原始資料!AR8<>"",原始資料!AS8=原始資料!AR8),N(AP8)+1,1)) | AR8: =IF(OR(原始資料!$A8="",43>設定!$B$3,原始資料!AT8=""),"",IF(AND(原始資料!AS8<>"",原始資料!AT8=原始資料!AS8),N(AQ8)+1,1)) | AS8: =IF(OR(原始資料!$A8="",44>設定!$B$3,原始資料!AU8=""),"",IF(AND(原始資料!AT8<>"",原始資料!AU8=原始資料!AT8),N(AR8)+1,1)) | AT8: =IF(OR(原始資料!$A8="",45>設定!$B$3,原始資料!AV8=""),"",IF(AND(原始資料!AU8<>"",原始資料!AV8=原始資料!AU8),N(AS8)+1,1)) | AU8: =IF(OR(原始資料!$A8="",46>設定!$B$3,原始資料!AW8=""),"",IF(AND(原始資料!AV8<>"",原始資料!AW8=原始資料!AV8),N(AT8)+1,1)) | AV8: =IF(OR(原始資料!$A8="",47>設定!$B$3,原始資料!AX8=""),"",IF(AND(原始資料!AW8<>"",原始資料!AX8=原始資料!AW8),N(AU8)+1,1)) | AW8: =IF(OR(原始資料!$A8="",48>設定!$B$3,原始資料!AY8=""),"",IF(AND(原始資料!AX8<>"",原始資料!AY8=原始資料!AX8),N(AV8)+1,1)) | AX8: =IF(OR(原始資料!$A8="",49>設定!$B$3,原始資料!AZ8=""),"",IF(AND(原始資料!AY8<>"",原始資料!AZ8=原始資料!AY8),N(AW8)+1,1)) | AY8: =IF(OR(原始資料!$A8="",50>設定!$B$3,原始資料!BA8=""),"",IF(AND(原始資料!AZ8<>"",原始資料!BA8=原始資料!AZ8),N(AX8)+1,1)) | AZ8: =IF(OR(原始資料!$A8="",51>設定!$B$3,原始資料!BB8=""),"",IF(AND(原始資料!BA8<>"",原始資料!BB8=原始資料!BA8),N(AY8)+1,1)) | BA8: =IF(OR(原始資料!$A8="",52>設定!$B$3,原始資料!BC8=""),"",IF(AND(原始資料!BB8<>"",原始資料!BC8=原始資料!BB8),N(AZ8)+1,1)) | BB8: =IF(OR(原始資料!$A8="",53>設定!$B$3,原始資料!BD8=""),"",IF(AND(原始資料!BC8<>"",原始資料!BD8=原始資料!BC8),N(BA8)+1,1)) | BC8: =IF(OR(原始資料!$A8="",54>設定!$B$3,原始資料!BE8=""),"",IF(AND(原始資料!BD8<>"",原始資料!BE8=原始資料!BD8),N(BB8)+1,1)) | BD8: =IF(OR(原始資料!$A8="",55>設定!$B$3,原始資料!BF8=""),"",IF(AND(原始資料!BE8<>"",原始資料!BF8=原始資料!BE8),N(BC8)+1,1)) | BE8: =IF(OR(原始資料!$A8="",56>設定!$B$3,原始資料!BG8=""),"",IF(AND(原始資料!BF8<>"",原始資料!BG8=原始資料!BF8),N(BD8)+1,1)) | BF8: =IF(OR(原始資料!$A8="",57>設定!$B$3,原始資料!BH8=""),"",IF(AND(原始資料!BG8<>"",原始資料!BH8=原始資料!BG8),N(BE8)+1,1)) | BG8: =IF(OR(原始資料!$A8="",58>設定!$B$3,原始資料!BI8=""),"",IF(AND(原始資料!BH8<>"",原始資料!BI8=原始資料!BH8),N(BF8)+1,1)) | BH8: =IF(OR(原始資料!$A8="",59>設定!$B$3,原始資料!BJ8=""),"",IF(AND(原始資料!BI8<>"",原始資料!BJ8=原始資料!BI8),N(BG8)+1,1)) | BI8: =IF(OR(原始資料!$A8="",60>設定!$B$3,原始資料!BK8=""),"",IF(AND(原始資料!BJ8<>"",原始資料!BK8=原始資料!BJ8),N(BH8)+1,1))
A9: =IF(原始資料!$A9="","",原始資料!$A9) | B9: =IF(OR(原始資料!$A9="",1>設定!$B$3,原始資料!D9=""),"",1) | C9: =IF(OR(原始資料!$A9="",2>設定!$B$3,原始資料!E9=""),"",IF(AND(原始資料!D9<>"",原始資料!E9=原始資料!D9),N(B9)+1,1)) | D9: =IF(OR(原始資料!$A9="",3>設定!$B$3,原始資料!F9=""),"",IF(AND(原始資料!E9<>"",原始資料!F9=原始資料!E9),N(C9)+1,1)) | E9: =IF(OR(原始資料!$A9="",4>設定!$B$3,原始資料!G9=""),"",IF(AND(原始資料!F9<>"",原始資料!G9=原始資料!F9),N(D9)+1,1)) | F9: =IF(OR(原始資料!$A9="",5>設定!$B$3,原始資料!H9=""),"",IF(AND(原始資料!G9<>"",原始資料!H9=原始資料!G9),N(E9)+1,1)) | G9: =IF(OR(原始資料!$A9="",6>設定!$B$3,原始資料!I9=""),"",IF(AND(原始資料!H9<>"",原始資料!I9=原始資料!H9),N(F9)+1,1)) | H9: =IF(OR(原始資料!$A9="",7>設定!$B$3,原始資料!J9=""),"",IF(AND(原始資料!I9<>"",原始資料!J9=原始資料!I9),N(G9)+1,1)) | I9: =IF(OR(原始資料!$A9="",8>設定!$B$3,原始資料!K9=""),"",IF(AND(原始資料!J9<>"",原始資料!K9=原始資料!J9),N(H9)+1,1)) | J9: =IF(OR(原始資料!$A9="",9>設定!$B$3,原始資料!L9=""),"",IF(AND(原始資料!K9<>"",原始資料!L9=原始資料!K9),N(I9)+1,1)) | K9: =IF(OR(原始資料!$A9="",10>設定!$B$3,原始資料!M9=""),"",IF(AND(原始資料!L9<>"",原始資料!M9=原始資料!L9),N(J9)+1,1)) | L9: =IF(OR(原始資料!$A9="",11>設定!$B$3,原始資料!N9=""),"",IF(AND(原始資料!M9<>"",原始資料!N9=原始資料!M9),N(K9)+1,1)) | M9: =IF(OR(原始資料!$A9="",12>設定!$B$3,原始資料!O9=""),"",IF(AND(原始資料!N9<>"",原始資料!O9=原始資料!N9),N(L9)+1,1)) | N9: =IF(OR(原始資料!$A9="",13>設定!$B$3,原始資料!P9=""),"",IF(AND(原始資料!O9<>"",原始資料!P9=原始資料!O9),N(M9)+1,1)) | O9: =IF(OR(原始資料!$A9="",14>設定!$B$3,原始資料!Q9=""),"",IF(AND(原始資料!P9<>"",原始資料!Q9=原始資料!P9),N(N9)+1,1)) | P9: =IF(OR(原始資料!$A9="",15>設定!$B$3,原始資料!R9=""),"",IF(AND(原始資料!Q9<>"",原始資料!R9=原始資料!Q9),N(O9)+1,1)) | Q9: =IF(OR(原始資料!$A9="",16>設定!$B$3,原始資料!S9=""),"",IF(AND(原始資料!R9<>"",原始資料!S9=原始資料!R9),N(P9)+1,1)) | R9: =IF(OR(原始資料!$A9="",17>設定!$B$3,原始資料!T9=""),"",IF(AND(原始資料!S9<>"",原始資料!T9=原始資料!S9),N(Q9)+1,1)) | S9: =IF(OR(原始資料!$A9="",18>設定!$B$3,原始資料!U9=""),"",IF(AND(原始資料!T9<>"",原始資料!U9=原始資料!T9),N(R9)+1,1)) | T9: =IF(OR(原始資料!$A9="",19>設定!$B$3,原始資料!V9=""),"",IF(AND(原始資料!U9<>"",原始資料!V9=原始資料!U9),N(S9)+1,1)) | U9: =IF(OR(原始資料!$A9="",20>設定!$B$3,原始資料!W9=""),"",IF(AND(原始資料!V9<>"",原始資料!W9=原始資料!V9),N(T9)+1,1)) | V9: =IF(OR(原始資料!$A9="",21>設定!$B$3,原始資料!X9=""),"",IF(AND(原始資料!W9<>"",原始資料!X9=原始資料!W9),N(U9)+1,1)) | W9: =IF(OR(原始資料!$A9="",22>設定!$B$3,原始資料!Y9=""),"",IF(AND(原始資料!X9<>"",原始資料!Y9=原始資料!X9),N(V9)+1,1)) | X9: =IF(OR(原始資料!$A9="",23>設定!$B$3,原始資料!Z9=""),"",IF(AND(原始資料!Y9<>"",原始資料!Z9=原始資料!Y9),N(W9)+1,1)) | Y9: =IF(OR(原始資料!$A9="",24>設定!$B$3,原始資料!AA9=""),"",IF(AND(原始資料!Z9<>"",原始資料!AA9=原始資料!Z9),N(X9)+1,1)) | Z9: =IF(OR(原始資料!$A9="",25>設定!$B$3,原始資料!AB9=""),"",IF(AND(原始資料!AA9<>"",原始資料!AB9=原始資料!AA9),N(Y9)+1,1)) | AA9: =IF(OR(原始資料!$A9="",26>設定!$B$3,原始資料!AC9=""),"",IF(AND(原始資料!AB9<>"",原始資料!AC9=原始資料!AB9),N(Z9)+1,1)) | AB9: =IF(OR(原始資料!$A9="",27>設定!$B$3,原始資料!AD9=""),"",IF(AND(原始資料!AC9<>"",原始資料!AD9=原始資料!AC9),N(AA9)+1,1)) | AC9: =IF(OR(原始資料!$A9="",28>設定!$B$3,原始資料!AE9=""),"",IF(AND(原始資料!AD9<>"",原始資料!AE9=原始資料!AD9),N(AB9)+1,1)) | AD9: =IF(OR(原始資料!$A9="",29>設定!$B$3,原始資料!AF9=""),"",IF(AND(原始資料!AE9<>"",原始資料!AF9=原始資料!AE9),N(AC9)+1,1)) | AE9: =IF(OR(原始資料!$A9="",30>設定!$B$3,原始資料!AG9=""),"",IF(AND(原始資料!AF9<>"",原始資料!AG9=原始資料!AF9),N(AD9)+1,1)) | AF9: =IF(OR(原始資料!$A9="",31>設定!$B$3,原始資料!AH9=""),"",IF(AND(原始資料!AG9<>"",原始資料!AH9=原始資料!AG9),N(AE9)+1,1)) | AG9: =IF(OR(原始資料!$A9="",32>設定!$B$3,原始資料!AI9=""),"",IF(AND(原始資料!AH9<>"",原始資料!AI9=原始資料!AH9),N(AF9)+1,1)) | AH9: =IF(OR(原始資料!$A9="",33>設定!$B$3,原始資料!AJ9=""),"",IF(AND(原始資料!AI9<>"",原始資料!AJ9=原始資料!AI9),N(AG9)+1,1)) | AI9: =IF(OR(原始資料!$A9="",34>設定!$B$3,原始資料!AK9=""),"",IF(AND(原始資料!AJ9<>"",原始資料!AK9=原始資料!AJ9),N(AH9)+1,1)) | AJ9: =IF(OR(原始資料!$A9="",35>設定!$B$3,原始資料!AL9=""),"",IF(AND(原始資料!AK9<>"",原始資料!AL9=原始資料!AK9),N(AI9)+1,1)) | AK9: =IF(OR(原始資料!$A9="",36>設定!$B$3,原始資料!AM9=""),"",IF(AND(原始資料!AL9<>"",原始資料!AM9=原始資料!AL9),N(AJ9)+1,1)) | AL9: =IF(OR(原始資料!$A9="",37>設定!$B$3,原始資料!AN9=""),"",IF(AND(原始資料!AM9<>"",原始資料!AN9=原始資料!AM9),N(AK9)+1,1)) | AM9: =IF(OR(原始資料!$A9="",38>設定!$B$3,原始資料!AO9=""),"",IF(AND(原始資料!AN9<>"",原始資料!AO9=原始資料!AN9),N(AL9)+1,1)) | AN9: =IF(OR(原始資料!$A9="",39>設定!$B$3,原始資料!AP9=""),"",IF(AND(原始資料!AO9<>"",原始資料!AP9=原始資料!AO9),N(AM9)+1,1)) | AO9: =IF(OR(原始資料!$A9="",40>設定!$B$3,原始資料!AQ9=""),"",IF(AND(原始資料!AP9<>"",原始資料!AQ9=原始資料!AP9),N(AN9)+1,1)) | AP9: =IF(OR(原始資料!$A9="",41>設定!$B$3,原始資料!AR9=""),"",IF(AND(原始資料!AQ9<>"",原始資料!AR9=原始資料!AQ9),N(AO9)+1,1)) | AQ9: =IF(OR(原始資料!$A9="",42>設定!$B$3,原始資料!AS9=""),"",IF(AND(原始資料!AR9<>"",原始資料!AS9=原始資料!AR9),N(AP9)+1,1)) | AR9: =IF(OR(原始資料!$A9="",43>設定!$B$3,原始資料!AT9=""),"",IF(AND(原始資料!AS9<>"",原始資料!AT9=原始資料!AS9),N(AQ9)+1,1)) | AS9: =IF(OR(原始資料!$A9="",44>設定!$B$3,原始資料!AU9=""),"",IF(AND(原始資料!AT9<>"",原始資料!AU9=原始資料!AT9),N(AR9)+1,1)) | AT9: =IF(OR(原始資料!$A9="",45>設定!$B$3,原始資料!AV9=""),"",IF(AND(原始資料!AU9<>"",原始資料!AV9=原始資料!AU9),N(AS9)+1,1)) | AU9: =IF(OR(原始資料!$A9="",46>設定!$B$3,原始資料!AW9=""),"",IF(AND(原始資料!AV9<>"",原始資料!AW9=原始資料!AV9),N(AT9)+1,1)) | AV9: =IF(OR(原始資料!$A9="",47>設定!$B$3,原始資料!AX9=""),"",IF(AND(原始資料!AW9<>"",原始資料!AX9=原始資料!AW9),N(AU9)+1,1)) | AW9: =IF(OR(原始資料!$A9="",48>設定!$B$3,原始資料!AY9=""),"",IF(AND(原始資料!AX9<>"",原始資料!AY9=原始資料!AX9),N(AV9)+1,1)) | AX9: =IF(OR(原始資料!$A9="",49>設定!$B$3,原始資料!AZ9=""),"",IF(AND(原始資料!AY9<>"",原始資料!AZ9=原始資料!AY9),N(AW9)+1,1)) | AY9: =IF(OR(原始資料!$A9="",50>設定!$B$3,原始資料!BA9=""),"",IF(AND(原始資料!AZ9<>"",原始資料!BA9=原始資料!AZ9),N(AX9)+1,1)) | AZ9: =IF(OR(原始資料!$A9="",51>設定!$B$3,原始資料!BB9=""),"",IF(AND(原始資料!BA9<>"",原始資料!BB9=原始資料!BA9),N(AY9)+1,1)) | BA9: =IF(OR(原始資料!$A9="",52>設定!$B$3,原始資料!BC9=""),"",IF(AND(原始資料!BB9<>"",原始資料!BC9=原始資料!BB9),N(AZ9)+1,1)) | BB9: =IF(OR(原始資料!$A9="",53>設定!$B$3,原始資料!BD9=""),"",IF(AND(原始資料!BC9<>"",原始資料!BD9=原始資料!BC9),N(BA9)+1,1)) | BC9: =IF(OR(原始資料!$A9="",54>設定!$B$3,原始資料!BE9=""),"",IF(AND(原始資料!BD9<>"",原始資料!BE9=原始資料!BD9),N(BB9)+1,1)) | BD9: =IF(OR(原始資料!$A9="",55>設定!$B$3,原始資料!BF9=""),"",IF(AND(原始資料!BE9<>"",原始資料!BF9=原始資料!BE9),N(BC9)+1,1)) | BE9: =IF(OR(原始資料!$A9="",56>設定!$B$3,原始資料!BG9=""),"",IF(AND(原始資料!BF9<>"",原始資料!BG9=原始資料!BF9),N(BD9)+1,1)) | BF9: =IF(OR(原始資料!$A9="",57>設定!$B$3,原始資料!BH9=""),"",IF(AND(原始資料!BG9<>"",原始資料!BH9=原始資料!BG9),N(BE9)+1,1)) | BG9: =IF(OR(原始資料!$A9="",58>設定!$B$3,原始資料!BI9=""),"",IF(AND(原始資料!BH9<>"",原始資料!BI9=原始資料!BH9),N(BF9)+1,1)) | BH9: =IF(OR(原始資料!$A9="",59>設定!$B$3,原始資料!BJ9=""),"",IF(AND(原始資料!BI9<>"",原始資料!BJ9=原始資料!BI9),N(BG9)+1,1)) | BI9: =IF(OR(原始資料!$A9="",60>設定!$B$3,原始資料!BK9=""),"",IF(AND(原始資料!BJ9<>"",原始資料!BK9=原始資料!BJ9),N(BH9)+1,1))
A10: =IF(原始資料!$A10="","",原始資料!$A10) | B10: =IF(OR(原始資料!$A10="",1>設定!$B$3,原始資料!D10=""),"",1) | C10: =IF(OR(原始資料!$A10="",2>設定!$B$3,原始資料!E10=""),"",IF(AND(原始資料!D10<>"",原始資料!E10=原始資料!D10),N(B10)+1,1)) | D10: =IF(OR(原始資料!$A10="",3>設定!$B$3,原始資料!F10=""),"",IF(AND(原始資料!E10<>"",原始資料!F10=原始資料!E10),N(C10)+1,1)) | E10: =IF(OR(原始資料!$A10="",4>設定!$B$3,原始資料!G10=""),"",IF(AND(原始資料!F10<>"",原始資料!G10=原始資料!F10),N(D10)+1,1)) | F10: =IF(OR(原始資料!$A10="",5>設定!$B$3,原始資料!H10=""),"",IF(AND(原始資料!G10<>"",原始資料!H10=原始資料!G10),N(E10)+1,1)) | G10: =IF(OR(原始資料!$A10="",6>設定!$B$3,原始資料!I10=""),"",IF(AND(原始資料!H10<>"",原始資料!I10=原始資料!H10),N(F10)+1,1)) | H10: =IF(OR(原始資料!$A10="",7>設定!$B$3,原始資料!J10=""),"",IF(AND(原始資料!I10<>"",原始資料!J10=原始資料!I10),N(G10)+1,1)) | I10: =IF(OR(原始資料!$A10="",8>設定!$B$3,原始資料!K10=""),"",IF(AND(原始資料!J10<>"",原始資料!K10=原始資料!J10),N(H10)+1,1)) | J10: =IF(OR(原始資料!$A10="",9>設定!$B$3,原始資料!L10=""),"",IF(AND(原始資料!K10<>"",原始資料!L10=原始資料!K10),N(I10)+1,1)) | K10: =IF(OR(原始資料!$A10="",10>設定!$B$3,原始資料!M10=""),"",IF(AND(原始資料!L10<>"",原始資料!M10=原始資料!L10),N(J10)+1,1)) | L10: =IF(OR(原始資料!$A10="",11>設定!$B$3,原始資料!N10=""),"",IF(AND(原始資料!M10<>"",原始資料!N10=原始資料!M10),N(K10)+1,1)) | M10: =IF(OR(原始資料!$A10="",12>設定!$B$3,原始資料!O10=""),"",IF(AND(原始資料!N10<>"",原始資料!O10=原始資料!N10),N(L10)+1,1)) | N10: =IF(OR(原始資料!$A10="",13>設定!$B$3,原始資料!P10=""),"",IF(AND(原始資料!O10<>"",原始資料!P10=原始資料!O10),N(M10)+1,1)) | O10: =IF(OR(原始資料!$A10="",14>設定!$B$3,原始資料!Q10=""),"",IF(AND(原始資料!P10<>"",原始資料!Q10=原始資料!P10),N(N10)+1,1)) | P10: =IF(OR(原始資料!$A10="",15>設定!$B$3,原始資料!R10=""),"",IF(AND(原始資料!Q10<>"",原始資料!R10=原始資料!Q10),N(O10)+1,1)) | Q10: =IF(OR(原始資料!$A10="",16>設定!$B$3,原始資料!S10=""),"",IF(AND(原始資料!R10<>"",原始資料!S10=原始資料!R10),N(P10)+1,1)) | R10: =IF(OR(原始資料!$A10="",17>設定!$B$3,原始資料!T10=""),"",IF(AND(原始資料!S10<>"",原始資料!T10=原始資料!S10),N(Q10)+1,1)) | S10: =IF(OR(原始資料!$A10="",18>設定!$B$3,原始資料!U10=""),"",IF(AND(原始資料!T10<>"",原始資料!U10=原始資料!T10),N(R10)+1,1)) | T10: =IF(OR(原始資料!$A10="",19>設定!$B$3,原始資料!V10=""),"",IF(AND(原始資料!U10<>"",原始資料!V10=原始資料!U10),N(S10)+1,1)) | U10: =IF(OR(原始資料!$A10="",20>設定!$B$3,原始資料!W10=""),"",IF(AND(原始資料!V10<>"",原始資料!W10=原始資料!V10),N(T10)+1,1)) | V10: =IF(OR(原始資料!$A10="",21>設定!$B$3,原始資料!X10=""),"",IF(AND(原始資料!W10<>"",原始資料!X10=原始資料!W10),N(U10)+1,1)) | W10: =IF(OR(原始資料!$A10="",22>設定!$B$3,原始資料!Y10=""),"",IF(AND(原始資料!X10<>"",原始資料!Y10=原始資料!X10),N(V10)+1,1)) | X10: =IF(OR(原始資料!$A10="",23>設定!$B$3,原始資料!Z10=""),"",IF(AND(原始資料!Y10<>"",原始資料!Z10=原始資料!Y10),N(W10)+1,1)) | Y10: =IF(OR(原始資料!$A10="",24>設定!$B$3,原始資料!AA10=""),"",IF(AND(原始資料!Z10<>"",原始資料!AA10=原始資料!Z10),N(X10)+1,1)) | Z10: =IF(OR(原始資料!$A10="",25>設定!$B$3,原始資料!AB10=""),"",IF(AND(原始資料!AA10<>"",原始資料!AB10=原始資料!AA10),N(Y10)+1,1)) | AA10: =IF(OR(原始資料!$A10="",26>設定!$B$3,原始資料!AC10=""),"",IF(AND(原始資料!AB10<>"",原始資料!AC10=原始資料!AB10),N(Z10)+1,1)) | AB10: =IF(OR(原始資料!$A10="",27>設定!$B$3,原始資料!AD10=""),"",IF(AND(原始資料!AC10<>"",原始資料!AD10=原始資料!AC10),N(AA10)+1,1)) | AC10: =IF(OR(原始資料!$A10="",28>設定!$B$3,原始資料!AE10=""),"",IF(AND(原始資料!AD10<>"",原始資料!AE10=原始資料!AD10),N(AB10)+1,1)) | AD10: =IF(OR(原始資料!$A10="",29>設定!$B$3,原始資料!AF10=""),"",IF(AND(原始資料!AE10<>"",原始資料!AF10=原始資料!AE10),N(AC10)+1,1)) | AE10: =IF(OR(原始資料!$A10="",30>設定!$B$3,原始資料!AG10=""),"",IF(AND(原始資料!AF10<>"",原始資料!AG10=原始資料!AF10),N(AD10)+1,1)) | AF10: =IF(OR(原始資料!$A10="",31>設定!$B$3,原始資料!AH10=""),"",IF(AND(原始資料!AG10<>"",原始資料!AH10=原始資料!AG10),N(AE10)+1,1)) | AG10: =IF(OR(原始資料!$A10="",32>設定!$B$3,原始資料!AI10=""),"",IF(AND(原始資料!AH10<>"",原始資料!AI10=原始資料!AH10),N(AF10)+1,1)) | AH10: =IF(OR(原始資料!$A10="",33>設定!$B$3,原始資料!AJ10=""),"",IF(AND(原始資料!AI10<>"",原始資料!AJ10=原始資料!AI10),N(AG10)+1,1)) | AI10: =IF(OR(原始資料!$A10="",34>設定!$B$3,原始資料!AK10=""),"",IF(AND(原始資料!AJ10<>"",原始資料!AK10=原始資料!AJ10),N(AH10)+1,1)) | AJ10: =IF(OR(原始資料!$A10="",35>設定!$B$3,原始資料!AL10=""),"",IF(AND(原始資料!AK10<>"",原始資料!AL10=原始資料!AK10),N(AI10)+1,1)) | AK10: =IF(OR(原始資料!$A10="",36>設定!$B$3,原始資料!AM10=""),"",IF(AND(原始資料!AL10<>"",原始資料!AM10=原始資料!AL10),N(AJ10)+1,1)) | AL10: =IF(OR(原始資料!$A10="",37>設定!$B$3,原始資料!AN10=""),"",IF(AND(原始資料!AM10<>"",原始資料!AN10=原始資料!AM10),N(AK10)+1,1)) | AM10: =IF(OR(原始資料!$A10="",38>設定!$B$3,原始資料!AO10=""),"",IF(AND(原始資料!AN10<>"",原始資料!AO10=原始資料!AN10),N(AL10)+1,1)) | AN10: =IF(OR(原始資料!$A10="",39>設定!$B$3,原始資料!AP10=""),"",IF(AND(原始資料!AO10<>"",原始資料!AP10=原始資料!AO10),N(AM10)+1,1)) | AO10: =IF(OR(原始資料!$A10="",40>設定!$B$3,原始資料!AQ10=""),"",IF(AND(原始資料!AP10<>"",原始資料!AQ10=原始資料!AP10),N(AN10)+1,1)) | AP10: =IF(OR(原始資料!$A10="",41>設定!$B$3,原始資料!AR10=""),"",IF(AND(原始資料!AQ10<>"",原始資料!AR10=原始資料!AQ10),N(AO10)+1,1)) | AQ10: =IF(OR(原始資料!$A10="",42>設定!$B$3,原始資料!AS10=""),"",IF(AND(原始資料!AR10<>"",原始資料!AS10=原始資料!AR10),N(AP10)+1,1)) | AR10: =IF(OR(原始資料!$A10="",43>設定!$B$3,原始資料!AT10=""),"",IF(AND(原始資料!AS10<>"",原始資料!AT10=原始資料!AS10),N(AQ10)+1,1)) | AS10: =IF(OR(原始資料!$A10="",44>設定!$B$3,原始資料!AU10=""),"",IF(AND(原始資料!AT10<>"",原始資料!AU10=原始資料!AT10),N(AR10)+1,1)) | AT10: =IF(OR(原始資料!$A10="",45>設定!$B$3,原始資料!AV10=""),"",IF(AND(原始資料!AU10<>"",原始資料!AV10=原始資料!AU10),N(AS10)+1,1)) | AU10: =IF(OR(原始資料!$A10="",46>設定!$B$3,原始資料!AW10=""),"",IF(AND(原始資料!AV10<>"",原始資料!AW10=原始資料!AV10),N(AT10)+1,1)) | AV10: =IF(OR(原始資料!$A10="",47>設定!$B$3,原始資料!AX10=""),"",IF(AND(原始資料!AW10<>"",原始資料!AX10=原始資料!AW10),N(AU10)+1,1)) | AW10: =IF(OR(原始資料!$A10="",48>設定!$B$3,原始資料!AY10=""),"",IF(AND(原始資料!AX10<>"",原始資料!AY10=原始資料!AX10),N(AV10)+1,1)) | AX10: =IF(OR(原始資料!$A10="",49>設定!$B$3,原始資料!AZ10=""),"",IF(AND(原始資料!AY10<>"",原始資料!AZ10=原始資料!AY10),N(AW10)+1,1)) | AY10: =IF(OR(原始資料!$A10="",50>設定!$B$3,原始資料!BA10=""),"",IF(AND(原始資料!AZ10<>"",原始資料!BA10=原始資料!AZ10),N(AX10)+1,1)) | AZ10: =IF(OR(原始資料!$A10="",51>設定!$B$3,原始資料!BB10=""),"",IF(AND(原始資料!BA10<>"",原始資料!BB10=原始資料!BA10),N(AY10)+1,1)) | BA10: =IF(OR(原始資料!$A10="",52>設定!$B$3,原始資料!BC10=""),"",IF(AND(原始資料!BB10<>"",原始資料!BC10=原始資料!BB10),N(AZ10)+1,1)) | BB10: =IF(OR(原始資料!$A10="",53>設定!$B$3,原始資料!BD10=""),"",IF(AND(原始資料!BC10<>"",原始資料!BD10=原始資料!BC10),N(BA10)+1,1)) | BC10: =IF(OR(原始資料!$A10="",54>設定!$B$3,原始資料!BE10=""),"",IF(AND(原始資料!BD10<>"",原始資料!BE10=原始資料!BD10),N(BB10)+1,1)) | BD10: =IF(OR(原始資料!$A10="",55>設定!$B$3,原始資料!BF10=""),"",IF(AND(原始資料!BE10<>"",原始資料!BF10=原始資料!BE10),N(BC10)+1,1)) | BE10: =IF(OR(原始資料!$A10="",56>設定!$B$3,原始資料!BG10=""),"",IF(AND(原始資料!BF10<>"",原始資料!BG10=原始資料!BF10),N(BD10)+1,1)) | BF10: =IF(OR(原始資料!$A10="",57>設定!$B$3,原始資料!BH10=""),"",IF(AND(原始資料!BG10<>"",原始資料!BH10=原始資料!BG10),N(BE10)+1,1)) | BG10: =IF(OR(原始資料!$A10="",58>設定!$B$3,原始資料!BI10=""),"",IF(AND(原始資料!BH10<>"",原始資料!BI10=原始資料!BH10),N(BF10)+1,1)) | BH10: =IF(OR(原始資料!$A10="",59>設定!$B$3,原始資料!BJ10=""),"",IF(AND(原始資料!BI10<>"",原始資料!BJ10=原始資料!BI10),N(BG10)+1,1)) | BI10: =IF(OR(原始資料!$A10="",60>設定!$B$3,原始資料!BK10=""),"",IF(AND(原始資料!BJ10<>"",原始資料!BK10=原始資料!BJ10),N(BH10)+1,1))
