Workbook

Sheet 使用說明
B1: 期中團體作業 事例分類與 Cohen’s κ 範本
B2: 員工意向調查 HRM922 2026 Fall 國立中山大學人力資源管理研究所 王豫萱
B4: 操作步驟
B5: 1 事例清單：每一列一則事例，分情境、行為、結果三欄。課堂上使用已收集的 40 則；期中作業換成本組收集的事例
B6: 2 事例清單 E 欄篩選：太籠統、看不出行為的剔除；不屬於本構念的剔除（例如合理申訴、正當拒絕）
B7: 3 編碼簿：全組讀完保留的事例後，討論出類別，填入類別名稱、定義、納入條件、排除條件；下拉選單會固定附上「無法歸類」
B8: 4 獨立分類：甲、乙各自另存一份檔案，甲只填「甲分類」、乙只填「乙分類」，分類時不討論、不看對方的檔案
B9: 5 合併：乙把自己檔案「乙分類」的 E 欄整欄複製，貼到甲檔案「乙分類」的 E 欄（選擇性貼上：值）
B10: 6 交叉表與κ：自動算出交叉表、觀察同意率、碰巧一致率、κ、判定結果與分歧最多的組合
B11: 7 討論與修訂：不一致的事例在事例清單 J、K 欄記下討論後的決定與理由；κ 未通過時修訂編碼簿，另存新檔重新分類，企劃書附兩次結果
B12: 8 標籤驗證：分類完成後才打開，填入旁人原話，看看「玻璃心」這類標籤落在哪些類別
B14: 三位組員時
... B32: Landis, J. R., & Koch, G. G. (1977). The measurement of observer agreement for categorical data. Biometrics, 33(1), 159–174. https://doi.org/10.2307/2529310

Sheet 編碼簿
A1: 編碼簿
A2: 全組讀完保留的事例後，討論出類別再填寫；類別名稱不可重複。下拉選單＝本表 B5:B14 加上最後一列的「無法歸類」
A4: 代號 | B4: 類別名稱 | C4: 定義 | D4: 納入條件 | E4: 排除條件 | F4: 典型事例編號
A5: 類別 1
A6: 類別 2
A7: 類別 3
A8: 類別 4
A9: 類別 5
A10: 類別 6
A11: 類別 7
A12: 類別 8
A13: 類別 9
A14: 類別 10
A15: 固定 | B15: 無法歸類 | C15: 看過定義後，仍無法歸入任何一類的事例

Sheet 事例清單
A1: 事例清單
A2: A–D 欄為事例；E 欄先篩選；G、H 欄自動帶入甲乙的分類；J、K 欄記錄討論後的決定
A3: ="事例 "&COUNTA(A5:A304)&" 則；保留 "&COUNTIF(E5:E304,"保留")&" 則；甲乙都已分類 "&SUMPRODUCT((G5:G304<>"")*(H5:H304<>"")*(F5:F304="是"))&" 則"
A4: 編號 | B4: 情境 | C4: 行為 | D4: 結果 | E4: 篩選 | F4: 納入計算 | G4: 甲的分類 | H4: 乙的分類 | I4: 是否一致 | J4: 討論後決定 | K4: 處理紀錄
A5: 01 | B5: 週會上業務主管質疑他整理的客戶名單 | C5: 當場眼眶泛紅，說話開始哽咽 | D5: 會議暫停五分鐘，後續報告改由同事代講 | F5: =IF(A5="","",IF(LEFT(E5,2)="剔除","否","是")) | G5: =IF(甲分類!E5="","",甲分類!E5) | H5: =IF(乙分類!E5="","",乙分類!E5) | I5: =IF(OR(G5="",H5=""),"",IF(G5=H5,"一致","不一致"))
A6: 02 | B6: 客戶在群組裡公開抱怨交期延誤 | C6: 在座位上沉默很久，午餐也沒去吃 | D6: 下午寄出的回覆信語氣很消極 | F6: =IF(A6="","",IF(LEFT(E6,2)="剔除","否","是")) | G6: =IF(甲分類!E6="","",甲分類!E6) | H6: =IF(乙分類!E6="","",乙分類!E6) | I6: =IF(OR(G6="",H6=""),"",IF(G6=H6,"一致","不一致"))
A7: 03 | B7: 主管退回企劃書，要求整份重寫 | C7: 拿著企劃書站起來大聲辯解，說主管沒看清楚 | D7: 辦公室氣氛很僵，主管改天才再談 | F7: =IF(A7="","",IF(LEFT(E7,2)="剔除","否","是")) | G7: =IF(甲分類!E7="","",甲分類!E7) | H7: =IF(乙分類!E7="","",乙分類!E7) | I7: =IF(OR(G7="",H7=""),"",IF(G7=H7,"一致","不一致"))
A8: 04 | B8: 年度考核面談拿到「待改進」 | C8: 面談結束後在樓梯間哭了二十分鐘 | D8: 回座位後整個下午沒有說話 | F8: =IF(A8="","",IF(LEFT(E8,2)="剔除","否","是")) | G8: =IF(甲分類!E8="","",甲分類!E8) | H8: =IF(乙分類!E8="","",乙分類!E8) | I8: =IF(OR(G8="",H8=""),"",IF(G8=H8,"一致","不一致"))
A9: 05 | B9: 資深同事在走廊提醒他文件格式不對 | C9: 臉一沉，回了一句「我知道」就轉身離開 | D9: 兩人之後一週沒有交談 | F9: =IF(A9="","",IF(LEFT(E9,2)="剔除","否","是")) | G9: =IF(甲分類!E9="","",甲分類!E9) | H9: =IF(乙分類!E9="","",乙分類!E9) | I9: =IF(OR(G9="",H9=""),"",IF(G9=H9,"一致","不一致"))
A10: 06 | B10: 專案檢討會上被點名進度落後 | C10: 說話聲音發抖，手一直握著筆 | D10: 報告草草結束，問題沒有討論完 | F10: =IF(A10="","",IF(LEFT(E10,2)="剔除","否","是")) | G10: =IF(甲分類!E10="","",甲分類!E10) | H10: =IF(乙分類!E10="","",乙分類!E10) | I10: =IF(OR(G10="",H10=""),"",IF(G10=H10,"一致","不一致"))
A11: 07 | B11: 被指出合約金額打錯 | C11: 當天下班前都在反覆檢查那份合約，沒辦法做別的事 | D11: 當天其他工作全部延到隔天 | F11: =IF(A11="","",IF(LEFT(E11,2)="剔除","否","是")) | G11: =IF(甲分類!E11="","",甲分類!E11) | H11: =IF(乙分類!E11="","",乙分類!E11) | I11: =IF(OR(G11="",H11=""),"",IF(G11=H11,"一致","不一致"))
A12: 08 | B12: 主管在一對一面談中說他簡報太冗長 | C12: 接下來三天都在重寫簡報，晚上睡不好 | D12: 原本排定的工作進度延後一週 | F12: =IF(A12="","",IF(LEFT(E12,2)="剔除","否","是")) | G12: =IF(甲分類!E12="","",甲分類!E12) | H12: =IF(乙分類!E12="","",乙分類!E12) | I12: =IF(OR(G12="",H12=""),"",IF(G12=H12,"一致","不一致"))
A13: 09 | B13: 被客戶當面批評服務態度 | C13: 隔天早上主動跟主管說心情還沒恢復，想先做後台工作 | D13: 主管安排他暫時不接觸客戶兩天 | F13: =IF(A13="","",IF(LEFT(E13,2)="剔除","否","是")) | G13: =IF(甲分類!E13="","",甲分類!E13) | H13: =IF(乙分類!E13="","",乙分類!E13) | I13: =IF(OR(G13="",H13=""),"",IF(G13=H13,"一致","不一致"))
A14: 10 | B14: 品管會議上被指出產品瑕疵是他漏檢 | C14: 會後一整週都很低落，常常一個人發呆 | D14: 那週的檢驗量比平常少三成 | F14: =IF(A14="","",IF(LEFT(E14,2)="剔除","否","是")) | G14: =IF(甲分類!E14="","",甲分類!E14) | H14: =IF(乙分類!E14="","",乙分類!E14) | I14: =IF(OR(G14="",H14=""),"",IF(G14=H14,"一致","不一致"))
A15: 11 | B15: 主管指出他的報銷單據缺漏太多，要他整份重填 | C15: 當天沒說什麼，隔週又向同事提起那次被退件的感受 | D15: 同事覺得他還在意那件事 | F15: =IF(A15="","",IF(LEFT(E15,2)="剔除","否","是")) | G15: =IF(甲分類!E15="","",甲分類!E15) | H15: =IF(乙分類!E15="","",乙分類!E15) | I15: =IF(OR(G15="",H15=""),"",IF(G15=H15,"一致","不一致"))
A16: 12 | B16: 試用期評估被建議加強溝通 | C16: 評估後一個多月，每次開會前都很緊張 | D16: 在會議中幾乎不發言 | F16: =IF(A16="","",IF(LEFT(E16,2)="剔除","否","是")) | G16: =IF(甲分類!E16="","",甲分類!E16) | H16: =IF(乙分類!E16="","",乙分類!E16) | I16: =IF(OR(G16="",H16=""),"",IF(G16=H16,"一致","不一致"))
... A27: 23 | B27: 同事在茶水間開他身材的玩笑 | C27: 當場表示不舒服，請對方不要再說 | D27: 對方道歉，之後沒有再發生 | F27: =IF(A27="","",IF(LEFT(E27,2)="剔除","否","是")) | G27: =IF(甲分類!E27="","",甲分類!E27) | H27: =IF(乙分類!E27="","",乙分類!E27) | I27: =IF(OR(G27="",H27=""),"",IF(G27=H27,"一致","不一致"))
A28: 24 | B28: 他就是很玻璃心 | F28: =IF(A28="","",IF(LEFT(E28,2)="剔除","否","是")) | G28: =IF(甲分類!E28="","",甲分類!E28) | H28: =IF(乙分類!E28="","",乙分類!E28) | I28: =IF(OR(G28="",H28=""),"",IF(G28=H28,"一致","不一致"))
A29: 25 | B29: 新人常常這樣 | C29: 反應很大 | F29: =IF(A29="","",IF(LEFT(E29,2)="剔除","否","是")) | G29: =IF(甲分類!E29="","",甲分類!E29) | H29: =IF(乙分類!E29="","",乙分類!E29) | I29: =IF(OR(G29="",H29=""),"",IF(G29=H29,"一致","不一致"))
A30: 26 | B30: 上次開會的時候 | C30: 他好像不太高興 | D30: 後來就那樣了 | F30: =IF(A30="","",IF(LEFT(E30,2)="剔除","否","是")) | G30: =IF(甲分類!E30="","",甲分類!E30) | H30: =IF(乙分類!E30="","",乙分類!E30) | I30: =IF(OR(G30="",H30=""),"",IF(G30=H30,"一致","不一致"))
A31: 27 | B31: 被主管指出簡報有錯字 | C31: 當場臉紅、說話變小聲 | D31: 會後跑去洗手間很久才回來 | F31: =IF(A31="","",IF(LEFT(E31,2)="剔除","否","是")) | G31: =IF(甲分類!E31="","",甲分類!E31) | H31: =IF(乙分類!E31="","",乙分類!E31) | I31: =IF(OR(G31="",H31=""),"",IF(G31=H31,"一致","不一致"))
A32: 28 | B32: 被主管問到專案預算為什麼超支 | C32: 語氣激動地說都是別的部門造成的，越講越大聲 | D32: 會議改期 | F32: =IF(A32="","",IF(LEFT(E32,2)="剔除","否","是")) | G32: =IF(甲分類!E32="","",甲分類!E32) | H32: =IF(乙分類!E32="","",乙分類!E32) | I32: =IF(OR(G32="",H32=""),"",IF(G32=H32,"一致","不一致"))
A33: 29 | B33: 被外部稽核指出流程缺失 | C33: 稽核期間每天加班到很晚，反覆整理文件，假日也睡不著 | D33: 稽核結束後請了三天病假 | F33: =IF(A33="","",IF(LEFT(E33,2)="剔除","否","是")) | G33: =IF(甲分類!E33="","",甲分類!E33) | H33: =IF(乙分類!E33="","",乙分類!E33) | I33: =IF(OR(G33="",H33=""),"",IF(G33=H33,"一致","不一致"))
A34: 30 | B34: 被主管說「這種錯不該犯」 | C34: 午休時一直在跟同事抱怨這句話，下午也還在提 | D34: 下午的工作幾乎沒有進度 | F34: =IF(A34="","",IF(LEFT(E34,2)="剔除","否","是")) | G34: =IF(甲分類!E34="","",甲分類!E34) | H34: =IF(乙分類!E34="","",乙分類!E34) | I34: =IF(OR(G34="",H34=""),"",IF(G34=H34,"一致","不一致"))
A35: 31 | B35: 被指派的同事說他交接文件寫得不清楚 | C35: 沉默不回應，之後交接都只用最簡短的文字 | D35: 後續交接出錯兩次 | F35: =IF(A35="","",IF(LEFT(E35,2)="剔除","否","是")) | G35: =IF(甲分類!E35="","",甲分類!E35) | H35: =IF(乙分類!E35="","",乙分類!E35) | I35: =IF(OR(G35="",H35=""),"",IF(G35=H35,"一致","不一致"))
A36: 32 | B36: 主管建議他多跟資深同事學習 | C36: 之後午餐刻意避開那位資深同事 | D36: 部門聚餐時座位也不坐在附近 | F36: =IF(A36="","",IF(LEFT(E36,2)="剔除","否","是")) | G36: =IF(甲分類!E36="","",甲分類!E36) | H36: =IF(乙分類!E36="","",乙分類!E36) | I36: =IF(OR(G36="",H36=""),"",IF(G36=H36,"一致","不一致"))
A37: 33 | B37: 專案結案會議中主管說他「表現普通」 | C37: 當天在座位上哭，同事遞衛生紙也沒有回應 | D37: 主管事後私下跟他道歉 | F37: =IF(A37="","",IF(LEFT(E37,2)="剔除","否","是")) | G37: =IF(甲分類!E37="","",甲分類!E37) | H37: =IF(乙分類!E37="","",乙分類!E37) | I37: =IF(OR(G37="",H37=""),"",IF(G37=H37,"一致","不一致"))
A38: 34 | B38: 被主管指出出貨單數量填錯 | C38: 之後所有單據都請同事幫忙再看一次才敢送出 | D38: 同事開始抱怨被打擾 | F38: =IF(A38="","",IF(LEFT(E38,2)="剔除","否","是")) | G38: =IF(甲分類!E38="","",甲分類!E38) | H38: =IF(乙分類!E38="","",乙分類!E38) | I38: =IF(OR(G38="",H38=""),"",IF(G38=H38,"一致","不一致"))
A39: 35 | B39: 被訓練講師在課堂上點出操作錯誤 | C39: 下課後跟主管說不想再參加這門訓練 | D39: 主管讓他改上線上課程 | F39: =IF(A39="","",IF(LEFT(E39,2)="剔除","否","是")) | G39: =IF(甲分類!E39="","",甲分類!E39) | H39: =IF(乙分類!E39="","",乙分類!E39) | I39: =IF(OR(G39="",H39=""),"",IF(G39=H39,"一致","不一致"))
A40: 36 | B40: 被客戶在電話裡大聲罵 | C40: 掛電話後手還在發抖，花了半小時才能接下一通 | D40: 當天接聽量比平常少一半 | F40: =IF(A40="","",IF(LEFT(E40,2)="剔除","否","是")) | G40: =IF(甲分類!E40="","",甲分類!E40) | H40: =IF(乙分類!E40="","",乙分類!E40) | I40: =IF(OR(G40="",H40=""),"",IF(G40=H40,"一致","不一致"))
A41: 37 | B41: 主管在全體會議上點名表揚別人、指出他的不足 | C41: 會後寫了一封很長的信解釋自己的努力，寄給主管 | D41: 主管覺得他反應過度 | F41: =IF(A41="","",IF(LEFT(E41,2)="剔除","否","是")) | G41: =IF(甲分類!E41="","",甲分類!E41) | H41: =IF(乙分類!E41="","",乙分類!E41) | I41: =IF(OR(G41="",H41=""),"",IF(G41=H41,"一致","不一致"))
... A44: 40 | B44: 被主管要求說明遲交原因 | C44: 說明完原因後主動提出改善做法，下次準時完成 | D44: 主管認為他處理得很好 | F44: =IF(A44="","",IF(LEFT(E44,2)="剔除","否","是")) | G44: =IF(甲分類!E44="","",甲分類!E44) | H44: =IF(乙分類!E44="","",乙分類!E44) | I44: =IF(OR(G44="",H44=""),"",IF(G44=H44,"一致","不一致"))
F45: =IF(A45="","",IF(LEFT(E45,2)="剔除","否","是")) | G45: =IF(甲分類!E45="","",甲分類!E45) | H45: =IF(乙分類!E45="","",乙分類!E45) | I45: =IF(OR(G45="",H45=""),"",IF(G45=H45,"一致","不一致"))
F46: =IF(A46="","",IF(LEFT(E46,2)="剔除","否","是")) | G46: =IF(甲分類!E46="","",甲分類!E46) | H46: =IF(乙分類!E46="","",乙分類!E46) | I46: =IF(OR(G46="",H46=""),"",IF(G46=H46,"一致","不一致"))
F47: =IF(A47="","",IF(LEFT(E47,2)="剔除","否","是")) | G47: =IF(甲分類!E47="","",甲分類!E47) | H47: =IF(乙分類!E47="","",乙分類!E47) | I47: =IF(OR(G47="",H47=""),"",IF(G47=H47,"一致","不一致"))
F48: =IF(A48="","",IF(LEFT(E48,2)="剔除","否","是")) | G48: =IF(甲分類!E48="","",甲分類!E48) | H48: =IF(乙分類!E48="","",乙分類!E48) | I48: =IF(OR(G48="",H48=""),"",IF(G48=H48,"一致","不一致"))
F49: =IF(A49="","",IF(LEFT(E49,2)="剔除","否","是")) | G49: =IF(甲分類!E49="","",甲分類!E49) | H49: =IF(乙分類!E49="","",乙分類!E49) | I49: =IF(OR(G49="",H49=""),"",IF(G49=H49,"一致","不一致"))
F50: =IF(A50="","",IF(LEFT(E50,2)="剔除","否","是")) | G50: =IF(甲分類!E50="","",甲分類!E50) | H50: =IF(乙分類!E50="","",乙分類!E50) | I50: =IF(OR(G50="",H50=""),"",IF(G50=H50,"一致","不一致"))
F51: =IF(A51="","",IF(LEFT(E51,2)="剔除","否","是")) | G51: =IF(甲分類!E51="","",甲分類!E51) | H51: =IF(乙分類!E51="","",乙分類!E51) | I51: =IF(OR(G51="",H51=""),"",IF(G51=H51,"一致","不一致"))
F52: =IF(A52="","",IF(LEFT(E52,2)="剔除","否","是")) | G52: =IF(甲分類!E52="","",甲分類!E52) | H52: =IF(乙分類!E52="","",乙分類!E52) | I52: =IF(OR(G52="",H52=""),"",IF(G52=H52,"一致","不一致"))
...

Sheet 甲分類
A1: 甲的分類
A2: 只由甲填寫 E 欄；分類時不討論，也不看另一位組員的檔案。剔除的事例顯示刪除線，不需分類
A4: 編號 | B4: 情境 | C4: 行為 | D4: 結果 | E4: 甲的分類
A5: =IF(事例清單!A5="","",事例清單!A5) | B5: =IF(事例清單!B5="","",事例清單!B5) | C5: =IF(事例清單!C5="","",事例清單!C5) | D5: =IF(事例清單!D5="","",事例清單!D5)
A6: =IF(事例清單!A6="","",事例清單!A6) | B6: =IF(事例清單!B6="","",事例清單!B6) | C6: =IF(事例清單!C6="","",事例清單!C6) | D6: =IF(事例清單!D6="","",事例清單!D6)
A7: =IF(事例清單!A7="","",事例清單!A7) | B7: =IF(事例清單!B7="","",事例清單!B7) | C7: =IF(事例清單!C7="","",事例清單!C7) | D7: =IF(事例清單!D7="","",事例清單!D7)
A8: =IF(事例清單!A8="","",事例清單!A8) | B8: =IF(事例清單!B8="","",事例清單!B8) | C8: =IF(事例清單!C8="","",事例清單!C8) | D8: =IF(事例清單!D8="","",事例清單!D8)
A9: =IF(事例清單!A9="","",事例清單!A9) | B9: =IF(事例清單!B9="","",事例清單!B9) | C9: =IF(事例清單!C9="","",事例清單!C9) | D9: =IF(事例清單!D9="","",事例清單!D9)
A10: =IF(事例清單!A10="","",事例清單!A10) | B10: =IF(事例清單!B10="","",事例清單!B10) | C10: =IF(事例清單!C10="","",事例清單!C10) | D10: =IF(事例清單!D10="","",事例清單!D10)
A11: =IF(事例清單!A11="","",事例清單!A11) | B11: =IF(事例清單!B11="","",事例清單!B11) | C11: =IF(事例清單!C11="","",事例清單!C11) | D11: =IF(事例清單!D11="","",事例清單!D11)
A12: =IF(事例清單!A12="","",事例清單!A12) | B12: =IF(事例清單!B12="","",事例清單!B12) | C12: =IF(事例清單!C12="","",事例清單!C12) | D12: =IF(事例清單!D12="","",事例清單!D12)
A13: =IF(事例清單!A13="","",事例清單!A13) | B13: =IF(事例清單!B13="","",事例清單!B13) | C13: =IF(事例清單!C13="","",事例清單!C13) | D13: =IF(事例清單!D13="","",事例清單!D13)
A14: =IF(事例清單!A14="","",事例清單!A14) | B14: =IF(事例清單!B14="","",事例清單!B14) | C14: =IF(事例清單!C14="","",事例清單!C14) | D14: =IF(事例清單!D14="","",事例清單!D14)
A15: =IF(事例清單!A15="","",事例清單!A15) | B15: =IF(事例清單!B15="","",事例清單!B15) | C15: =IF(事例清單!C15="","",事例清單!C15) | D15: =IF(事例清單!D15="","",事例清單!D15)
A16: =IF(事例清單!A16="","",事例清單!A16) | B16: =IF(事例清單!B16="","",事例清單!B16) | C16: =IF(事例清單!C16="","",事例清單!C16) | D16: =IF(事例清單!D16="","",事例清單!D16)
... A304: =IF(事例清單!A304="","",事例清單!A304) | B304: =IF(事例清單!B304="","",事例清單!B304) | C304: =IF(事例清單!C304="","",事例清單!C304) | D304: =IF(事例清單!D304="","",事例清單!D304)

Sheet 乙分類
A1: 乙的分類
A2: 只由乙填寫 E 欄；分類時不討論，也不看另一位組員的檔案。剔除的事例顯示刪除線，不需分類
A4: 編號 | B4: 情境 | C4: 行為 | D4: 結果 | E4: 乙的分類
A5: =IF(事例清單!A5="","",事例清單!A5) | B5: =IF(事例清單!B5="","",事例清單!B5) | C5: =IF(事例清單!C5="","",事例清單!C5) | D5: =IF(事例清單!D5="","",事例清單!D5)
A6: =IF(事例清單!A6="","",事例清單!A6) | B6: =IF(事例清單!B6="","",事例清單!B6) | C6: =IF(事例清單!C6="","",事例清單!C6) | D6: =IF(事例清單!D6="","",事例清單!D6)
A7: =IF(事例清單!A7="","",事例清單!A7) | B7: =IF(事例清單!B7="","",事例清單!B7) | C7: =IF(事例清單!C7="","",事例清單!C7) | D7: =IF(事例清單!D7="","",事例清單!D7)
A8: =IF(事例清單!A8="","",事例清單!A8) | B8: =IF(事例清單!B8="","",事例清單!B8) | C8: =IF(事例清單!C8="","",事例清單!C8) | D8: =IF(事例清單!D8="","",事例清單!D8)
A9: =IF(事例清單!A9="","",事例清單!A9) | B9: =IF(事例清單!B9="","",事例清單!B9) | C9: =IF(事例清單!C9="","",事例清單!C9) | D9: =IF(事例清單!D9="","",事例清單!D9)
A10: =IF(事例清單!A10="","",事例清單!A10) | B10: =IF(事例清單!B10="","",事例清單!B10) | C10: =IF(事例清單!C10="","",事例清單!C10) | D10: =IF(事例清單!D10="","",事例清單!D10)
A11: =IF(事例清單!A11="","",事例清單!A11) | B11: =IF(事例清單!B11="","",事例清單!B11) | C11: =IF(事例清單!C11="","",事例清單!C11) | D11: =IF(事例清單!D11="","",事例清單!D11)
A12: =IF(事例清單!A12="","",事例清單!A12) | B12: =IF(事例清單!B12="","",事例清單!B12) | C12: =IF(事例清單!C12="","",事例清單!C12) | D12: =IF(事例清單!D12="","",事例清單!D12)
A13: =IF(事例清單!A13="","",事例清單!A13) | B13: =IF(事例清單!B13="","",事例清單!B13) | C13: =IF(事例清單!C13="","",事例清單!C13) | D13: =IF(事例清單!D13="","",事例清單!D13)
A14: =IF(事例清單!A14="","",事例清單!A14) | B14: =IF(事例清單!B14="","",事例清單!B14) | C14: =IF(事例清單!C14="","",事例清單!C14) | D14: =IF(事例清單!D14="","",事例清單!D14)
A15: =IF(事例清單!A15="","",事例清單!A15) | B15: =IF(事例清單!B15="","",事例清單!B15) | C15: =IF(事例清單!C15="","",事例清單!C15) | D15: =IF(事例清單!D15="","",事例清單!D15)
A16: =IF(事例清單!A16="","",事例清單!A16) | B16: =IF(事例清單!B16="","",事例清單!B16) | C16: =IF(事例清單!C16="","",事例清單!C16) | D16: =IF(事例清單!D16="","",事例清單!D16)
... A304: =IF(事例清單!A304="","",事例清單!A304) | B304: =IF(事例清單!B304="","",事例清單!B304) | C304: =IF(事例清單!C304="","",事例清單!C304) | D304: =IF(事例清單!D304="","",事例清單!D304)

Sheet 交叉表與κ
A1: 交叉表與 Cohen’s κ（自動計算，請勿修改）
A2: 橫列是甲的分類，直欄是乙的分類；粉紅色對角線是兩人歸到同一類的事例數
A4: 甲 ＼ 乙 | B4: =IF(編碼簿!$B$5="","",編碼簿!$B$5) | C4: =IF(編碼簿!$B$6="","",編碼簿!$B$6) | D4: =IF(編碼簿!$B$7="","",編碼簿!$B$7) | E4: =IF(編碼簿!$B$8="","",編碼簿!$B$8) | F4: =IF(編碼簿!$B$9="","",編碼簿!$B$9) | G4: =IF(編碼簿!$B$10="","",編碼簿!$B$10) | H4: =IF(編碼簿!$B$11="","",編碼簿!$B$11) | I4: =IF(編碼簿!$B$12="","",編碼簿!$B$12) | J4: =IF(編碼簿!$B$13="","",編碼簿!$B$13) | K4: =IF(編碼簿!$B$14="","",編碼簿!$B$14) | L4: =IF(編碼簿!$B$15="","",編碼簿!$B$15) | M4: 甲合計
A5: =IF(編碼簿!$B$5="","",編碼簿!$B$5) | B5: =IF(OR($A5="",B$4=""),"",COUNTIFS(事例清單!$G$5:$G$304,$A5,事例清單!$H$5:$H$304,B$4,事例清單!$F$5:$F$304,"是")) | C5: =IF(OR($A5="",C$4=""),"",COUNTIFS(事例清單!$G$5:$G$304,$A5,事例清單!$H$5:$H$304,C$4,事例清單!$F$5:$F$304,"是")) | D5: =IF(OR($A5="",D$4=""),"",COUNTIFS(事例清單!$G$5:$G$304,$A5,事例清單!$H$5:$H$304,D$4,事例清單!$F$5:$F$304,"是")) | E5: =IF(OR($A5="",E$4=""),"",COUNTIFS(事例清單!$G$5:$G$304,$A5,事例清單!$H$5:$H$304,E$4,事例清單!$F$5:$F$304,"是")) | F5: =IF(OR($A5="",F$4=""),"",COUNTIFS(事例清單!$G$5:$G$304,$A5,事例清單!$H$5:$H$304,F$4,事例清單!$F$5:$F$304,"是")) | G5: =IF(OR($A5="",G$4=""),"",COUNTIFS(事例清單!$G$5:$G$304,$A5,事例清單!$H$5:$H$304,G$4,事例清單!$F$5:$F$304,"是")) | H5: =IF(OR($A5="",H$4=""),"",COUNTIFS(事例清單!$G$5:$G$304,$A5,事例清單!$H$5:$H$304,H$4,事例清單!$F$5:$F$304,"是")) | I5: =IF(OR($A5="",I$4=""),"",COUNTIFS(事例清單!$G$5:$G$304,$A5,事例清單!$H$5:$H$304,I$4,事例清單!$F$5:$F$304,"是")) | ... L5: =IF(OR($A5="",L$4=""),"",COUNTIFS(事例清單!$G$5:$G$304,$A5,事例清單!$H$5:$H$304,L$4,事例清單!$F$5:$F$304,"是")) | M5: =IF($A5="","",SUM(B5:L5)) | N5: =IF(OR($A$5="",C$4=""),"","甲歸「"&$A$5&"」、乙歸「"&C$4&"」") | O5: =IF(N5="",0,C5) | P5: =IF($A5="",0,N(M5)*N(B16))
A6: =IF(編碼簿!$B$6="","",編碼簿!$B$6) | B6: =IF(OR($A6="",B$4=""),"",COUNTIFS(事例清單!$G$5:$G$304,$A6,事例清單!$H$5:$H$304,B$4,事例清單!$F$5:$F$304,"是")) | C6: =IF(OR($A6="",C$4=""),"",COUNTIFS(事例清單!$G$5:$G$304,$A6,事例清單!$H$5:$H$304,C$4,事例清單!$F$5:$F$304,"是")) | D6: =IF(OR($A6="",D$4=""),"",COUNTIFS(事例清單!$G$5:$G$304,$A6,事例清單!$H$5:$H$304,D$4,事例清單!$F$5:$F$304,"是")) | E6: =IF(OR($A6="",E$4=""),"",COUNTIFS(事例清單!$G$5:$G$304,$A6,事例清單!$H$5:$H$304,E$4,事例清單!$F$5:$F$304,"是")) | F6: =IF(OR($A6="",F$4=""),"",COUNTIFS(事例清單!$G$5:$G$304,$A6,事例清單!$H$5:$H$304,F$4,事例清單!$F$5:$F$304,"是")) | G6: =IF(OR($A6="",G$4=""),"",COUNTIFS(事例清單!$G$5:$G$304,$A6,事例清單!$H$5:$H$304,G$4,事例清單!$F$5:$F$304,"是")) | H6: =IF(OR($A6="",H$4=""),"",COUNTIFS(事例清單!$G$5:$G$304,$A6,事例清單!$H$5:$H$304,H$4,事例清單!$F$5:$F$304,"是")) | I6: =IF(OR($A6="",I$4=""),"",COUNTIFS(事例清單!$G$5:$G$304,$A6,事例清單!$H$5:$H$304,I$4,事例清單!$F$5:$F$304,"是")) | ... L6: =IF(OR($A6="",L$4=""),"",COUNTIFS(事例清單!$G$5:$G$304,$A6,事例清單!$H$5:$H$304,L$4,事例清單!$F$5:$F$304,"是")) | M6: =IF($A6="","",SUM(B6:L6)) | N6: =IF(OR($A$5="",D$4=""),"","甲歸「"&$A$5&"」、乙歸「"&D$4&"」") | O6: =IF(N6="",0,D5) | P6: =IF($A6="",0,N(M6)*N(C16))
A7: =IF(編碼簿!$B$7="","",編碼簿!$B$7) | B7: =IF(OR($A7="",B$4=""),"",COUNTIFS(事例清單!$G$5:$G$304,$A7,事例清單!$H$5:$H$304,B$4,事例清單!$F$5:$F$304,"是")) | C7: =IF(OR($A7="",C$4=""),"",COUNTIFS(事例清單!$G$5:$G$304,$A7,事例清單!$H$5:$H$304,C$4,事例清單!$F$5:$F$304,"是")) | D7: =IF(OR($A7="",D$4=""),"",COUNTIFS(事例清單!$G$5:$G$304,$A7,事例清單!$H$5:$H$304,D$4,事例清單!$F$5:$F$304,"是")) | E7: =IF(OR($A7="",E$4=""),"",COUNTIFS(事例清單!$G$5:$G$304,$A7,事例清單!$H$5:$H$304,E$4,事例清單!$F$5:$F$304,"是")) | F7: =IF(OR($A7="",F$4=""),"",COUNTIFS(事例清單!$G$5:$G$304,$A7,事例清單!$H$5:$H$304,F$4,事例清單!$F$5:$F$304,"是")) | G7: =IF(OR($A7="",G$4=""),"",COUNTIFS(事例清單!$G$5:$G$304,$A7,事例清單!$H$5:$H$304,G$4,事例清單!$F$5:$F$304,"是")) | H7: =IF(OR($A7="",H$4=""),"",COUNTIFS(事例清單!$G$5:$G$304,$A7,事例清單!$H$5:$H$304,H$4,事例清單!$F$5:$F$304,"是")) | I7: =IF(OR($A7="",I$4=""),"",COUNTIFS(事例清單!$G$5:$G$304,$A7,事例清單!$H$5:$H$304,I$4,事例清單!$F$5:$F$304,"是")) | ... L7: =IF(OR($A7="",L$4=""),"",COUNTIFS(事例清單!$G$5:$G$304,$A7,事例清單!$H$5:$H$304,L$4,事例清單!$F$5:$F$304,"是")) | M7: =IF($A7="","",SUM(B7:L7)) | N7: =IF(OR($A$5="",E$4=""),"","甲歸「"&$A$5&"」、乙歸「"&E$4&"」") | O7: =IF(N7="",0,E5) | P7: =IF($A7="",0,N(M7)*N(D16))
A8: =IF(編碼簿!$B$8="","",編碼簿!$B$8) | B8: =IF(OR($A8="",B$4=""),"",COUNTIFS(事例清單!$G$5:$G$304,$A8,事例清單!$H$5:$H$304,B$4,事例清單!$F$5:$F$304,"是")) | C8: =IF(OR($A8="",C$4=""),"",COUNTIFS(事例清單!$G$5:$G$304,$A8,事例清單!$H$5:$H$304,C$4,事例清單!$F$5:$F$304,"是")) | D8: =IF(OR($A8="",D$4=""),"",COUNTIFS(事例清單!$G$5:$G$304,$A8,事例清單!$H$5:$H$304,D$4,事例清單!$F$5:$F$304,"是")) | E8: =IF(OR($A8="",E$4=""),"",COUNTIFS(事例清單!$G$5:$G$304,$A8,事例清單!$H$5:$H$304,E$4,事例清單!$F$5:$F$304,"是")) | F8: =IF(OR($A8="",F$4=""),"",COUNTIFS(事例清單!$G$5:$G$304,$A8,事例清單!$H$5:$H$304,F$4,事例清單!$F$5:$F$304,"是")) | G8: =IF(OR($A8="",G$4=""),"",COUNTIFS(事例清單!$G$5:$G$304,$A8,事例清單!$H$5:$H$304,G$4,事例清單!$F$5:$F$304,"是")) | H8: =IF(OR($A8="",H$4=""),"",COUNTIFS(事例清單!$G$5:$G$304,$A8,事例清單!$H$5:$H$304,H$4,事例清單!$F$5:$F$304,"是")) | I8: =IF(OR($A8="",I$4=""),"",COUNTIFS(事例清單!$G$5:$G$304,$A8,事例清單!$H$5:$H$304,I$4,事例清單!$F$5:$F$304,"是")) | ... L8: =IF(OR($A8="",L$4=""),"",COUNTIFS(事例清單!$G$5:$G$304,$A8,事例清單!$H$5:$H$304,L$4,事例清單!$F$5:$F$304,"是")) | M8: =IF($A8="","",SUM(B8:L8)) | N8: =IF(OR($A$5="",F$4=""),"","甲歸「"&$A$5&"」、乙歸「"&F$4&"」") | O8: =IF(N8="",0,F5) | P8: =IF($A8="",0,N(M8)*N(E16))
A9: =IF(編碼簿!$B$9="","",編碼簿!$B$9) | B9: =IF(OR($A9="",B$4=""),"",COUNTIFS(事例清單!$G$5:$G$304,$A9,事例清單!$H$5:$H$304,B$4,事例清單!$F$5:$F$304,"是")) | C9: =IF(OR($A9="",C$4=""),"",COUNTIFS(事例清單!$G$5:$G$304,$A9,事例清單!$H$5:$H$304,C$4,事例清單!$F$5:$F$304,"是")) | D9: =IF(OR($A9="",D$4=""),"",COUNTIFS(事例清單!$G$5:$G$304,$A9,事例清單!$H$5:$H$304,D$4,事例清單!$F$5:$F$304,"是")) | E9: =IF(OR($A9="",E$4=""),"",COUNTIFS(事例清單!$G$5:$G$304,$A9,事例清單!$H$5:$H$304,E$4,事例清單!$F$5:$F$304,"是")) | F9: =IF(OR($A9="",F$4=""),"",COUNTIFS(事例清單!$G$5:$G$304,$A9,事例清單!$H$5:$H$304,F$4,事例清單!$F$5:$F$304,"是")) | G9: =IF(OR($A9="",G$4=""),"",COUNTIFS(事例清單!$G$5:$G$304,$A9,事例清單!$H$5:$H$304,G$4,事例清單!$F$5:$F$304,"是")) | H9: =IF(OR($A9="",H$4=""),"",COUNTIFS(事例清單!$G$5:$G$304,$A9,事例清單!$H$5:$H$304,H$4,事例清單!$F$5:$F$304,"是")) | I9: =IF(OR($A9="",I$4=""),"",COUNTIFS(事例清單!$G$5:$G$304,$A9,事例清單!$H$5:$H$304,I$4,事例清單!$F$5:$F$304,"是")) | ... L9: =IF(OR($A9="",L$4=""),"",COUNTIFS(事例清單!$G$5:$G$304,$A9,事例清單!$H$5:$H$304,L$4,事例清單!$F$5:$F$304,"是")) | M9: =IF($A9="","",SUM(B9:L9)) | N9: =IF(OR($A$5="",G$4=""),"","甲歸「"&$A$5&"」、乙歸「"&G$4&"」") | O9: =IF(N9="",0,G5) | P9: =IF($A9="",0,N(M9)*N(F16))
A10: =IF(編碼簿!$B$10="","",編碼簿!$B$10) | B10: =IF(OR($A10="",B$4=""),"",COUNTIFS(事例清單!$G$5:$G$304,$A10,事例清單!$H$5:$H$304,B$4,事例清單!$F$5:$F$304,"是")) | C10: =IF(OR($A10="",C$4=""),"",COUNTIFS(事例清單!$G$5:$G$304,$A10,事例清單!$H$5:$H$304,C$4,事例清單!$F$5:$F$304,"是")) | D10: =IF(OR($A10="",D$4=""),"",COUNTIFS(事例清單!$G$5:$G$304,$A10,事例清單!$H$5:$H$304,D$4,事例清單!$F$5:$F$304,"是")) | E10: =IF(OR($A10="",E$4=""),"",COUNTIFS(事例清單!$G$5:$G$304,$A10,事例清單!$H$5:$H$304,E$4,事例清單!$F$5:$F$304,"是")) | F10: =IF(OR($A10="",F$4=""),"",COUNTIFS(事例清單!$G$5:$G$304,$A10,事例清單!$H$5:$H$304,F$4,事例清單!$F$5:$F$304,"是")) | G10: =IF(OR($A10="",G$4=""),"",COUNTIFS(事例清單!$G$5:$G$304,$A10,事例清單!$H$5:$H$304,G$4,事例清單!$F$5:$F$304,"是")) | H10: =IF(OR($A10="",H$4=""),"",COUNTIFS(事例清單!$G$5:$G$304,$A10,事例清單!$H$5:$H$304,H$4,事例清單!$F$5:$F$304,"是")) | I10: =IF(OR($A10="",I$4=""),"",COUNTIFS(事例清單!$G$5:$G$304,$A10,事例清單!$H$5:$H$304,I$4,事例清單!$F$5:$F$304,"是")) | ... L10: =IF(OR($A10="",L$4=""),"",COUNTIFS(事例清單!$G$5:$G$304,$A10,事例清單!$H$5:$H$304,L$4,事例清單!$F$5:$F$304,"是")) | M10: =IF($A10="","",SUM(B10:L10)) | N10: =IF(OR($A$5="",H$4=""),"","甲歸「"&$A$5&"」、乙歸「"&H$4&"」") | O10: =IF(N10="",0,H5) | P10: =IF($A10="",0,N(M10)*N(G16))
A11: =IF(編碼簿!$B$11="","",編碼簿!$B$11) | B11: =IF(OR($A11="",B$4=""),"",COUNTIFS(事例清單!$G$5:$G$304,$A11,事例清單!$H$5:$H$304,B$4,事例清單!$F$5:$F$304,"是")) | C11: =IF(OR($A11="",C$4=""),"",COUNTIFS(事例清單!$G$5:$G$304,$A11,事例清單!$H$5:$H$304,C$4,事例清單!$F$5:$F$304,"是")) | D11: =IF(OR($A11="",D$4=""),"",COUNTIFS(事例清單!$G$5:$G$304,$A11,事例清單!$H$5:$H$304,D$4,事例清單!$F$5:$F$304,"是")) | E11: =IF(OR($A11="",E$4=""),"",COUNTIFS(事例清單!$G$5:$G$304,$A11,事例清單!$H$5:$H$304,E$4,事例清單!$F$5:$F$304,"是")) | F11: =IF(OR($A11="",F$4=""),"",COUNTIFS(事例清單!$G$5:$G$304,$A11,事例清單!$H$5:$H$304,F$4,事例清單!$F$5:$F$304,"是")) | G11: =IF(OR($A11="",G$4=""),"",COUNTIFS(事例清單!$G$5:$G$304,$A11,事例清單!$H$5:$H$304,G$4,事例清單!$F$5:$F$304,"是")) | H11: =IF(OR($A11="",H$4=""),"",COUNTIFS(事例清單!$G$5:$G$304,$A11,事例清單!$H$5:$H$304,H$4,事例清單!$F$5:$F$304,"是")) | I11: =IF(OR($A11="",I$4=""),"",COUNTIFS(事例清單!$G$5:$G$304,$A11,事例清單!$H$5:$H$304,I$4,事例清單!$F$5:$F$304,"是")) | ... L11: =IF(OR($A11="",L$4=""),"",COUNTIFS(事例清單!$G$5:$G$304,$A11,事例清單!$H$5:$H$304,L$4,事例清單!$F$5:$F$304,"是")) | M11: =IF($A11="","",SUM(B11:L11)) | N11: =IF(OR($A$5="",I$4=""),"","甲歸「"&$A$5&"」、乙歸「"&I$4&"」") | O11: =IF(N11="",0,I5) | P11: =IF($A11="",0,N(M11)*N(H16))
A12: =IF(編碼簿!$B$12="","",編碼簿!$B$12) | B12: =IF(OR($A12="",B$4=""),"",COUNTIFS(事例清單!$G$5:$G$304,$A12,事例清單!$H$5:$H$304,B$4,事例清單!$F$5:$F$304,"是")) | C12: =IF(OR($A12="",C$4=""),"",COUNTIFS(事例清單!$G$5:$G$304,$A12,事例清單!$H$5:$H$304,C$4,事例清單!$F$5:$F$304,"是")) | D12: =IF(OR($A12="",D$4=""),"",COUNTIFS(事例清單!$G$5:$G$304,$A12,事例清單!$H$5:$H$304,D$4,事例清單!$F$5:$F$304,"是")) | E12: =IF(OR($A12="",E$4=""),"",COUNTIFS(事例清單!$G$5:$G$304,$A12,事例清單!$H$5:$H$304,E$4,事例清單!$F$5:$F$304,"是")) | F12: =IF(OR($A12="",F$4=""),"",COUNTIFS(事例清單!$G$5:$G$304,$A12,事例清單!$H$5:$H$304,F$4,事例清單!$F$5:$F$304,"是")) | G12: =IF(OR($A12="",G$4=""),"",COUNTIFS(事例清單!$G$5:$G$304,$A12,事例清單!$H$5:$H$304,G$4,事例清單!$F$5:$F$304,"是")) | H12: =IF(OR($A12="",H$4=""),"",COUNTIFS(事例清單!$G$5:$G$304,$A12,事例清單!$H$5:$H$304,H$4,事例清單!$F$5:$F$304,"是")) | I12: =IF(OR($A12="",I$4=""),"",COUNTIFS(事例清單!$G$5:$G$304,$A12,事例清單!$H$5:$H$304,I$4,事例清單!$F$5:$F$304,"是")) | ... L12: =IF(OR($A12="",L$4=""),"",COUNTIFS(事例清單!$G$5:$G$304,$A12,事例清單!$H$5:$H$304,L$4,事例清單!$F$5:$F$304,"是")) | M12: =IF($A12="","",SUM(B12:L12)) | N12: =IF(OR($A$5="",J$4=""),"","甲歸「"&$A$5&"」、乙歸「"&J$4&"」") | O12: =IF(N12="",0,J5) | P12: =IF($A12="",0,N(M12)*N(I16))
A13: =IF(編碼簿!$B$13="","",編碼簿!$B$13) | B13: =IF(OR($A13="",B$4=""),"",COUNTIFS(事例清單!$G$5:$G$304,$A13,事例清單!$H$5:$H$304,B$4,事例清單!$F$5:$F$304,"是")) | C13: =IF(OR($A13="",C$4=""),"",COUNTIFS(事例清單!$G$5:$G$304,$A13,事例清單!$H$5:$H$304,C$4,事例清單!$F$5:$F$304,"是")) | D13: =IF(OR($A13="",D$4=""),"",COUNTIFS(事例清單!$G$5:$G$304,$A13,事例清單!$H$5:$H$304,D$4,事例清單!$F$5:$F$304,"是")) | E13: =IF(OR($A13="",E$4=""),"",COUNTIFS(事例清單!$G$5:$G$304,$A13,事例清單!$H$5:$H$304,E$4,事例清單!$F$5:$F$304,"是")) | F13: =IF(OR($A13="",F$4=""),"",COUNTIFS(事例清單!$G$5:$G$304,$A13,事例清單!$H$5:$H$304,F$4,事例清單!$F$5:$F$304,"是")) | G13: =IF(OR($A13="",G$4=""),"",COUNTIFS(事例清單!$G$5:$G$304,$A13,事例清單!$H$5:$H$304,G$4,事例清單!$F$5:$F$304,"是")) | H13: =IF(OR($A13="",H$4=""),"",COUNTIFS(事例清單!$G$5:$G$304,$A13,事例清單!$H$5:$H$304,H$4,事例清單!$F$5:$F$304,"是")) | I13: =IF(OR($A13="",I$4=""),"",COUNTIFS(事例清單!$G$5:$G$304,$A13,事例清單!$H$5:$H$304,I$4,事例清單!$F$5:$F$304,"是")) | ... L13: =IF(OR($A13="",L$4=""),"",COUNTIFS(事例清單!$G$5:$G$304,$A13,事例清單!$H$5:$H$304,L$4,事例清單!$F$5:$F$304,"是")) | M13: =IF($A13="","",SUM(B13:L13)) | N13: =IF(OR($A$5="",K$4=""),"","甲歸「"&$A$5&"」、乙歸「"&K$4&"」") | O13: =IF(N13="",0,K5) | P13: =IF($A13="",0,N(M13)*N(J16))
A14: =IF(編碼簿!$B$14="","",編碼簿!$B$14) | B14: =IF(OR($A14="",B$4=""),"",COUNTIFS(事例清單!$G$5:$G$304,$A14,事例清單!$H$5:$H$304,B$4,事例清單!$F$5:$F$304,"是")) | C14: =IF(OR($A14="",C$4=""),"",COUNTIFS(事例清單!$G$5:$G$304,$A14,事例清單!$H$5:$H$304,C$4,事例清單!$F$5:$F$304,"是")) | D14: =IF(OR($A14="",D$4=""),"",COUNTIFS(事例清單!$G$5:$G$304,$A14,事例清單!$H$5:$H$304,D$4,事例清單!$F$5:$F$304,"是")) | E14: =IF(OR($A14="",E$4=""),"",COUNTIFS(事例清單!$G$5:$G$304,$A14,事例清單!$H$5:$H$304,E$4,事例清單!$F$5:$F$304,"是")) | F14: =IF(OR($A14="",F$4=""),"",COUNTIFS(事例清單!$G$5:$G$304,$A14,事例清單!$H$5:$H$304,F$4,事例清單!$F$5:$F$304,"是")) | G14: =IF(OR($A14="",G$4=""),"",COUNTIFS(事例清單!$G$5:$G$304,$A14,事例清單!$H$5:$H$304,G$4,事例清單!$F$5:$F$304,"是")) | H14: =IF(OR($A14="",H$4=""),"",COUNTIFS(事例清單!$G$5:$G$304,$A14,事例清單!$H$5:$H$304,H$4,事例清單!$F$5:$F$304,"是")) | I14: =IF(OR($A14="",I$4=""),"",COUNTIFS(事例清單!$G$5:$G$304,$A14,事例清單!$H$5:$H$304,I$4,事例清單!$F$5:$F$304,"是")) | ... L14: =IF(OR($A14="",L$4=""),"",COUNTIFS(事例清單!$G$5:$G$304,$A14,事例清單!$H$5:$H$304,L$4,事例清單!$F$5:$F$304,"是")) | M14: =IF($A14="","",SUM(B14:L14)) | N14: =IF(OR($A$5="",L$4=""),"","甲歸「"&$A$5&"」、乙歸「"&L$4&"」") | O14: =IF(N14="",0,L5) | P14: =IF($A14="",0,N(M14)*N(K16))
A15: =IF(編碼簿!$B$15="","",編碼簿!$B$15) | B15: =IF(OR($A15="",B$4=""),"",COUNTIFS(事例清單!$G$5:$G$304,$A15,事例清單!$H$5:$H$304,B$4,事例清單!$F$5:$F$304,"是")) | C15: =IF(OR($A15="",C$4=""),"",COUNTIFS(事例清單!$G$5:$G$304,$A15,事例清單!$H$5:$H$304,C$4,事例清單!$F$5:$F$304,"是")) | D15: =IF(OR($A15="",D$4=""),"",COUNTIFS(事例清單!$G$5:$G$304,$A15,事例清單!$H$5:$H$304,D$4,事例清單!$F$5:$F$304,"是")) | E15: =IF(OR($A15="",E$4=""),"",COUNTIFS(事例清單!$G$5:$G$304,$A15,事例清單!$H$5:$H$304,E$4,事例清單!$F$5:$F$304,"是")) | F15: =IF(OR($A15="",F$4=""),"",COUNTIFS(事例清單!$G$5:$G$304,$A15,事例清單!$H$5:$H$304,F$4,事例清單!$F$5:$F$304,"是")) | G15: =IF(OR($A15="",G$4=""),"",COUNTIFS(事例清單!$G$5:$G$304,$A15,事例清單!$H$5:$H$304,G$4,事例清單!$F$5:$F$304,"是")) | H15: =IF(OR($A15="",H$4=""),"",COUNTIFS(事例清單!$G$5:$G$304,$A15,事例清單!$H$5:$H$304,H$4,事例清單!$F$5:$F$304,"是")) | I15: =IF(OR($A15="",I$4=""),"",COUNTIFS(事例清單!$G$5:$G$304,$A15,事例清單!$H$5:$H$304,I$4,事例清單!$F$5:$F$304,"是")) | ... L15: =IF(OR($A15="",L$4=""),"",COUNTIFS(事例清單!$G$5:$G$304,$A15,事例清單!$H$5:$H$304,L$4,事例清單!$F$5:$F$304,"是")) | M15: =IF($A15="","",SUM(B15:L15)) | N15: =IF(OR($A$6="",B$4=""),"","甲歸「"&$A$6&"」、乙歸「"&B$4&"」") | O15: =IF(N15="",0,B6) | P15: =IF($A15="",0,N(M15)*N(L16))
A16: 乙合計 | B16: =IF(B$4="","",SUM(B5:B15)) | C16: =IF(C$4="","",SUM(C5:C15)) | D16: =IF(D$4="","",SUM(D5:D15)) | E16: =IF(E$4="","",SUM(E5:E15)) | F16: =IF(F$4="","",SUM(F5:F15)) | G16: =IF(G$4="","",SUM(G5:G15)) | H16: =IF(H$4="","",SUM(H5:H15)) | I16: =IF(I$4="","",SUM(I5:I15)) | ... L16: =IF(L$4="","",SUM(L5:L15)) | M16: =SUM(B5:L15) | N16: =IF(OR($A$6="",D$4=""),"","甲歸「"&$A$6&"」、乙歸「"&D$4&"」") | O16: =IF(N16="",0,D6)
A17: 結果 | N17: =IF(OR($A$6="",E$4=""),"","甲歸「"&$A$6&"」、乙歸「"&E$4&"」") | O17: =IF(N17="",0,E6)
A18: 事例總數 N | B18: =M16 | C18: 保留、且甲乙都已分類的事例 | N18: =IF(OR($A$6="",F$4=""),"","甲歸「"&$A$6&"」、乙歸「"&F$4&"」") | O18: =IF(N18="",0,F6)
A19: 對角線事例數 | B19: =SUM(B5,C6,D7,E8,F9,G10,H11,I12,J13,K14,L15) | C19: 兩人歸到同一類 | N19: =IF(OR($A$6="",G$4=""),"","甲歸「"&$A$6&"」、乙歸「"&G$4&"」") | O19: =IF(N19="",0,G6)
A20: 觀察同意率 | B20: =IF(B18=0,"",B19/B18) | C20: 對角線事例數 ÷ N | N20: =IF(OR($A$6="",H$4=""),"","甲歸「"&$A$6&"」、乙歸「"&H$4&"」") | O20: =IF(N20="",0,H6)
A21: 碰巧一致率 | B21: =IF(B18=0,"",SUM(P5:P15)/B18^2) | C21: 各類（甲合計 × 乙合計）加總，再除以 N² | N21: =IF(OR($A$6="",I$4=""),"","甲歸「"&$A$6&"」、乙歸「"&I$4&"」") | O21: =IF(N21="",0,I6)
A22: Cohen’s κ | B22: =IF(B18=0,"",IF(B21>=1,"無法計算",(B20-B21)/(1-B21))) | C22: （觀察同意率 − 碰巧一致率）÷（1 − 碰巧一致率） | N22: =IF(OR($A$6="",J$4=""),"","甲歸「"&$A$6&"」、乙歸「"&J$4&"」") | O22: =IF(N22="",0,J6)
A23: 判定 | B23: =IF(B22="","請先完成甲乙分類",IF(B22="無法計算","無法計算：所有事例都在同一類",IF(B22>=0.81,"通過：幾乎完全一致",IF(B22>=0.61,"通過：高度一致",IF(B22>=0.41,"未通過：中等一致，修編碼簿後重新分類",IF(B22>0,"不通過：一致性偏低，類別定義需重寫","嚴重：一致程度未超過隨機一致的水準")))))) | N23: =IF(OR($A$6="",K$4=""),"","甲歸「"&$A$6&"」、乙歸「"&K$4&"」") | O23: =IF(N23="",0,K6)
A24: 分歧最多的組合 | B24: =IF(OR(B18=0,MAX(O5:O200)=0),"無",INDEX(N5:N200,MATCH(MAX(O5:O200),O5:O200,0))&"，共 "&MAX(O5:O200)&" 則") | N24: =IF(OR($A$6="",L$4=""),"","甲歸「"&$A$6&"」、乙歸「"&L$4&"」") | O24: =IF(N24="",0,L6)
A25: 只有一人分類 | B25: =SUMPRODUCT((事例清單!F5:F304="是")*((事例清單!G5:G304="")<>(事例清單!H5:H304=""))) | C25: 大於 0 表示有事例只有一人分類，這些事例沒有納入計算 | N25: =IF(OR($A$7="",B$4=""),"","甲歸「"&$A$7&"」、乙歸「"&B$4&"」") | O25: =IF(N25="",0,B7)
A26: 未納入計算 | B26: =SUMPRODUCT((事例清單!F5:F304="是")*(事例清單!G5:G304<>"")*(事例清單!H5:H304<>""))-B18 | C26: 大於 0 表示有分類不在編碼簿中 | N26: =IF(OR($A$7="",C$4=""),"","甲歸「"&$A$7&"」、乙歸「"&C$4&"」") | O26: =IF(N26="",0,C7)
N27: =IF(OR($A$7="",E$4=""),"","甲歸「"&$A$7&"」、乙歸「"&E$4&"」") | O27: =IF(N27="",0,E7)
N28: =IF(OR($A$7="",F$4=""),"","甲歸「"&$A$7&"」、乙歸「"&F$4&"」") | O28: =IF(N28="",0,F7)
N29: =IF(OR($A$7="",G$4=""),"","甲歸「"&$A$7&"」、乙歸「"&G$4&"」") | O29: =IF(N29="",0,G7)
N30: =IF(OR($A$7="",H$4=""),"","甲歸「"&$A$7&"」、乙歸「"&H$4&"」") | O30: =IF(N30="",0,H7)
N31: =IF(OR($A$7="",I$4=""),"","甲歸「"&$A$7&"」、乙歸「"&I$4&"」") | O31: =IF(N31="",0,I7)
N32: =IF(OR($A$7="",J$4=""),"","甲歸「"&$A$7&"」、乙歸「"&J$4&"」") | O32: =IF(N32="",0,J7)
N33: =IF(OR($A$7="",K$4=""),"","甲歸「"&$A$7&"」、乙歸「"&K$4&"」") | O33: =IF(N33="",0,K7)
N34: =IF(OR($A$7="",L$4=""),"","甲歸「"&$A$7&"」、乙歸「"&L$4&"」") | O34: =IF(N34="",0,L7)
N35: =IF(OR($A$8="",B$4=""),"","甲歸「"&$A$8&"」、乙歸「"&B$4&"」") | O35: =IF(N35="",0,B8)
N36: =IF(OR($A$8="",C$4=""),"","甲歸「"&$A$8&"」、乙歸「"&C$4&"」") | O36: =IF(N36="",0,C8)
N37: =IF(OR($A$8="",D$4=""),"","甲歸「"&$A$8&"」、乙歸「"&D$4&"」") | O37: =IF(N37="",0,D8)
N38: =IF(OR($A$8="",F$4=""),"","甲歸「"&$A$8&"」、乙歸「"&F$4&"」") | O38: =IF(N38="",0,F8)
N39: =IF(OR($A$8="",G$4=""),"","甲歸「"&$A$8&"」、乙歸「"&G$4&"」") | O39: =IF(N39="",0,G8)
N40: =IF(OR($A$8="",H$4=""),"","甲歸「"&$A$8&"」、乙歸「"&H$4&"」") | O40: =IF(N40="",0,H8)
N41: =IF(OR($A$8="",I$4=""),"","甲歸「"&$A$8&"」、乙歸「"&I$4&"」") | O41: =IF(N41="",0,I8)
...

Sheet 標籤驗證
A1: 標籤驗證（分類完成後才看）
A2: 填入事例當時旁人的原話，檢驗流行語這個標籤，實際落在哪些類別的行為上
A4: 編號 | B4: 最後採用的分類 | C4: 旁人原話 | D4: 含「玻璃心」 | F4: 要檢驗的標籤 | G4: 玻璃心
A5: =IF(事例清單!A5="","",事例清單!A5) | B5: =IF(事例清單!F5<>"是","",IF(事例清單!J5<>"",事例清單!J5,IF(事例清單!I5="一致",事例清單!G5,""))) | C5: 他也太玻璃心了吧，講一句就哭 | D5: =IF(C5="","",IF(ISNUMBER(SEARCH($G$4,C5)),"有",""))
A6: =IF(事例清單!A6="","",事例清單!A6) | B6: =IF(事例清單!F6<>"是","",IF(事例清單!J6<>"",事例清單!J6,IF(事例清單!I6="一致",事例清單!G6,""))) | C6: 被客戶念一句就這樣，新人都經不起 | D6: =IF(C6="","",IF(ISNUMBER(SEARCH($G$4,C6)),"有","")) | F6: 類別 | G6: 事例數 | H6: 被貼上標籤
A7: =IF(事例清單!A7="","",事例清單!A7) | B7: =IF(事例清單!F7<>"是","",IF(事例清單!J7<>"",事例清單!J7,IF(事例清單!I7="一致",事例清單!G7,""))) | C7: 草莓族就是這樣，碰一下就爛 | D7: =IF(C7="","",IF(ISNUMBER(SEARCH($G$4,C7)),"有","")) | F7: =IF(編碼簿!$B$5="","",編碼簿!$B$5) | G7: =IF(F7="","",COUNTIF($B$5:$B$304,F7)) | H7: =IF(F7="","",COUNTIFS($B$5:$B$304,F7,$D$5:$D$304,"有"))
A8: =IF(事例清單!A8="","",事例清單!A8) | B8: =IF(事例清單!F8<>"是","",IF(事例清單!J8<>"",事例清單!J8,IF(事例清單!I8="一致",事例清單!G8,""))) | C8: 太脆弱了，以後怎麼帶人 | D8: =IF(C8="","",IF(ISNUMBER(SEARCH($G$4,C8)),"有","")) | F8: =IF(編碼簿!$B$6="","",編碼簿!$B$6) | G8: =IF(F8="","",COUNTIF($B$5:$B$304,F8)) | H8: =IF(F8="","",COUNTIFS($B$5:$B$304,F8,$D$5:$D$304,"有"))
A9: =IF(事例清單!A9="","",事例清單!A9) | B9: =IF(事例清單!F9<>"是","",IF(事例清單!J9<>"",事例清單!J9,IF(事例清單!I9="一致",事例清單!G9,""))) | C9: 他就是玻璃心 | D9: =IF(C9="","",IF(ISNUMBER(SEARCH($G$4,C9)),"有","")) | F9: =IF(編碼簿!$B$7="","",編碼簿!$B$7) | G9: =IF(F9="","",COUNTIF($B$5:$B$304,F9)) | H9: =IF(F9="","",COUNTIFS($B$5:$B$304,F9,$D$5:$D$304,"有"))
A10: =IF(事例清單!A10="","",事例清單!A10) | B10: =IF(事例清單!F10<>"是","",IF(事例清單!J10<>"",事例清單!J10,IF(事例清單!I10="一致",事例清單!G10,""))) | C10: 被保護得太好了吧 | D10: =IF(C10="","",IF(ISNUMBER(SEARCH($G$4,C10)),"有","")) | F10: =IF(編碼簿!$B$8="","",編碼簿!$B$8) | G10: =IF(F10="","",COUNTIF($B$5:$B$304,F10)) | H10: =IF(F10="","",COUNTIFS($B$5:$B$304,F10,$D$5:$D$304,"有"))
A11: =IF(事例清單!A11="","",事例清單!A11) | B11: =IF(事例清單!F11<>"是","",IF(事例清單!J11<>"",事例清單!J11,IF(事例清單!I11="一致",事例清單!G11,""))) | C11: 玻璃心，一點小事想那麼久 | D11: =IF(C11="","",IF(ISNUMBER(SEARCH($G$4,C11)),"有","")) | F11: =IF(編碼簿!$B$9="","",編碼簿!$B$9) | G11: =IF(F11="","",COUNTIF($B$5:$B$304,F11)) | H11: =IF(F11="","",COUNTIFS($B$5:$B$304,F11,$D$5:$D$304,"有"))
A12: =IF(事例清單!A12="","",事例清單!A12) | B12: =IF(事例清單!F12<>"是","",IF(事例清單!J12<>"",事例清單!J12,IF(事例清單!I12="一致",事例清單!G12,""))) | C12: 想太多了，這麼不禁念 | D12: =IF(C12="","",IF(ISNUMBER(SEARCH($G$4,C12)),"有","")) | F12: =IF(編碼簿!$B$10="","",編碼簿!$B$10) | G12: =IF(F12="","",COUNTIF($B$5:$B$304,F12)) | H12: =IF(F12="","",COUNTIFS($B$5:$B$304,F12,$D$5:$D$304,"有"))
A13: =IF(事例清單!A13="","",事例清單!A13) | B13: =IF(事例清單!F13<>"是","",IF(事例清單!J13<>"",事例清單!J13,IF(事例清單!I13="一致",事例清單!G13,""))) | C13: 現在的年輕人真的比較玻璃心 | D13: =IF(C13="","",IF(ISNUMBER(SEARCH($G$4,C13)),"有","")) | F13: =IF(編碼簿!$B$11="","",編碼簿!$B$11) | G13: =IF(F13="","",COUNTIF($B$5:$B$304,F13)) | H13: =IF(F13="","",COUNTIFS($B$5:$B$304,F13,$D$5:$D$304,"有"))
A14: =IF(事例清單!A14="","",事例清單!A14) | B14: =IF(事例清單!F14<>"是","",IF(事例清單!J14<>"",事例清單!J14,IF(事例清單!I14="一致",事例清單!G14,""))) | C14: 心太軟，做品管不適合 | D14: =IF(C14="","",IF(ISNUMBER(SEARCH($G$4,C14)),"有","")) | F14: =IF(編碼簿!$B$12="","",編碼簿!$B$12) | G14: =IF(F14="","",COUNTIF($B$5:$B$304,F14)) | H14: =IF(F14="","",COUNTIFS($B$5:$B$304,F14,$D$5:$D$304,"有"))
A15: =IF(事例清單!A15="","",事例清單!A15) | B15: =IF(事例清單!F15<>"是","",IF(事例清單!J15<>"",事例清單!J15,IF(事例清單!I15="一致",事例清單!G15,""))) | C15: 記仇喔，玻璃心 | D15: =IF(C15="","",IF(ISNUMBER(SEARCH($G$4,C15)),"有","")) | F15: =IF(編碼簿!$B$13="","",編碼簿!$B$13) | G15: =IF(F15="","",COUNTIF($B$5:$B$304,F15)) | H15: =IF(F15="","",COUNTIFS($B$5:$B$304,F15,$D$5:$D$304,"有"))
A16: =IF(事例清單!A16="","",事例清單!A16) | B16: =IF(事例清單!F16<>"是","",IF(事例清單!J16<>"",事例清單!J16,IF(事例清單!I16="一致",事例清單!G16,""))) | C16: 太敏感了 | D16: =IF(C16="","",IF(ISNUMBER(SEARCH($G$4,C16)),"有","")) | F16: =IF(編碼簿!$B$14="","",編碼簿!$B$14) | G16: =IF(F16="","",COUNTIF($B$5:$B$304,F16)) | H16: =IF(F16="","",COUNTIFS($B$5:$B$304,F16,$D$5:$D$304,"有"))
A17: =IF(事例清單!A17="","",事例清單!A17) | B17: =IF(事例清單!F17<>"是","",IF(事例清單!J17<>"",事例清單!J17,IF(事例清單!I17="一致",事例清單!G17,""))) | C17: 玻璃心，講一下就封鎖 | D17: =IF(C17="","",IF(ISNUMBER(SEARCH($G$4,C17)),"有","")) | F17: =IF(編碼簿!$B$15="","",編碼簿!$B$15) | G17: =IF(F17="","",COUNTIF($B$5:$B$304,F17)) | H17: =IF(F17="","",COUNTIFS($B$5:$B$304,F17,$D$5:$D$304,"有"))
A18: =IF(事例清單!A18="","",事例清單!A18) | B18: =IF(事例清單!F18<>"是","",IF(事例清單!J18<>"",事例清單!J18,IF(事例清單!I18="一致",事例清單!G18,""))) | C18: 躲什麼，就是玻璃心 | D18: =IF(C18="","",IF(ISNUMBER(SEARCH($G$4,C18)),"有",""))
A19: =IF(事例清單!A19="","",事例清單!A19) | B19: =IF(事例清單!F19<>"是","",IF(事例清單!J19<>"",事例清單!J19,IF(事例清單!I19="一致",事例清單!G19,""))) | C19: 草莓族，不敢面對 | D19: =IF(C19="","",IF(ISNUMBER(SEARCH($G$4,C19)),"有","")) | F19: 標籤集中在哪幾類，代表大家用這個詞時，主要指的是哪些行為；標籤分散在各類，代表這個詞的意思很廣
A20: =IF(事例清單!A20="","",事例清單!A20) | B20: =IF(事例清單!F20<>"是","",IF(事例清單!J20<>"",事例清單!J20,IF(事例清單!I20="一致",事例清單!G20,""))) | C20: 玻璃心又愛面子 | D20: =IF(C20="","",IF(ISNUMBER(SEARCH($G$4,C20)),"有",""))
A21: =IF(事例清單!A21="","",事例清單!A21) | B21: =IF(事例清單!F21<>"是","",IF(事例清單!J21<>"",事例清單!J21,IF(事例清單!I21="一致",事例清單!G21,""))) | C21: 他就是聽不得別人講 | D21: =IF(C21="","",IF(ISNUMBER(SEARCH($G$4,C21)),"有",""))
A22: =IF(事例清單!A22="","",事例清單!A22) | B22: =IF(事例清單!F22<>"是","",IF(事例清單!J22<>"",事例清單!J22,IF(事例清單!I22="一致",事例清單!G22,""))) | C22: 受不了一點批評就想走 | D22: =IF(C22="","",IF(ISNUMBER(SEARCH($G$4,C22)),"有",""))
A23: =IF(事例清單!A23="","",事例清單!A23) | B23: =IF(事例清單!F23<>"是","",IF(事例清單!J23<>"",事例清單!J23,IF(事例清單!I23="一致",事例清單!G23,""))) | C23: 玻璃心 | D23: =IF(C23="","",IF(ISNUMBER(SEARCH($G$4,C23)),"有",""))
A24: =IF(事例清單!A24="","",事例清單!A24) | B24: =IF(事例清單!F24<>"是","",IF(事例清單!J24<>"",事例清單!J24,IF(事例清單!I24="一致",事例清單!G24,""))) | C24: 太脆弱 | D24: =IF(C24="","",IF(ISNUMBER(SEARCH($G$4,C24)),"有",""))
A25: =IF(事例清單!A25="","",事例清單!A25) | B25: =IF(事例清單!F25<>"是","",IF(事例清單!J25<>"",事例清單!J25,IF(事例清單!I25="一致",事例清單!G25,""))) | C25: 他好玻璃心，連這個也要申訴 | D25: =IF(C25="","",IF(ISNUMBER(SEARCH($G$4,C25)),"有",""))
A26: =IF(事例清單!A26="","",事例清單!A26) | B26: =IF(事例清單!F26<>"是","",IF(事例清單!J26<>"",事例清單!J26,IF(事例清單!I26="一致",事例清單!G26,""))) | C26: 這年輕人很玻璃心，叫一下都不行 | D26: =IF(C26="","",IF(ISNUMBER(SEARCH($G$4,C26)),"有",""))
A27: =IF(事例清單!A27="","",事例清單!A27) | B27: =IF(事例清單!F27<>"是","",IF(事例清單!J27<>"",事例清單!J27,IF(事例清單!I27="一致",事例清單!G27,""))) | C27: 開個玩笑也不行，玻璃心 | D27: =IF(C27="","",IF(ISNUMBER(SEARCH($G$4,C27)),"有",""))
A28: =IF(事例清單!A28="","",事例清單!A28) | B28: =IF(事例清單!F28<>"是","",IF(事例清單!J28<>"",事例清單!J28,IF(事例清單!I28="一致",事例清單!G28,""))) | C28: 大家都知道 | D28: =IF(C28="","",IF(ISNUMBER(SEARCH($G$4,C28)),"有",""))
A29: =IF(事例清單!A29="","",事例清單!A29) | B29: =IF(事例清單!F29<>"是","",IF(事例清單!J29<>"",事例清單!J29,IF(事例清單!I29="一致",事例清單!G29,""))) | D29: =IF(C29="","",IF(ISNUMBER(SEARCH($G$4,C29)),"有",""))
A30: =IF(事例清單!A30="","",事例清單!A30) | B30: =IF(事例清單!F30<>"是","",IF(事例清單!J30<>"",事例清單!J30,IF(事例清單!I30="一致",事例清單!G30,""))) | C30: 玻璃心吧 | D30: =IF(C30="","",IF(ISNUMBER(SEARCH($G$4,C30)),"有",""))
A31: =IF(事例清單!A31="","",事例清單!A31) | B31: =IF(事例清單!F31<>"是","",IF(事例清單!J31<>"",事例清單!J31,IF(事例清單!I31="一致",事例清單!G31,""))) | C31: 這也要難過 | D31: =IF(C31="","",IF(ISNUMBER(SEARCH($G$4,C31)),"有",""))
A32: =IF(事例清單!A32="","",事例清單!A32) | B32: =IF(事例清單!F32<>"是","",IF(事例清單!J32<>"",事例清單!J32,IF(事例清單!I32="一致",事例清單!G32,""))) | C32: 情緒控管很差 | D32: =IF(C32="","",IF(ISNUMBER(SEARCH($G$4,C32)),"有",""))
A33: =IF(事例清單!A33="","",事例清單!A33) | B33: =IF(事例清單!F33<>"是","",IF(事例清單!J33<>"",事例清單!J33,IF(事例清單!I33="一致",事例清單!G33,""))) | C33: 太認真也是一種玻璃心 | D33: =IF(C33="","",IF(ISNUMBER(SEARCH($G$4,C33)),"有",""))
A34: =IF(事例清單!A34="","",事例清單!A34) | B34: =IF(事例清單!F34<>"是","",IF(事例清單!J34<>"",事例清單!J34,IF(事例清單!I34="一致",事例清單!G34,""))) | C34: 就是玻璃心 | D34: =IF(C34="","",IF(ISNUMBER(SEARCH($G$4,C34)),"有",""))
A35: =IF(事例清單!A35="","",事例清單!A35) | B35: =IF(事例清單!F35<>"是","",IF(事例清單!J35<>"",事例清單!J35,IF(事例清單!I35="一致",事例清單!G35,""))) | C35: 被唸一次就擺爛 | D35: =IF(C35="","",IF(ISNUMBER(SEARCH($G$4,C35)),"有",""))
A36: =IF(事例清單!A36="","",事例清單!A36) | B36: =IF(事例清單!F36<>"是","",IF(事例清單!J36<>"",事例清單!J36,IF(事例清單!I36="一致",事例清單!G36,""))) | C36: 心眼小又玻璃心 | D36: =IF(C36="","",IF(ISNUMBER(SEARCH($G$4,C36)),"有",""))
A37: =IF(事例清單!A37="","",事例清單!A37) | B37: =IF(事例清單!F37<>"是","",IF(事例清單!J37<>"",事例清單!J37,IF(事例清單!I37="一致",事例清單!G37,""))) | C37: 太玻璃心了 | D37: =IF(C37="","",IF(ISNUMBER(SEARCH($G$4,C37)),"有",""))
A38: =IF(事例清單!A38="","",事例清單!A38) | B38: =IF(事例清單!F38<>"是","",IF(事例清單!J38<>"",事例清單!J38,IF(事例清單!I38="一致",事例清單!G38,""))) | C38: 被罵一次就怕成這樣 | D38: =IF(C38="","",IF(ISNUMBER(SEARCH($G$4,C38)),"有",""))
A39: =IF(事例清單!A39="","",事例清單!A39) | B39: =IF(事例清單!F39<>"是","",IF(事例清單!J39<>"",事例清單!J39,IF(事例清單!I39="一致",事例清單!G39,""))) | C39: 玻璃心，以後怎麼升遷 | D39: =IF(C39="","",IF(ISNUMBER(SEARCH($G$4,C39)),"有",""))
A40: =IF(事例清單!A40="","",事例清單!A40) | B40: =IF(事例清單!F40<>"是","",IF(事例清單!J40<>"",事例清單!J40,IF(事例清單!I40="一致",事例清單!G40,""))) | C40: 這樣就受不了 | D40: =IF(C40="","",IF(ISNUMBER(SEARCH($G$4,C40)),"有",""))
A41: =IF(事例清單!A41="","",事例清單!A41) | B41: =IF(事例清單!F41<>"是","",IF(事例清單!J41<>"",事例清單!J41,IF(事例清單!I41="一致",事例清單!G41,""))) | C41: 玻璃心又愛計較 | D41: =IF(C41="","",IF(ISNUMBER(SEARCH($G$4,C41)),"有",""))
...
